Workbook
Name ACQ_AMORTIZATION: Financing!$D$19
Name ACQ_FEE: Assumptions!$I$9
Name ACQ_LOAN_FEE: Financing!$D$16
Name ACQ_LOAN_TERM: Financing!$D$20
Name ACQ_PREPAY_PENALTY: Financing!$D$18
Name ACQ_PREPAY_WINDOW: Financing!$D$17
Name AM_FEE: Assumptions!$F$13
Name CAP_RESERVES: Assumptions!$D$34
Name CLOSE_DATE: Assumptions!$I$13
Name CLOSING_COSTS: Assumptions!$I$10
Name CM_FEE: Assumptions!$F$14
Name COSTS_OF_SALE: Assumptions!$L$7
Name CURR_ASSESSED_VAL: Assumptions!$B$52
Name DISTRIBUTION_FREQ: Assumptions!$L$12
Name EXIT_CAP: Assumptions!$L$9
Name EXP_GROWTH: Assumptions!$E$32
Name FIXED_CHARGES: Assumptions!$B$51
Name HOLD_PERIOD: Assumptions!$M$8
Name IO_ACQ: Financing!$D$15
Name IO_MEZZ: Financing!$E$15
Name IO_REFI: Financing!$F$15
Name MEZZ_AMORTIZATION: Financing!$E$19
Name MEZZ_LOAN_FEE: Financing!$E$16
Name MEZZ_PREPAY_PENALTY: Financing!$E$18
Name MEZZ_PREPAY_WINDOW: Financing!$E$17
Name MGMT_FEE: Assumptions!$E$33
Name MGMT_FEEs: Assumptions!$E$33
Name NLA: Assumptions!$C$5
Name PROPERTY_TAX_RATE: Assumptions!$B$50
Name PURCH_PRICE: Assumptions!$I$7
Name REASSESSED_UPON_SALE: Assumptions!$B$55
Name REFI_AMORTIZATION: Financing!$F$19
Name REFI_LOAN_FEE: Financing!$F$16
Name REFI_LOAN_TERM: Financing!$F$20
Name REFI_PREPAY_PENALTY: Financing!$F$18
Name REFI_PREPAY_WINDOW: Financing!$F$17
Name TOTAL_COST: Summary!$E$7
Name units: [3]Rents!$C$51
Name Units: Rent!$D$67
Name VALUE_ASSESSED: Assumptions!$B$54
Name WORKING_CAP: Assumptions!$I$11
Name YEAR_REASSESSED: Assumptions!$B$53

Sheet Checks
A1: Checks
A2: Monthly CF Equal Annual CF | B2: =ABS(SUM('Combined CF'!$O$6:$O$60)-SUM('Combined CF'!$A$6:$A$60))<0.01 -> TRUE
A3: Equity Investment = Sum of All Negative Cash Flows | B3: =ABS(Summary!E22+SUMIF('Combined CF'!Q60:ES60,"<"&0))<0.01 -> TRUE
A4: Expenses Sheet Row 26,27 Formula(Property Tax+Mngt Fee) = Row 21,22 Value(Property Tax+Mngt Fee) | B4: =ABS(SUM(Expenses!B20:NI21)-SUM(Expenses!B15:NI16))<0.01 -> TRUE
A5: Net Working Capital Equals Working Capital Distributed | B5: =ABS(WORKING_CAP-'Combined CF'!A48)<0.01 -> TRUE
B6: =SUMIF(Expenses!$B$12:$NI$12,1,Expenses!$B$20:$NI$20)+'CFS-Main Page'!G39-Assumptions!B45<0.01 -> TRUE
A9: Underwriting Notes & Assumptions
A11: General Modeling Notes
A12: 1. We have used the Rent comps from Hello Data and added the screenshot for the rent comps as well.
A13: 2. We made a change on Rent page to choose from either of Comps or RR market rent in Col L. Also you can compare the rents of Classic vs renovated in the Rows F5 to O6.
A14: 3. We have added a switch for the Taxes in the Pro Forma Assumptions to choose between T12 taxes and taxes on Reassessed value.
A15: 4. Broker numbers are not added as there was no Broker OM available.
A16: Our Assumptions
A17: General Assumptions
A18: 1. General assumptions (including market rent growth, expense growth, tax growth, and property management fees) are consistent with those applied in the prior model.
A19: 2. For financing, we have a 3 year I/O period and all in rate of 5.41% (5 year Treasury Yield of 4.007% + 1.40% spread).
A20: 3. Market Rents (For new and renewal leases) have been taken as $34.27 as per Colliers' 2025 Q4 Retail Report for the Downtown submarket (Over 10K Sqft).
A21: Asking Price and Exit Assumptions
... A32: Question to the team Catalyst

Sheet Summary
D1: Summary Details | G1: Levered Return Metrics | R1: Retail/Office Rent Roll (Consolidated) | Y1: Sensitivity Intervals | AB1: Tenant | AC1: Percentage of Base Rent
D2: Purchase Price | E2: =Assumptions!I7 -> 180000000 | G2: IRR | H2: =XIRR('Combined CF'!$Q$60:$ES$60,'Combined CF'!$Q$4:$ES$4) -> 0.14881178 | R2: Suite | S2: Tenant | T2: SF | U2: In-Place Rent/SF | V2: Reimbursement | W2: Expiration | Y2: Hold Period | Z2: 12 | AB2: =S3 -> Health PC Reserve | AC2: =U3*T3/($T$13*$U$13) -> 0.20427929
D3: Purchase Price Per SF | E3: =Assumptions!I8 -> 13447.889 | G3: Equity Multiple | H3: =SUMIF('Combined CF'!$Q$60:$ES$60,">"&0)/-SUMIF('Combined CF'!$Q$60:$ES$60,"<"&0) -> 1.926724 | R3: =Leases!A5 -> 1 | S3: =Leases!C5 -> Health PC Reserve | T3: =Leases!B5 -> 2583 | U3: =IFERROR(Leases!$D$170/T3,0) -> 2.639375 | V3: =Leases!G5 -> NNN | W3: =Leases!E5 -> 47330 | Y3: Exit Cap | Z3: 0.005 | AB3: =S4 -> Uptown Veterinary Hospital | AC3: =U4*T4/($T$13*$U$13) -> 0.21943263
D4: Going-In Cap Rate | E4: =Assumptions!I12 -> 0.028285466 | G4: Average Cash-on-Cash Return | H4: =AVERAGEIF('Combined CF'!$D$2:$M$2,"<="&HOLD_PERIOD/12,'Combined CF'!$D$63:$M$63) -> 0.039588165 | R4: =Leases!A21 -> 2 | S4: =Leases!C21 -> Uptown Veterinary Hospital | T4: =Leases!B21 -> 3367 | U4: =IFERROR(Leases!$D$186/Summary!T4,0) -> 2.175 | V4: =Leases!G21 -> NNN | W4: =Leases!E21 -> 46265 | AB4: =S5 -> Indigo Tea and Coffee Co. Grounds, LLC | AC4: =U5*T5/($T$13*$U$13) -> 0.19271751
D5: Going-In DSCR | E5: ='Combined CF'!R14/-'Combined CF'!R41 -> 0.77802392 | R5: =Leases!$A$37 -> 3 | S5: =Leases!$C$37 -> Indigo Tea and Coffee Co. Grounds, LLC | T5: =Leases!$B$37 -> 2437 | U5: =IFERROR(Leases!$D$202/Summary!T5,0) -> 2.6391667 | V5: =Leases!$G$37 -> NNN | W5: =Leases!$E$37 -> 46721 | Y5: Chart Metrics | AB5: =S6 -> Raghav Sundaresh | AC5: =U6*T6/($T$13*$U$13) -> 0.19140661
D6: Going-In Debt Yield | E6: ='Combined CF'!D14/'Combined CF'!C39 -> 0.040407809 | G6: Unlevered Return Metrics | R6: =Leases!$A$53 -> 4 | S6: =Leases!$C$53 -> Raghav Sundaresh | T6: =Leases!$B$53 -> 2568 | U6: =IFERROR(Leases!$D$218/Summary!T6,0) -> 2.4875 | V6: =Leases!$G$53 -> NNN | W6: =Leases!$E$53 -> 47330 | Y6: Metric | Z6: Net Operating Income | AB6: =S7 -> Pizzeria Sapienza CLT, LLC | AC6: =U7*T7/($T$13*$U$13) -> 0.19216395
D7: Total Cost | E7: =Assumptions!F27 -> 1.8509946e+08 | G7: IRR | H7: =XIRR('Combined CF'!$Q$36:$ES$36,'Combined CF'!$Q$4:$ES$4) -> 0.093561557 | R7: =Leases!$A$69 -> 5 | S7: =Leases!$C$69 -> Pizzeria Sapienza CLT, LLC | T7: =Leases!$B$69 -> 2430 | U7: =IFERROR(Leases!$D$234/Summary!T7,0) -> 2.6391667 | V7: =Leases!$G$69 -> NNN | W7: =Leases!$E$69 -> 46873 | AB7: =S8 -> 0 | AC7: =U8*T8/($T$13*$U$13) -> 0
D8: All-In Basis Per SF | E8: =E7/Assumptions!C5 -> 13828.873 | G8: Equity Multiple | H8: =SUMIF('Combined CF'!$Q$36:$ES$36,">"&0)/-SUMIF('Combined CF'!$Q$36:$ES$36,"<"&0) -> 1.5042331 | R8: =Leases!$A$85 -> 0 | S8: =Leases!$C$85 -> 0 | T8: =Leases!$B$85 -> 0 | U8: =IFERROR(Leases!$D$250/Summary!T8,0) -> 0 | V8: =Leases!$G$85 -> 0 | W8: =Leases!$E$85 -> 0 | AB8: =S9 -> 0 | AC8: =U9*T9/($T$13*$U$13) -> 0
G9: Average Cash-on-Cash Return | H9: =AVERAGEIF(CF!D2:M2,"<="&HOLD_PERIOD/12,'Combined CF'!$D$62:$M$62) -> 0.055575425 | R9: =Leases!$A$101 -> 0 | S9: =Leases!$C$101 -> 0 | T9: =Leases!$B$101 -> 0 | U9: =IFERROR(Leases!$D$266/Summary!T9,0) -> 0 | V9: =Leases!$G$101 -> 0 | W9: =Leases!$E$101 -> 0 | AB9: =S10 -> 0 | AC9: =U10*T10/($T$13*$U$13) -> 0
D10: Capital Budget Breakdown | R10: =Leases!$A$117 -> 0 | S10: =Leases!$C$117 -> 0 | T10: =Leases!$B$117 -> 0 | U10: =IFERROR(Leases!$D$282/Summary!T10,0) -> 0 | V10: =Leases!$G$117 -> 0 | W10: =Leases!$E$117 -> 0 | AB10: =S11 -> 0 | AC10: =U11*T11/($T$13*$U$13) -> 0
D11: Common Area Capital Budget | E11: ='Construction Budget'!C19 -> 0 | G11: Sale Details | R11: =Leases!$A$133 -> 0 | S11: =Leases!$C$133 -> 0 | T11: =Leases!$B$133 -> 0 | U11: =IFERROR(Leases!$D$298/Summary!T11,0) -> 0 | V11: =Leases!$G$133 -> 0 | W11: =Leases!$E$133 -> 0 | AB11: =S12 -> 0 | AC11: =U12*T12/($T$13*$U$13) -> 0
D12: Common Area Capital Budget Per SF | E12: =+E11/Assumptions!C5 -> 0 | G12: Sale Date | H12: =HLOOKUP(HOLD_PERIOD,CF!R4:ET5,2,0) -> 47968 | R12: =Leases!$A$149 -> 0 | S12: =Leases!$C$149 -> 0 | T12: =Leases!$B$149 -> 0 | U12: =IFERROR(Leases!$D$314/Summary!T12,0) -> 0 | V12: =Leases!$G$149 -> 0 | W12: =Leases!$E$149 -> 0
D13: TI/LC Costs | E13: =-SUM(CF!P31:P32) -> 457082.1 | G13: Exit Cap Rate | H13: =EXIT_CAP -> 0.0575 | S13: Total/Weighted Average | T13: =SUM(T3:T12) -> 13385 | U13: =SUMPRODUCT($T$3:$T$12,U3:U12)/T13 -> 2.4933474 | W13: =SUMPRODUCT($T$3:$T$12,W3:W12)/T13 -> 46868.252
D14: TI/LC Costs Per SF | E14: =E13/Assumptions!C5 -> 34.148831 | G14: Cap Rate Expansion Per Year | H14: =(H13-Assumptions!I12)/(Assumptions!M8/12) -> 0.0058429068
D15: Total Capital Costs | E15: =SUM(E11,E13) -> 457082.1 | G15: Sale Price | H15: ='Combined CF'!A33 -> 2.2520356e+08
D16: Total Capital Costs Per SF | E16: =E15/Assumptions!C5 -> 34.148831 | G16: Sale Price Per SF | H16: =H15/Assumptions!C5 -> 16825.069
D17: Month Construction Starts | E17: ='Construction Budget'!E19 -> 0 | G17: Costs of Sale | H17: =-'Combined CF'!A34 -> 2252035.6
D18: Month Construction Ends | E18: ='Construction Budget'!F19 -> 0 | G18: Value CAGR | H18: =RATE(Assumptions!M8/12,,-Assumptions!I7,H15,0,) -> 0.04582868
D20: Total Sources | G20: IRR Partitioning
D21: Acquisition/Mezzanine Loan Proceeds | E21: ='Combined CF'!O39+'Combined CF'!O40 -> 1.26e+08 | G21: From Sale/Financing | H21: =MAX(MIN('Combined CF'!O66/SUM('Combined CF'!O65:O66),1),0) -> 0.86772518
D22: Equity | E22: =E24-E21 -> 59099459 | G22: From Operating CF | H22: =MAX(MIN('Combined CF'!O65/SUM('Combined CF'!O65:O66),1),0) -> 0.13227482
D24: Total Sources | E24: =E36 -> 1.8509946e+08
D26: Total Uses
D27: Purchase Price | E27: =Assumptions!I7 -> 180000000
D28: Acquisition Fee | E28: =Assumptions!I9 -> 1800000
D29: Other Costs | E29: =SUM(Assumptions!F26,Assumptions!F22,Assumptions!F20) -> 0
D30: Construction Management Fee | E30: =-SUM('Combined CF'!R25:ES25) -> 0
D31: TI / LC Costs | E31: =SUM('Combined CF'!R57:ES57) -> 457082.1
D32: Construction Expenses | E32: =Assumptions!$F$25 -> 0
D33: Operating Shortfalls | E33: =SUM('Combined CF'!R56:ES56) -> 1582377
D34: Working Capital | E34: =+Assumptions!I11 -> 0
D35: Loan Fees | E35: =-'Combined CF'!Q43 -> 1260000
D36: Total Uses | E36: =SUM(E27:E35) -> 1.8509946e+08
D39: Month | E39: 1 | F39: =E39+1 -> 2 | G39: =F39+1 -> 3 | H39: =G39+1 -> 4 | I39: =H39+1 -> 5 | J39: =I39+1 -> 6 | K39: =J39+1 -> 7 | L39: =K39+1 -> 8 | M39: =L39+1 -> 9 | ... DT39: =DS39+1 -> 120
D40: Month Ending | E40: =IF(CF!S5<=Summary!$H$12,CF!S5,"") -> 46173 | F40: =IF(CF!T5<=Summary!$H$12,CF!T5,"") -> 46203 | G40: =IF(CF!U5<=Summary!$H$12,CF!U5,"") -> 46234 | H40: =IF(CF!V5<=Summary!$H$12,CF!V5,"") -> 46265 | I40: =IF(CF!W5<=Summary!$H$12,CF!W5,"") -> 46295 | J40: =IF(CF!X5<=Summary!$H$12,CF!X5,"") -> 46326 | K40: =IF(CF!Y5<=Summary!$H$12,CF!Y5,"") -> 46356 | L40: =IF(CF!Z5<=Summary!$H$12,CF!Z5,"") -> 46387 | ... DT40: =IF(CF!EH5<=Summary!$H$12,CF!EH5,"")
D41: =Z6 -> Net Operating Income | E41: =IF(AND(E40<=$H$12,VLOOKUP($D$41,$E$44:$F$56,2,0)="Positive"),VLOOKUP($D$41,'Combined CF'!$P$6:$ES$50,Summary!E39+2,0),IF(AND(E40<=$H$12,VLOOKUP($D$41,$E$44:$F$56,2,0)="Negative"),ABS(VLOOKUP($D$41,'Combined CF'!$P$6:$ES$50,Summary!E39+2,0)),"")) -> 425744.61 | F41: =IF(AND(F40<=$H$12,VLOOKUP($D$41,$E$44:$F$56,2,0)="Positive"),VLOOKUP($D$41,'Combined CF'!$P$6:$ES$50,Summary!F39+2,0),IF(AND(F40<=$H$12,VLOOKUP($D$41,$E$44:$F$56,2,0)="Negative"),ABS(VLOOKUP($D$41,'Combined CF'!$P$6:$ES$50,Summary!F39+2,0)),"")) -> 425744.61 | G41: =IF(AND(G40<=$H$12,VLOOKUP($D$41,$E$44:$F$56,2,0)="Positive"),VLOOKUP($D$41,'Combined CF'!$P$6:$ES$50,Summary!G39+2,0),IF(AND(G40<=$H$12,VLOOKUP($D$41,$E$44:$F$56,2,0)="Negative"),ABS(VLOOKUP($D$41,'Combined CF'!$P$6:$ES$50,Summary!G39+2,0)),"")) -> 425937.54 | H41: =IF(AND(H40<=$H$12,VLOOKUP($D$41,$E$44:$F$56,2,0)="Positive"),VLOOKUP($D$41,'Combined CF'!$P$6:$ES$50,Summary!H39+2,0),IF(AND(H40<=$H$12,VLOOKUP($D$41,$E$44:$F$56,2,0)="Negative"),ABS(VLOOKUP($D$41,'Combined CF'!$P$6:$ES$50,Summary!H39+2,0)),"")) -> 426333.7 | I41: =IF(AND(I40<=$H$12,VLOOKUP($D$41,$E$44:$F$56,2,0)="Positive"),VLOOKUP($D$41,'Combined CF'!$P$6:$ES$50,Summary!I39+2,0),IF(AND(I40<=$H$12,VLOOKUP($D$41,$E$44:$F$56,2,0)="Negative"),ABS(VLOOKUP($D$41,'Combined CF'!$P$6:$ES$50,Summary!I39+2,0)),"")) -> 417550.78 | J41: =IF(AND(J40<=$H$12,VLOOKUP($D$41,$E$44:$F$56,2,0)="Positive"),VLOOKUP($D$41,'Combined CF'!$P$6:$ES$50,Summary!J39+2,0),IF(AND(J40<=$H$12,VLOOKUP($D$41,$E$44:$F$56,2,0)="Negative"),ABS(VLOOKUP($D$41,'Combined CF'!$P$6:$ES$50,Summary!J39+2,0)),"")) -> 417547.47 | K41: =IF(AND(K40<=$H$12,VLOOKUP($D$41,$E$44:$F$56,2,0)="Positive"),VLOOKUP($D$41,'Combined CF'!$P$6:$ES$50,Summary!K39+2,0),IF(AND(K40<=$H$12,VLOOKUP($D$41,$E$44:$F$56,2,0)="Negative"),ABS(VLOOKUP($D$41,'Combined CF'!$P$6:$ES$50,Summary!K39+2,0)),"")) -> 419010.48 | L41: =IF(AND(L40<=$H$12,VLOOKUP($D$41,$E$44:$F$56,2,0)="Positive"),VLOOKUP($D$41,'Combined CF'!$P$6:$ES$50,Summary!L39+2,0),IF(AND(L40<=$H$12,VLOOKUP($D$41,$E$44:$F$56,2,0)="Negative"),ABS(VLOOKUP($D$41,'Combined CF'!$P$6:$ES$50,Summary!L39+2,0)),"")) -> 419010.48 | ... DT41: =IF(AND(DT40<=$H$12,VLOOKUP($D$41,$E$44:$F$56,2,0)="Positive"),VLOOKUP($D$41,'Combined CF'!$P$6:$ES$50,Summary!DT39+2,0),IF(AND(DT40<=$H$12,VLOOKUP($D$41,$E$44:$F$56,2,0)="Negative"),ABS(VLOOKUP($D$41,'Combined CF'!$P$6:$ES$50,Summary!DT39+2,0)),""))
E44: Net Rental Income | F44: Positive
E45: CAM Reimbursements | F45: Positive
E46: Percentage Rent | F46: Positive
E47: Effective Gross Revenue | F47: Positive
...

Sheet Combined CF
B1: =Assumptions!A1 -> Levered Return Metrics | C1: =Assumptions!B1 -> IRR | D1: =Assumptions!C1 -> 0.14881178 | E1: =Assumptions!D1 -> Equity Multiple | F1: =Assumptions!E1 -> 1.926724 | G1: =Assumptions!F1 -> Unlevered Return Metrics | H1: =Assumptions!G1 -> IRR | I1: =Assumptions!H1 -> 0.093561557 | ... K1: =Assumptions!J1 -> 1.5042331
B2: Year | C2: 0 | D2: 1 | E2: =D2+1 -> 2 | F2: =E2+1 -> 3 | G2: =F2+1 -> 4 | H2: =G2+1 -> 5 | I2: =H2+1 -> 6 | J2: =I2+1 -> 7 | K2: =J2+1 -> 8 | L2: =K2+1 -> 9 | M2: =L2+1 -> 10 | P2: Year | Q2: 0 | R2: 1 | S2: 1 | T2: 1 | U2: 1 | V2: 1 | W2: 1 | X2: 1 | Y2: 1 | Z2: 1 | AA2: 1 | AB2: 1 | AC2: 1 | AD2: =R2+1 -> 2 | AE2: =S2+1 -> 2 | AF2: =T2+1 -> 2 | AG2: =U2+1 -> 2 | AH2: =V2+1 -> 2 | AI2: =W2+1 -> 2 | AJ2: =X2+1 -> 2 | AK2: =Y2+1 -> 2 | ... ES2: =EG2+1 -> 11
P3: Month | Q3: 0 | R3: 1 | S3: =R3+1 -> 2 | T3: =S3+1 -> 3 | U3: =T3+1 -> 4 | V3: =U3+1 -> 5 | W3: =V3+1 -> 6 | X3: =W3+1 -> 7 | Y3: =X3+1 -> 8 | Z3: =Y3+1 -> 9 | ... ES3: =ER3+1 -> 132
B4: Month Ending | C4: =CLOSE_DATE -> 46142 | D4: =EOMONTH(C4,12) -> 46507 | E4: =EOMONTH(D4,12) -> 46873 | F4: =EOMONTH(E4,12) -> 47238 | G4: =EOMONTH(F4,12) -> 47603 | H4: =EOMONTH(G4,12) -> 47968 | I4: =EOMONTH(H4,12) -> 48334 | J4: =EOMONTH(I4,12) -> 48699 | K4: =EOMONTH(J4,12) -> 49064 | ... M4: =EOMONTH(L4,12) -> 49795 | P4: Month Ending | Q4: =CLOSE_DATE -> 46142 | R4: =Leases!D167 -> 46173 | S4: =EOMONTH(R4,1) -> 46203 | T4: =EOMONTH(S4,1) -> 46234 | U4: =EOMONTH(T4,1) -> 46265 | V4: =EOMONTH(U4,1) -> 46295 | W4: =EOMONTH(V4,1) -> 46326 | X4: =EOMONTH(W4,1) -> 46356 | Y4: =EOMONTH(X4,1) -> 46387 | Z4: =EOMONTH(Y4,1) -> 46418 | ... ES4: =EOMONTH(ER4,1) -> 50160
A6: =SUM(C6:M6) -> 97882425 | B6: Net Rental Income | D6: =SUMIF($R$2:$ES$2,D$2,$R6:$ES6) -> 10248853 | E6: =SUMIF($R$2:$ES$2,E$2,$R6:$ES6) -> 15260922 | F6: =SUMIF($R$2:$ES$2,F$2,$R6:$ES6) -> 16748297 | G6: =SUMIF($R$2:$ES$2,G$2,$R6:$ES6) -> 17970973 | H6: =SUMIF($R$2:$ES$2,H$2,$R6:$ES6) -> 18581410 | I6: =SUMIF($R$2:$ES$2,I$2,$R6:$ES6) -> 19071970 | J6: =SUMIF($R$2:$ES$2,J$2,$R6:$ES6) -> 0 | K6: =SUMIF($R$2:$ES$2,K$2,$R6:$ES6) -> 0 | ... M6: =SUMIF($R$2:$ES$2,M$2,$R6:$ES6) -> 0 | O6: =SUM(Q6:ES6) -> 97882425 | P6: Net Rental Income | R6: =INDEX(CF!$Q$11:$ET$35,MATCH($P6,CF!$Q$11:$Q$35,0),MATCH(R$4,CF!$Q$5:$ET$5,0))+SUMIF('CFS-Main Page'!$G$15:$AA$15,R$2,'CFS-Main Page'!$G$25:$AA$25)/12 -> 855290.12 | S6: =INDEX(CF!$Q$11:$ET$35,MATCH($P6,CF!$Q$11:$Q$35,0),MATCH(S$4,CF!$Q$5:$ET$5,0))+SUMIF('CFS-Main Page'!$G$15:$AA$15,S$2,'CFS-Main Page'!$G$25:$AA$25)/12 -> 855290.12 | T6: =INDEX(CF!$Q$11:$ET$35,MATCH($P6,CF!$Q$11:$Q$35,0),MATCH(T$4,CF!$Q$5:$ET$5,0))+SUMIF('CFS-Main Page'!$G$15:$AA$15,T$2,'CFS-Main Page'!$G$25:$AA$25)/12 -> 855483.05 | U6: =INDEX(CF!$Q$11:$ET$35,MATCH($P6,CF!$Q$11:$Q$35,0),MATCH(U$4,CF!$Q$5:$ET$5,0))+SUMIF('CFS-Main Page'!$G$15:$AA$15,U$2,'CFS-Main Page'!$G$25:$AA$25)/12 -> 855879.21 | V6: =INDEX(CF!$Q$11:$ET$35,MATCH($P6,CF!$Q$11:$Q$35,0),MATCH(V$4,CF!$Q$5:$ET$5,0))+SUMIF('CFS-Main Page'!$G$15:$AA$15,V$2,'CFS-Main Page'!$G$25:$AA$25)/12 -> 848555.99 | W6: =INDEX(CF!$Q$11:$ET$35,MATCH($P6,CF!$Q$11:$Q$35,0),MATCH(W$4,CF!$Q$5:$ET$5,0))+SUMIF('CFS-Main Page'!$G$15:$AA$15,W$2,'CFS-Main Page'!$G$25:$AA$25)/12 -> 848555.99 | X6: =INDEX(CF!$Q$11:$ET$35,MATCH($P6,CF!$Q$11:$Q$35,0),MATCH(X$4,CF!$Q$5:$ET$5,0))+SUMIF('CFS-Main Page'!$G$15:$AA$15,X$2,'CFS-Main Page'!$G$25:$AA$25)/12 -> 848555.99 | Y6: =INDEX(CF!$Q$11:$ET$35,MATCH($P6,CF!$Q$11:$Q$35,0),MATCH(Y$4,CF!$Q$5:$ET$5,0))+SUMIF('CFS-Main Page'!$G$15:$AA$15,Y$2,'CFS-Main Page'!$G$25:$AA$25)/12 -> 848555.99 | ... ES6: =INDEX(CF!$Q$11:$ET$35,MATCH($P6,CF!$Q$11:$Q$35,0),MATCH(ES$4,CF!$Q$5:$ET$5,0))+SUMIF('CFS-Main Page'!$G$15:$AA$15,ES$2,'CFS-Main Page'!$G$25:$AA$25)/12 -> 0
A8: =SUM(C8:M8) -> 6587768.1 | B8: Total Other Income | D8: =SUMIF($R$2:$ES$2,D$2,$R8:$ES8) -> 1025953.7 | E8: =SUMIF($R$2:$ES$2,E$2,$R8:$ES8) -> 1054982.1 | F8: =SUMIF($R$2:$ES$2,F$2,$R8:$ES8) -> 1083864.5 | G8: =SUMIF($R$2:$ES$2,G$2,$R8:$ES8) -> 1110756.3 | H8: =SUMIF($R$2:$ES$2,H$2,$R8:$ES8) -> 1145760.7 | I8: =SUMIF($R$2:$ES$2,I$2,$R8:$ES8) -> 1166450.7 | J8: =SUMIF($R$2:$ES$2,J$2,$R8:$ES8) -> 0 | K8: =SUMIF($R$2:$ES$2,K$2,$R8:$ES8) -> 0 | ... M8: =SUMIF($R$2:$ES$2,M$2,$R8:$ES8) -> 0 | O8: =SUM(Q8:ES8) -> 6587768.1 | P8: Total Other Income | R8: =INDEX(CF!$Q$11:$ET$35,MATCH($P8,CF!$Q$11:$Q$35,0),MATCH(R$4,CF!$Q$5:$ET$5,0))+SUMIF('CFS-Main Page'!$G$15:$AA$15,R$2,'CFS-Main Page'!$G$29:$AA$29)/12 -> 85667.576 | S8: =INDEX(CF!$Q$11:$ET$35,MATCH($P8,CF!$Q$11:$Q$35,0),MATCH(S$4,CF!$Q$5:$ET$5,0))+SUMIF('CFS-Main Page'!$G$15:$AA$15,S$2,'CFS-Main Page'!$G$29:$AA$29)/12 -> 85680.591 | T8: =INDEX(CF!$Q$11:$ET$35,MATCH($P8,CF!$Q$11:$Q$35,0),MATCH(T$4,CF!$Q$5:$ET$5,0))+SUMIF('CFS-Main Page'!$G$15:$AA$15,T$2,'CFS-Main Page'!$G$29:$AA$29)/12 -> 85693.636 | U8: =INDEX(CF!$Q$11:$ET$35,MATCH($P8,CF!$Q$11:$Q$35,0),MATCH(U$4,CF!$Q$5:$ET$5,0))+SUMIF('CFS-Main Page'!$G$15:$AA$15,U$2,'CFS-Main Page'!$G$29:$AA$29)/12 -> 85706.71 | V8: =INDEX(CF!$Q$11:$ET$35,MATCH($P8,CF!$Q$11:$Q$35,0),MATCH(V$4,CF!$Q$5:$ET$5,0))+SUMIF('CFS-Main Page'!$G$15:$AA$15,V$2,'CFS-Main Page'!$G$29:$AA$29)/12 -> 84260.115 | W8: =INDEX(CF!$Q$11:$ET$35,MATCH($P8,CF!$Q$11:$Q$35,0),MATCH(W$4,CF!$Q$5:$ET$5,0))+SUMIF('CFS-Main Page'!$G$15:$AA$15,W$2,'CFS-Main Page'!$G$29:$AA$29)/12 -> 84269.944 | X8: =INDEX(CF!$Q$11:$ET$35,MATCH($P8,CF!$Q$11:$Q$35,0),MATCH(X$4,CF!$Q$5:$ET$5,0))+SUMIF('CFS-Main Page'!$G$15:$AA$15,X$2,'CFS-Main Page'!$G$29:$AA$29)/12 -> 85746.11 | Y8: =INDEX(CF!$Q$11:$ET$35,MATCH($P8,CF!$Q$11:$Q$35,0),MATCH(Y$4,CF!$Q$5:$ET$5,0))+SUMIF('CFS-Main Page'!$G$15:$AA$15,Y$2,'CFS-Main Page'!$G$29:$AA$29)/12 -> 85759.303 | ... ES8: =INDEX(CF!$Q$11:$ET$35,MATCH($P8,CF!$Q$11:$Q$35,0),MATCH(ES$4,CF!$Q$5:$ET$5,0))+SUMIF('CFS-Main Page'!$G$15:$AA$15,ES$2,'CFS-Main Page'!$G$29:$AA$29)/12 -> 0
A10: =SUM(C10:M10) -> 1.0447019e+08 | B10: Effective Gross Revenue | D10: =SUMIF($R$2:$ES$2,D$2,$R10:$ES10) -> 11274806 | E10: =SUMIF($R$2:$ES$2,E$2,$R10:$ES10) -> 16315904 | F10: =SUMIF($R$2:$ES$2,F$2,$R10:$ES10) -> 17832162 | G10: =SUMIF($R$2:$ES$2,G$2,$R10:$ES10) -> 19081729 | H10: =SUMIF($R$2:$ES$2,H$2,$R10:$ES10) -> 19727171 | I10: =SUMIF($R$2:$ES$2,I$2,$R10:$ES10) -> 20238421 | J10: =SUMIF($R$2:$ES$2,J$2,$R10:$ES10) -> 0 | K10: =SUMIF($R$2:$ES$2,K$2,$R10:$ES10) -> 0 | ... M10: =SUMIF($R$2:$ES$2,M$2,$R10:$ES10) -> 0 | O10: =SUM(Q10:ES10) -> 1.0447019e+08 | P10: Effective Gross Revenue | R10: =SUM(R6,R8) -> 940957.7 | S10: =SUM(S6,S8) -> 940970.71 | T10: =SUM(T6,T8) -> 941176.68 | U10: =SUM(U6,U8) -> 941585.92 | V10: =SUM(V6,V8) -> 932816.1 | W10: =SUM(W6,W8) -> 932825.93 | X10: =SUM(X6,X8) -> 934302.1 | Y10: =SUM(Y6,Y8) -> 934315.29 | ... ES10: =SUM(ES6,ES8) -> 0
A12: =SUM(C12:M12) -> -40512383 | B12: Total Operating Expenses | D12: =SUMIF($R$2:$ES$2,D$2,$R12:$ES12) -> -6183422.6 | E12: =SUMIF($R$2:$ES$2,E$2,$R12:$ES12) -> -6458691.4 | F12: =SUMIF($R$2:$ES$2,F$2,$R12:$ES12) -> -6640903.2 | G12: =SUMIF($R$2:$ES$2,G$2,$R12:$ES12) -> -6820371.4 | H12: =SUMIF($R$2:$ES$2,H$2,$R12:$ES12) -> -7119777.9 | I12: =SUMIF($R$2:$ES$2,I$2,$R12:$ES12) -> -7289216.5 | J12: =SUMIF($R$2:$ES$2,J$2,$R12:$ES12) -> 0 | K12: =SUMIF($R$2:$ES$2,K$2,$R12:$ES12) -> 0 | ... M12: =SUMIF($R$2:$ES$2,M$2,$R12:$ES12) -> 0 | O12: =SUM(Q12:ES12) -> -40512383 | P12: Total Operating Expenses | R12: =INDEX(CF!$Q$11:$ET$35,MATCH($P12,CF!$Q$11:$Q$35,0),MATCH(R$4,CF!$Q$5:$ET$5,0))-SUMIF('CFS-Main Page'!$G$15:$AA$15,R$2,'CFS-Main Page'!$G$46:$AA$46)/12 -> -515213.09 | S12: =INDEX(CF!$Q$11:$ET$35,MATCH($P12,CF!$Q$11:$Q$35,0),MATCH(S$4,CF!$Q$5:$ET$5,0))-SUMIF('CFS-Main Page'!$G$15:$AA$15,S$2,'CFS-Main Page'!$G$46:$AA$46)/12 -> -515226.1 | T12: =INDEX(CF!$Q$11:$ET$35,MATCH($P12,CF!$Q$11:$Q$35,0),MATCH(T$4,CF!$Q$5:$ET$5,0))-SUMIF('CFS-Main Page'!$G$15:$AA$15,T$2,'CFS-Main Page'!$G$46:$AA$46)/12 -> -515239.15 | U12: =INDEX(CF!$Q$11:$ET$35,MATCH($P12,CF!$Q$11:$Q$35,0),MATCH(U$4,CF!$Q$5:$ET$5,0))-SUMIF('CFS-Main Page'!$G$15:$AA$15,U$2,'CFS-Main Page'!$G$46:$AA$46)/12 -> -515252.22 | V12: =INDEX(CF!$Q$11:$ET$35,MATCH($P12,CF!$Q$11:$Q$35,0),MATCH(V$4,CF!$Q$5:$ET$5,0))-SUMIF('CFS-Main Page'!$G$15:$AA$15,V$2,'CFS-Main Page'!$G$46:$AA$46)/12 -> -515265.32 | W12: =INDEX(CF!$Q$11:$ET$35,MATCH($P12,CF!$Q$11:$Q$35,0),MATCH(W$4,CF!$Q$5:$ET$5,0))-SUMIF('CFS-Main Page'!$G$15:$AA$15,W$2,'CFS-Main Page'!$G$46:$AA$46)/12 -> -515278.46 | X12: =INDEX(CF!$Q$11:$ET$35,MATCH($P12,CF!$Q$11:$Q$35,0),MATCH(X$4,CF!$Q$5:$ET$5,0))-SUMIF('CFS-Main Page'!$G$15:$AA$15,X$2,'CFS-Main Page'!$G$46:$AA$46)/12 -> -515291.62 | Y12: =INDEX(CF!$Q$11:$ET$35,MATCH($P12,CF!$Q$11:$Q$35,0),MATCH(Y$4,CF!$Q$5:$ET$5,0))-SUMIF('CFS-Main Page'!$G$15:$AA$15,Y$2,'CFS-Main Page'!$G$46:$AA$46)/12 -> -515304.81 | ... ES12: =INDEX(CF!$Q$11:$ET$35,MATCH($P12,CF!$Q$11:$Q$35,0),MATCH(ES$4,CF!$Q$5:$ET$5,0))-SUMIF('CFS-Main Page'!$G$15:$AA$15,ES$2,'CFS-Main Page'!$G$46:$AA$46)/12 -> 0
A14: =SUM(C14:M14) -> 63957810 | B14: Net Operating Income | D14: =SUMIF($R$2:$ES$2,D$2,$R14:$ES14) -> 5091383.9 | E14: =SUMIF($R$2:$ES$2,E$2,$R14:$ES14) -> 9857212.3 | F14: =SUMIF($R$2:$ES$2,F$2,$R14:$ES14) -> 11191259 | G14: =SUMIF($R$2:$ES$2,G$2,$R14:$ES14) -> 12261358 | H14: =SUMIF($R$2:$ES$2,H$2,$R14:$ES14) -> 12607393 | I14: =SUMIF($R$2:$ES$2,I$2,$R14:$ES14) -> 12949204 | J14: =SUMIF($R$2:$ES$2,J$2,$R14:$ES14) -> 0 | K14: =SUMIF($R$2:$ES$2,K$2,$R14:$ES14) -> 0 | ... M14: =SUMIF($R$2:$ES$2,M$2,$R14:$ES14) -> 0 | O14: =SUM(Q14:ES14) -> 63957810 | P14: Net Operating Income | R14: =SUM(R10,R12) -> 425744.61 | S14: =SUM(S10,S12) -> 425744.61 | T14: =SUM(T10,T12) -> 425937.54 | U14: =SUM(U10,U12) -> 426333.7 | V14: =SUM(V10,V12) -> 417550.78 | W14: =SUM(W10,W12) -> 417547.47 | X14: =SUM(X10,X12) -> 419010.48 | Y14: =SUM(Y10,Y12) -> 419010.48 | ... ES14: =SUM(ES10,ES12) -> 0
A16: =SUM(C16:M16) -> -457082.1 | B16: Total TI/LC Expenses | D16: =SUMIF($R$2:$ES$2,D$2,$R16:$ES16) -> -113576.43 | E16: =SUMIF($R$2:$ES$2,E$2,$R16:$ES16) -> -82964.871 | F16: =SUMIF($R$2:$ES$2,F$2,$R16:$ES16) -> -82971.826 | G16: =SUMIF($R$2:$ES$2,G$2,$R16:$ES16) -> -177568.98 | H16: =SUMIF($R$2:$ES$2,H$2,$R16:$ES16) -> 0 | I16: =SUMIF($R$2:$ES$2,I$2,$R16:$ES16) -> 0 | J16: =SUMIF($R$2:$ES$2,J$2,$R16:$ES16) -> 0 | K16: =SUMIF($R$2:$ES$2,K$2,$R16:$ES16) -> 0 | ... M16: =SUMIF($R$2:$ES$2,M$2,$R16:$ES16) -> 0 | O16: =SUM(Q16:ES16) -> -457082.1 | P16: Total TI/LC Expenses | R16: =INDEX(CF!$Q$11:$ET$35,MATCH($P16,CF!$Q$11:$Q$35,0),MATCH(R$4,CF!$Q$5:$ET$5,0)) -> 0 | S16: =INDEX(CF!$Q$11:$ET$35,MATCH($P16,CF!$Q$11:$Q$35,0),MATCH(S$4,CF!$Q$5:$ET$5,0)) -> 0 | T16: =INDEX(CF!$Q$11:$ET$35,MATCH($P16,CF!$Q$11:$Q$35,0),MATCH(T$4,CF!$Q$5:$ET$5,0)) -> 0 | U16: =INDEX(CF!$Q$11:$ET$35,MATCH($P16,CF!$Q$11:$Q$35,0),MATCH(U$4,CF!$Q$5:$ET$5,0)) -> 0 | V16: =INDEX(CF!$Q$11:$ET$35,MATCH($P16,CF!$Q$11:$Q$35,0),MATCH(V$4,CF!$Q$5:$ET$5,0)) -> 0 | W16: =INDEX(CF!$Q$11:$ET$35,MATCH($P16,CF!$Q$11:$Q$35,0),MATCH(W$4,CF!$Q$5:$ET$5,0)) -> -113576.43 | X16: =INDEX(CF!$Q$11:$ET$35,MATCH($P16,CF!$Q$11:$Q$35,0),MATCH(X$4,CF!$Q$5:$ET$5,0)) -> 0 | Y16: =INDEX(CF!$Q$11:$ET$35,MATCH($P16,CF!$Q$11:$Q$35,0),MATCH(Y$4,CF!$Q$5:$ET$5,0)) -> 0 | ... ES16: =INDEX(CF!$Q$11:$ET$35,MATCH($P16,CF!$Q$11:$Q$35,0),MATCH(ES$4,CF!$Q$5:$ET$5,0)) -> 0
A18: =SUM(C18:M18) -> 50551524 | B18: Total Cash Flow Before Debt Service | D18: =SUMIF($R$2:$ES$2,D$2,$R18:$ES18) -> 4977807.5 | E18: =SUMIF($R$2:$ES$2,E$2,$R18:$ES18) -> 9774247.5 | F18: =SUMIF($R$2:$ES$2,F$2,$R18:$ES18) -> 11108287 | G18: =SUMIF($R$2:$ES$2,G$2,$R18:$ES18) -> 12083789 | H18: =SUMIF($R$2:$ES$2,H$2,$R18:$ES18) -> 12607393 | I18: =SUMIF($R$2:$ES$2,I$2,$R18:$ES18) -> 0 | J18: =SUMIF($R$2:$ES$2,J$2,$R18:$ES18) -> 0 | K18: =SUMIF($R$2:$ES$2,K$2,$R18:$ES18) -> 0 | ... M18: =SUMIF($R$2:$ES$2,M$2,$R18:$ES18) -> 0 | O18: =SUM(Q18:ES18) -> 50551524 | P18: Total Cash Flow Before Debt Service | R18: =IF(R$3<=HOLD_PERIOD,SUM(R14,R16),0) -> 425744.61 | S18: =IF(S$3<=HOLD_PERIOD,SUM(S14,S16),0) -> 425744.61 | T18: =IF(T$3<=HOLD_PERIOD,SUM(T14,T16),0) -> 425937.54 | U18: =IF(U$3<=HOLD_PERIOD,SUM(U14,U16),0) -> 426333.7 | V18: =IF(V$3<=HOLD_PERIOD,SUM(V14,V16),0) -> 417550.78 | W18: =IF(W$3<=HOLD_PERIOD,SUM(W14,W16),0) -> 303971.05 | X18: =IF(X$3<=HOLD_PERIOD,SUM(X14,X16),0) -> 419010.48 | Y18: =IF(Y$3<=HOLD_PERIOD,SUM(Y14,Y16),0) -> 419010.48 | ... ES18: =IF(ES$3<=HOLD_PERIOD,SUM(ES14,ES16),0) -> 0
A20: =SUM(C20:M20) -> -33462.5 | B20: Capital Reserves | D20: =SUMIF($R$2:$ES$2,D$2,$R20:$ES20) -> -6692.5 | E20: =SUMIF($R$2:$ES$2,E$2,$R20:$ES20) -> -6692.5 | F20: =SUMIF($R$2:$ES$2,F$2,$R20:$ES20) -> -6692.5 | G20: =SUMIF($R$2:$ES$2,G$2,$R20:$ES20) -> -6692.5 | H20: =SUMIF($R$2:$ES$2,H$2,$R20:$ES20) -> -6692.5 | I20: =SUMIF($R$2:$ES$2,I$2,$R20:$ES20) -> 0 | J20: =SUMIF($R$2:$ES$2,J$2,$R20:$ES20) -> 0 | K20: =SUMIF($R$2:$ES$2,K$2,$R20:$ES20) -> 0 | ... M20: =SUMIF($R$2:$ES$2,M$2,$R20:$ES20) -> 0 | O20: =SUM(Q20:ES20) -> -33462.5 | P20: Capital Reserves | R20: =IF(R$3<=HOLD_PERIOD,-CAP_RESERVES*NLA/12,0) -> -557.70833 | S20: =IF(S$3<=HOLD_PERIOD,-CAP_RESERVES*NLA/12,0) -> -557.70833 | T20: =IF(T$3<=HOLD_PERIOD,-CAP_RESERVES*NLA/12,0) -> -557.70833 | U20: =IF(U$3<=HOLD_PERIOD,-CAP_RESERVES*NLA/12,0) -> -557.70833 | V20: =IF(V$3<=HOLD_PERIOD,-CAP_RESERVES*NLA/12,0) -> -557.70833 | W20: =IF(W$3<=HOLD_PERIOD,-CAP_RESERVES*NLA/12,0) -> -557.70833 | X20: =IF(X$3<=HOLD_PERIOD,-CAP_RESERVES*NLA/12,0) -> -557.70833 | Y20: =IF(Y$3<=HOLD_PERIOD,-CAP_RESERVES*NLA/12,0) -> -557.70833 | ... ES20: =IF(ES$3<=HOLD_PERIOD,-CAP_RESERVES*NLA/12,0) -> 0
A21: =SUM(C21:M21) -> 0 | B21: Construction Expenses | D21: =SUMIF($R$2:$ES$2,D$2,$R21:$ES21) -> 0 | E21: =SUMIF($R$2:$ES$2,E$2,$R21:$ES21) -> 0 | F21: =SUMIF($R$2:$ES$2,F$2,$R21:$ES21) -> 0 | G21: =SUMIF($R$2:$ES$2,G$2,$R21:$ES21) -> 0 | H21: =SUMIF($R$2:$ES$2,H$2,$R21:$ES21) -> 0 | I21: =SUMIF($R$2:$ES$2,I$2,$R21:$ES21) -> 0 | J21: =SUMIF($R$2:$ES$2,J$2,$R21:$ES21) -> 0 | K21: =SUMIF($R$2:$ES$2,K$2,$R21:$ES21) -> 0 | ... M21: =SUMIF($R$2:$ES$2,M$2,$R21:$ES21) -> 0 | O21: =SUM(Q21:ES21) -> 0 | P21: Construction Expenses | R21: =-'Construction Budget'!W8 -> 0 | S21: =-'Construction Budget'!X8 -> 0 | T21: =-'Construction Budget'!Y8 -> 0 | U21: =-'Construction Budget'!Z8 -> 0 | V21: =-'Construction Budget'!AA8 -> 0 | W21: =-'Construction Budget'!AB8 -> 0 | X21: =-'Construction Budget'!AC8 -> 0 | Y21: =-'Construction Budget'!AD8 -> 0 | ... ES21: =-'Construction Budget'!EX8 -> 0
B23: Partnership Expenses | P23: Partnership Expenses
A24: =SUM(C24:M24) -> 0 | B24: Asset Management Fee | D24: =SUMIF($R$2:$ES$2,D$2,$R24:$ES24) -> 0 | E24: =SUMIF($R$2:$ES$2,E$2,$R24:$ES24) -> 0 | F24: =SUMIF($R$2:$ES$2,F$2,$R24:$ES24) -> 0 | G24: =SUMIF($R$2:$ES$2,G$2,$R24:$ES24) -> 0 | H24: =SUMIF($R$2:$ES$2,H$2,$R24:$ES24) -> 0 | I24: =SUMIF($R$2:$ES$2,I$2,$R24:$ES24) -> 0 | J24: =SUMIF($R$2:$ES$2,J$2,$R24:$ES24) -> 0 | K24: =SUMIF($R$2:$ES$2,K$2,$R24:$ES24) -> 0 | ... M24: =SUMIF($R$2:$ES$2,M$2,$R24:$ES24) -> 0 | O24: =SUM(Q24:ES24) -> 0 | P24: Asset Management Fee | R24: =IF(OR(Summary!$E$22*AM_FEE/12>(R18+R41),R$3>HOLD_PERIOD),0,-Summary!$E$22*AM_FEE/12) -> 0 | S24: =IF(OR(Summary!$E$22*AM_FEE/12>(S18+S41),S$3>HOLD_PERIOD),0,-Summary!$E$22*AM_FEE/12) -> 0 | T24: =IF(OR(Summary!$E$22*AM_FEE/12>(T18+T41),T$3>HOLD_PERIOD),0,-Summary!$E$22*AM_FEE/12) -> 0 | U24: =IF(OR(Summary!$E$22*AM_FEE/12>(U18+U41),U$3>HOLD_PERIOD),0,-Summary!$E$22*AM_FEE/12) -> 0 | V24: =IF(OR(Summary!$E$22*AM_FEE/12>(V18+V41),V$3>HOLD_PERIOD),0,-Summary!$E$22*AM_FEE/12) -> 0 | W24: =IF(OR(Summary!$E$22*AM_FEE/12>(W18+W41),W$3>HOLD_PERIOD),0,-Summary!$E$22*AM_FEE/12) -> 0 | X24: =IF(OR(Summary!$E$22*AM_FEE/12>(X18+X41),X$3>HOLD_PERIOD),0,-Summary!$E$22*AM_FEE/12) -> 0 | Y24: =IF(OR(Summary!$E$22*AM_FEE/12>(Y18+Y41),Y$3>HOLD_PERIOD),0,-Summary!$E$22*AM_FEE/12) -> 0 | ... ES24: =IF(OR(Summary!$E$22*AM_FEE/12>(ES18+ES41),ES$3>HOLD_PERIOD),0,-Summary!$E$22*AM_FEE/12) -> 0
A25: =SUM(C25:M25) -> 0 | B25: Construction Management Fee | D25: =SUMIF($R$2:$ES$2,D$2,$R25:$ES25) -> 0 | E25: =SUMIF($R$2:$ES$2,E$2,$R25:$ES25) -> 0 | F25: =SUMIF($R$2:$ES$2,F$2,$R25:$ES25) -> 0 | G25: =SUMIF($R$2:$ES$2,G$2,$R25:$ES25) -> 0 | H25: =SUMIF($R$2:$ES$2,H$2,$R25:$ES25) -> 0 | I25: =SUMIF($R$2:$ES$2,I$2,$R25:$ES25) -> 0 | J25: =SUMIF($R$2:$ES$2,J$2,$R25:$ES25) -> 0 | K25: =SUMIF($R$2:$ES$2,K$2,$R25:$ES25) -> 0 | ... M25: =SUMIF($R$2:$ES$2,M$2,$R25:$ES25) -> 0 | O25: =SUM(Q25:ES25) -> 0 | P25: Construction Management Fee | R25: =R21*CM_FEE -> 0 | S25: =S21*CM_FEE -> 0 | T25: =T21*CM_FEE -> 0 | U25: =U21*CM_FEE -> 0 | V25: =V21*CM_FEE -> 0 | W25: =W21*CM_FEE -> 0 | X25: =X21*CM_FEE -> 0 | Y25: =Y21*CM_FEE -> 0 | ... ES25: =ES21*CM_FEE -> 0
B27: Acquisition Information | P27: Acquisition Information
A28: =SUM(C28:M28) -> -180000000 | B28: Purchase Price | C28: =SUMIF($Q$2:$ES$2,C$2,$Q28:$ES28) -> -180000000 | O28: =SUM(Q28:ES28) -> -180000000 | P28: Purchase Price | Q28: =-PURCH_PRICE -> -180000000
A29: =SUM(C29:M29) -> -1800000 | B29: Acquisition Fee | C29: =SUMIF($Q$2:$ES$2,C$2,$Q29:$ES29) -> -1800000 | O29: =SUM(Q29:ES29) -> -1800000 | P29: Acquisition Fee | Q29: =-ACQ_FEE -> -1800000
A30: =SUM(C30:M30) -> 0 | B30: Closing Costs | C30: =SUMIF($Q$2:$ES$2,C$2,$Q30:$ES30) -> 0 | O30: =SUM(Q30:ES30) -> 0 | P30: Closing Costs | Q30: =-CLOSING_COSTS -> 0
B32: Sale Information | P32: Sale Information
A33: =SUM(C33:M33) -> 2.2520356e+08 | B33: Sale Proceeds | D33: =SUMIF($R$2:$ES$2,D$2,$R33:$ES33) -> 0 | E33: =SUMIF($R$2:$ES$2,E$2,$R33:$ES33) -> 0 | F33: =SUMIF($R$2:$ES$2,F$2,$R33:$ES33) -> 0 | G33: =SUMIF($R$2:$ES$2,G$2,$R33:$ES33) -> 0 | H33: =SUMIF($R$2:$ES$2,H$2,$R33:$ES33) -> 2.2520356e+08 | I33: =SUMIF($R$2:$ES$2,I$2,$R33:$ES33) -> 0 | J33: =SUMIF($R$2:$ES$2,J$2,$R33:$ES33) -> 0 | K33: =SUMIF($R$2:$ES$2,K$2,$R33:$ES33) -> 0 | ... M33: =SUMIF($R$2:$ES$2,M$2,$R33:$ES33) -> 0 | O33: =SUM(Q33:ES33) -> 2.2520356e+08 | P33: Sale Proceeds | R33: =IF(R$3=HOLD_PERIOD,SUM(S14:AD14)/EXIT_CAP,0) -> 0 | S33: =IF(S$3=HOLD_PERIOD,SUM(T14:AE14)/EXIT_CAP,0) -> 0 | T33: =IF(T$3=HOLD_PERIOD,SUM(U14:AF14)/EXIT_CAP,0) -> 0 | U33: =IF(U$3=HOLD_PERIOD,SUM(V14:AG14)/EXIT_CAP,0) -> 0 | V33: =IF(V$3=HOLD_PERIOD,SUM(W14:AH14)/EXIT_CAP,0) -> 0 | W33: =IF(W$3=HOLD_PERIOD,SUM(X14:AI14)/EXIT_CAP,0) -> 0 | X33: =IF(X$3=HOLD_PERIOD,SUM(Y14:AJ14)/EXIT_CAP,0) -> 0 | Y33: =IF(Y$3=HOLD_PERIOD,SUM(Z14:AK14)/EXIT_CAP,0) -> 0 | ... ES33: =IF(ES$3=HOLD_PERIOD,SUM(ET14:FE14)/EXIT_CAP,0) -> 0
A34: =SUM(C34:M34) -> -2252035.6 | B34: Costs of Sale | D34: =SUMIF($R$2:$ES$2,D$2,$R34:$ES34) -> 0 | E34: =SUMIF($R$2:$ES$2,E$2,$R34:$ES34) -> 0 | F34: =SUMIF($R$2:$ES$2,F$2,$R34:$ES34) -> 0 | G34: =SUMIF($R$2:$ES$2,G$2,$R34:$ES34) -> 0 | H34: =SUMIF($R$2:$ES$2,H$2,$R34:$ES34) -> -2252035.6 | I34: =SUMIF($R$2:$ES$2,I$2,$R34:$ES34) -> 0 | J34: =SUMIF($R$2:$ES$2,J$2,$R34:$ES34) -> 0 | K34: =SUMIF($R$2:$ES$2,K$2,$R34:$ES34) -> 0 | ... M34: =SUMIF($R$2:$ES$2,M$2,$R34:$ES34) -> 0 | O34: =SUM(Q34:ES34) -> -2252035.6 | P34: Costs of Sale | R34: =R33*-COSTS_OF_SALE -> 0 | S34: =S33*-COSTS_OF_SALE -> 0 | T34: =T33*-COSTS_OF_SALE -> 0 | U34: =U33*-COSTS_OF_SALE -> 0 | V34: =V33*-COSTS_OF_SALE -> 0 | W34: =W33*-COSTS_OF_SALE -> 0 | X34: =X33*-COSTS_OF_SALE -> 0 | Y34: =Y33*-COSTS_OF_SALE -> 0 | ... ES34: =ES33*-COSTS_OF_SALE -> 0
A36: =SUM(C36:M36) -> 91669581 | B36: Total Unlevered Cash Flow | C36: =SUMIF($Q$2:$ES$2,C$2,$Q36:$ES36) -> -181800000 | D36: =SUMIF($R$2:$ES$2,D$2,$R36:$ES36) -> 4971115 | E36: =SUMIF($R$2:$ES$2,E$2,$R36:$ES36) -> 9767555 | F36: =SUMIF($R$2:$ES$2,F$2,$R36:$ES36) -> 11101594 | G36: =SUMIF($R$2:$ES$2,G$2,$R36:$ES36) -> 12077096 | H36: =SUMIF($R$2:$ES$2,H$2,$R36:$ES36) -> 2.3555222e+08 | I36: =SUMIF($R$2:$ES$2,I$2,$R36:$ES36) -> 0 | J36: =SUMIF($R$2:$ES$2,J$2,$R36:$ES36) -> 0 | K36: =SUMIF($R$2:$ES$2,K$2,$R36:$ES36) -> 0 | ... M36: =SUMIF($R$2:$ES$2,M$2,$R36:$ES36) -> 0 | O36: =SUM(Q36:ES36) -> 91669581 | P36: Total Unlevered Cash Flow | Q36: =SUM(Q18:Q34) -> -181800000 | R36: =SUM(R18:R34) -> 425186.9 | S36: =SUM(S18:S34) -> 425186.9 | T36: =SUM(T18:T34) -> 425379.83 | U36: =SUM(U18:U34) -> 425775.99 | V36: =SUM(V18:V34) -> 416993.07 | W36: =SUM(W18:W34) -> 303413.34 | X36: =SUM(X18:X34) -> 418452.77 | ... ES36: =SUM(ES18:ES34) -> 0
B38: Loan Information | P38: Loan Information
A39: =SUM(C39:M39) -> 1.26e+08 | B39: Acquisition Loan/Refinance Proceeds | C39: =SUMIF($Q$2:$ES$2,C$2,$Q39:$ES39) -> 1.26e+08 | D39: =SUMIF($R$2:$ES$2,D$2,$R39:$ES39) -> 0 | E39: =SUMIF($R$2:$ES$2,E$2,$R39:$ES39) -> 0 | F39: =SUMIF($R$2:$ES$2,F$2,$R39:$ES39) -> 0 | G39: =SUMIF($R$2:$ES$2,G$2,$R39:$ES39) -> 0 | H39: =SUMIF($R$2:$ES$2,H$2,$R39:$ES39) -> 0 | I39: =SUMIF($R$2:$ES$2,I$2,$R39:$ES39) -> 0 | J39: =SUMIF($R$2:$ES$2,J$2,$R39:$ES39) -> 0 | K39: =SUMIF($R$2:$ES$2,K$2,$R39:$ES39) -> 0 | ... M39: =SUMIF($R$2:$ES$2,M$2,$R39:$ES39) -> 0 | O39: =SUM(Q39:ES39) -> 1.26e+08 | P39: Acquisition Loan/Refinance Proceeds | Q39: =Financing!D3+Financing!E3 -> 1.26e+08 | R39: =IF(R$3>=HOLD_PERIOD,0,IF(R$3=ACQ_LOAN_TERM,Financing!$F$3,0)) -> 0 | S39: =IF(S$3>=HOLD_PERIOD,0,IF(S$3=ACQ_LOAN_TERM,Financing!$F$3,0)) -> 0 | T39: =IF(T$3>=HOLD_PERIOD,0,IF(T$3=ACQ_LOAN_TERM,Financing!$F$3,0)) -> 0 | U39: =IF(U$3>=HOLD_PERIOD,0,IF(U$3=ACQ_LOAN_TERM,Financing!$F$3,0)) -> 0 | V39: =IF(V$3>=HOLD_PERIOD,0,IF(V$3=ACQ_LOAN_TERM,Financing!$F$3,0)) -> 0 | W39: =IF(W$3>=HOLD_PERIOD,0,IF(W$3=ACQ_LOAN_TERM,Financing!$F$3,0)) -> 0 | X39: =IF(X$3>=HOLD_PERIOD,0,IF(X$3=ACQ_LOAN_TERM,Financing!$F$3,0)) -> 0 | Y39: =IF(Y$3>=HOLD_PERIOD,0,IF(Y$3=ACQ_LOAN_TERM,Financing!$F$3,0)) -> 0 | ... ES39: =IF(ES$3>=HOLD_PERIOD,0,IF(ES$3=ACQ_LOAN_TERM,Financing!$F$3,0)) -> 0
A40: =SUM(C40:M40) -> 0 | B40: Additional Loan Proceeds | D40: =SUMIF($R$2:$ES$2,D$2,$R40:$ES40) -> 0 | E40: =SUMIF($R$2:$ES$2,E$2,$R40:$ES40) -> 0 | F40: =SUMIF($R$2:$ES$2,F$2,$R40:$ES40) -> 0 | G40: =SUMIF($R$2:$ES$2,G$2,$R40:$ES40) -> 0 | H40: =SUMIF($R$2:$ES$2,H$2,$R40:$ES40) -> 0 | I40: =SUMIF($R$2:$ES$2,I$2,$R40:$ES40) -> 0 | J40: =SUMIF($R$2:$ES$2,J$2,$R40:$ES40) -> 0 | K40: =SUMIF($R$2:$ES$2,K$2,$R40:$ES40) -> 0 | ... M40: =SUMIF($R$2:$ES$2,M$2,$R40:$ES40) -> 0 | O40: =SUM(Q40:ES40) -> 0 | P40: Additional Loan Proceeds | R40: =SUMIF(Financing!$A:$A,"ALP",Financing!D:D) -> 0 | S40: =SUMIF(Financing!$A:$A,"ALP",Financing!E:E) -> 0 | T40: =SUMIF(Financing!$A:$A,"ALP",Financing!F:F) -> 0 | U40: =SUMIF(Financing!$A:$A,"ALP",Financing!G:G) -> 0 | V40: =SUMIF(Financing!$A:$A,"ALP",Financing!H:H) -> 0 | W40: =SUMIF(Financing!$A:$A,"ALP",Financing!I:I) -> 0 | X40: =SUMIF(Financing!$A:$A,"ALP",Financing!J:J) -> 0 | Y40: =SUMIF(Financing!$A:$A,"ALP",Financing!K:K) -> 0 | Z40: =SUMIF(Financing!$A:$A,"ALP",Financing!L:L) -> 0 | AA40: =SUMIF(Financing!$A:$A,"ALP",Financing!M:M) -> 0 | AB40: =SUMIF(Financing!$A:$A,"ALP",Financing!N:N) -> 0 | AC40: =SUMIF(Financing!$A:$A,"ALP",Financing!O:O) -> 0 | AD40: =SUMIF(Financing!$A:$A,"ALP",Financing!P:P) -> 0 | AE40: =SUMIF(Financing!$A:$A,"ALP",Financing!Q:Q) -> 0 | AF40: =SUMIF(Financing!$A:$A,"ALP",Financing!R:R) -> 0 | AG40: =SUMIF(Financing!$A:$A,"ALP",Financing!S:S) -> 0 | AH40: =SUMIF(Financing!$A:$A,"ALP",Financing!T:T) -> 0 | AI40: =SUMIF(Financing!$A:$A,"ALP",Financing!U:U) -> 0 | AJ40: =SUMIF(Financing!$A:$A,"ALP",Financing!V:V) -> 0 | AK40: =SUMIF(Financing!$A:$A,"ALP",Financing!W:W) -> 0 | AL40: =SUMIF(Financing!$A:$A,"ALP",Financing!X:X) -> 0 | AM40: =SUMIF(Financing!$A:$A,"ALP",Financing!Y:Y) -> 0 | AN40: =SUMIF(Financing!$A:$A,"ALP",Financing!Z:Z) -> 0 | AO40: =SUMIF(Financing!$A:$A,"ALP",Financing!AA:AA) -> 0 | AP40: =SUMIF(Financing!$A:$A,"ALP",Financing!AB:AB) -> 0 | AQ40: =SUMIF(Financing!$A:$A,"ALP",Financing!AC:AC) -> 0 | AR40: =SUMIF(Financing!$A:$A,"ALP",Financing!AD:AD) -> 0 | AS40: =SUMIF(Financing!$A:$A,"ALP",Financing!AE:AE) -> 0 | AT40: =SUMIF(Financing!$A:$A,"ALP",Financing!AF:AF) -> 0 | AU40: =SUMIF(Financing!$A:$A,"ALP",Financing!AG:AG) -> 0 | AV40: =SUMIF(Financing!$A:$A,"ALP",Financing!AH:AH) -> 0 | AW40: =SUMIF(Financing!$A:$A,"ALP",Financing!AI:AI) -> 0 | AX40: =SUMIF(Financing!$A:$A,"ALP",Financing!AJ:AJ) -> 0 | AY40: =SUMIF(Financing!$A:$A,"ALP",Financing!AK:AK) -> 0 | AZ40: =SUMIF(Financing!$A:$A,"ALP",Financing!AL:AL) -> 0 | BA40: =SUMIF(Financing!$A:$A,"ALP",Financing!AM:AM) -> 0 | BB40: =SUMIF(Financing!$A:$A,"ALP",Financing!AN:AN) -> 0 | BC40: =SUMIF(Financing!$A:$A,"ALP",Financing!AO:AO) -> 0 | BD40: =SUMIF(Financing!$A:$A,"ALP",Financing!AP:AP) -> 0 | BE40: =SUMIF(Financing!$A:$A,"ALP",Financing!AQ:AQ) -> 0 | BF40: =SUMIF(Financing!$A:$A,"ALP",Financing!AR:AR) -> 0 | BG40: =SUMIF(Financing!$A:$A,"ALP",Financing!AS:AS) -> 0 | BH40: =SUMIF(Financing!$A:$A,"ALP",Financing!AT:AT) -> 0 | BI40: =SUMIF(Financing!$A:$A,"ALP",Financing!AU:AU) -> 0 | BJ40: =SUMIF(Financing!$A:$A,"ALP",Financing!AV:AV) -> 0 | BK40: =SUMIF(Financing!$A:$A,"ALP",Financing!AW:AW) -> 0 | BL40: =SUMIF(Financing!$A:$A,"ALP",Financing!AX:AX) -> 0 | BM40: =SUMIF(Financing!$A:$A,"ALP",Financing!AY:AY) -> 0 | BN40: =SUMIF(Financing!$A:$A,"ALP",Financing!AZ:AZ) -> 0 | BO40: =SUMIF(Financing!$A:$A,"ALP",Financing!BA:BA) -> 0 | BP40: =SUMIF(Financing!$A:$A,"ALP",Financing!BB:BB) -> 0 | BQ40: =SUMIF(Financing!$A:$A,"ALP",Financing!BC:BC) -> 0 | BR40: =SUMIF(Financing!$A:$A,"ALP",Financing!BD:BD) -> 0 | BS40: =SUMIF(Financing!$A:$A,"ALP",Financing!BE:BE) -> 0 | BT40: =SUMIF(Financing!$A:$A,"ALP",Financing!BF:BF) -> 0 | BU40: =SUMIF(Financing!$A:$A,"ALP",Financing!BG:BG) -> 0 | BV40: =SUMIF(Financing!$A:$A,"ALP",Financing!BH:BH) -> 0 | BW40: =SUMIF(Financing!$A:$A,"ALP",Financing!BI:BI) -> 0 | BX40: =SUMIF(Financing!$A:$A,"ALP",Financing!BJ:BJ) -> 0 | BY40: =SUMIF(Financing!$A:$A,"ALP",Financing!BK:BK) -> 0 | BZ40: =SUMIF(Financing!$A:$A,"ALP",Financing!BL:BL) -> 0 | CA40: =SUMIF(Financing!$A:$A,"ALP",Financing!BM:BM) -> 0 | CB40: =SUMIF(Financing!$A:$A,"ALP",Financing!BN:BN) -> 0 | CC40: =SUMIF(Financing!$A:$A,"ALP",Financing!BO:BO) -> 0 | CD40: =SUMIF(Financing!$A:$A,"ALP",Financing!BP:BP) -> 0 | CE40: =SUMIF(Financing!$A:$A,"ALP",Financing!BQ:BQ) -> 0 | CF40: =SUMIF(Financing!$A:$A,"ALP",Financing!BR:BR) -> 0 | CG40: =SUMIF(Financing!$A:$A,"ALP",Financing!BS:BS) -> 0 | CH40: =SUMIF(Financing!$A:$A,"ALP",Financing!BT:BT) -> 0 | CI40: =SUMIF(Financing!$A:$A,"ALP",Financing!BU:BU) -> 0 | CJ40: =SUMIF(Financing!$A:$A,"ALP",Financing!BV:BV) -> 0 | CK40: =SUMIF(Financing!$A:$A,"ALP",Financing!BW:BW) -> 0 | CL40: =SUMIF(Financing!$A:$A,"ALP",Financing!BX:BX) -> 0 | CM40: =SUMIF(Financing!$A:$A,"ALP",Financing!BY:BY) -> 0 | CN40: =SUMIF(Financing!$A:$A,"ALP",Financing!BZ:BZ) -> 0 | CO40: =SUMIF(Financing!$A:$A,"ALP",Financing!CA:CA) -> 0 | CP40: =SUMIF(Financing!$A:$A,"ALP",Financing!CB:CB) -> 0 | CQ40: =SUMIF(Financing!$A:$A,"ALP",Financing!CC:CC) -> 0 | CR40: =SUMIF(Financing!$A:$A,"ALP",Financing!CD:CD) -> 0 | CS40: =SUMIF(Financing!$A:$A,"ALP",Financing!CE:CE) -> 0 | CT40: =SUMIF(Financing!$A:$A,"ALP",Financing!CF:CF) -> 0 | CU40: =SUMIF(Financing!$A:$A,"ALP",Financing!CG:CG) -> 0 | CV40: =SUMIF(Financing!$A:$A,"ALP",Financing!CH:CH) -> 0 | CW40: =SUMIF(Financing!$A:$A,"ALP",Financing!CI:CI) -> 0 | CX40: =SUMIF(Financing!$A:$A,"ALP",Financing!CJ:CJ) -> 0 | CY40: =SUMIF(Financing!$A:$A,"ALP",Financing!CK:CK) -> 0 | CZ40: =SUMIF(Financing!$A:$A,"ALP",Financing!CL:CL) -> 0 | DA40: =SUMIF(Financing!$A:$A,"ALP",Financing!CM:CM) -> 0 | DB40: =SUMIF(Financing!$A:$A,"ALP",Financing!CN:CN) -> 0 | DC40: =SUMIF(Financing!$A:$A,"ALP",Financing!CO:CO) -> 0 | DD40: =SUMIF(Financing!$A:$A,"ALP",Financing!CP:CP) -> 0 | DE40: =SUMIF(Financing!$A:$A,"ALP",Financing!CQ:CQ) -> 0 | DF40: =SUMIF(Financing!$A:$A,"ALP",Financing!CR:CR) -> 0 | DG40: =SUMIF(Financing!$A:$A,"ALP",Financing!CS:CS) -> 0 | DH40: =SUMIF(Financing!$A:$A,"ALP",Financing!CT:CT) -> 0 | DI40: =SUMIF(Financing!$A:$A,"ALP",Financing!CU:CU) -> 0 | DJ40: =SUMIF(Financing!$A:$A,"ALP",Financing!CV:CV) -> 0 | DK40: =SUMIF(Financing!$A:$A,"ALP",Financing!CW:CW) -> 0 | DL40: =SUMIF(Financing!$A:$A,"ALP",Financing!CX:CX) -> 0 | DM40: =SUMIF(Financing!$A:$A,"ALP",Financing!CY:CY) -> 0 | DN40: =SUMIF(Financing!$A:$A,"ALP",Financing!CZ:CZ) -> 0 | DO40: =SUMIF(Financing!$A:$A,"ALP",Financing!DA:DA) -> 0 | DP40: =SUMIF(Financing!$A:$A,"ALP",Financing!DB:DB) -> 0 | DQ40: =SUMIF(Financing!$A:$A,"ALP",Financing!DC:DC) -> 0 | DR40: =SUMIF(Financing!$A:$A,"ALP",Financing!DD:DD) -> 0 | DS40: =SUMIF(Financing!$A:$A,"ALP",Financing!DE:DE) -> 0 | DT40: =SUMIF(Financing!$A:$A,"ALP",Financing!DF:DF) -> 0 | DU40: =SUMIF(Financing!$A:$A,"ALP",Financing!DG:DG) -> 0 | DV40: =SUMIF(Financing!$A:$A,"ALP",Financing!DH:DH) -> 0 | DW40: =SUMIF(Financing!$A:$A,"ALP",Financing!DI:DI) -> 0 | DX40: =SUMIF(Financing!$A:$A,"ALP",Financing!DJ:DJ) -> 0 | DY40: =SUMIF(Financing!$A:$A,"ALP",Financing!DK:DK) -> 0 | DZ40: =SUMIF(Financing!$A:$A,"ALP",Financing!DL:DL) -> 0 | EA40: =SUMIF(Financing!$A:$A,"ALP",Financing!DM:DM) -> 0 | EB40: =SUMIF(Financing!$A:$A,"ALP",Financing!DN:DN) -> 0 | EC40: =SUMIF(Financing!$A:$A,"ALP",Financing!DO:DO) -> 0 | ED40: =SUMIF(Financing!$A:$A,"ALP",Financing!DP:DP) -> 0 | EE40: =SUMIF(Financing!$A:$A,"ALP",Financing!DQ:DQ) -> 0 | EF40: =SUMIF(Financing!$A:$A,"ALP",Financing!DR:DR) -> 0 | EG40: =SUMIF(Financing!$A:$A,"ALP",Financing!DS:DS) -> 0 | EH40: =SUMIF(Financing!$A:$A,"ALP",Financing!DT:DT) -> 0 | EI40: =SUMIF(Financing!$A:$A,"ALP",Financing!DU:DU) -> 0 | EJ40: =SUMIF(Financing!$A:$A,"ALP",Financing!DV:DV) -> 0 | EK40: =SUMIF(Financing!$A:$A,"ALP",Financing!DW:DW) -> 0 | EL40: =SUMIF(Financing!$A:$A,"ALP",Financing!DX:DX) -> 0 | EM40: =SUMIF(Financing!$A:$A,"ALP",Financing!DY:DY) -> 0 | EN40: =SUMIF(Financing!$A:$A,"ALP",Financing!DZ:DZ) -> 0 | EO40: =SUMIF(Financing!$A:$A,"ALP",Financing!EA:EA) -> 0 | EP40: =SUMIF(Financing!$A:$A,"ALP",Financing!EB:EB) -> 0 | EQ40: =SUMIF(Financing!$A:$A,"ALP",Financing!EC:EC) -> 0 | ER40: =SUMIF(Financing!$A:$A,"ALP",Financing!ED:ED) -> 0 | ES40: =SUMIF(Financing!$A:$A,"ALP",Financing!EE:EE) -> 0
A41: =SUM(C41:M41) -> -38837452 | B41: Debt Service | D41: =SUMIF($R$2:$ES$2,D$2,$R41:$ES41) -> -6667068.5 | E41: =SUMIF($R$2:$ES$2,E$2,$R41:$ES41) -> -6908842.5 | F41: =SUMIF($R$2:$ES$2,F$2,$R41:$ES41) -> -7160690.2 | G41: =SUMIF($R$2:$ES$2,G$2,$R41:$ES41) -> -8958827.1 | H41: =SUMIF($R$2:$ES$2,H$2,$R41:$ES41) -> -9142023.5 | I41: =SUMIF($R$2:$ES$2,I$2,$R41:$ES41) -> 0 | J41: =SUMIF($R$2:$ES$2,J$2,$R41:$ES41) -> 0 | K41: =SUMIF($R$2:$ES$2,K$2,$R41:$ES41) -> 0 | ... M41: =SUMIF($R$2:$ES$2,M$2,$R41:$ES41) -> 0 | O41: =SUM(Q41:ES41) -> -38837452 | P41: Debt Service | R41: =-SUMIF(Financing!$A:$A,"TLP",Financing!D:D) -> -547212.75 | S41: =-SUMIF(Financing!$A:$A,"TLP",Financing!E:E) -> -548530.5 | T41: =-SUMIF(Financing!$A:$A,"TLP",Financing!F:F) -> -549777.9 | U41: =-SUMIF(Financing!$A:$A,"TLP",Financing!G:G) -> -551220.6 | V41: =-SUMIF(Financing!$A:$A,"TLP",Financing!H:H) -> -552754.65 | W41: =-SUMIF(Financing!$A:$A,"TLP",Financing!I:I) -> -554317.05 | X41: =-SUMIF(Financing!$A:$A,"TLP",Financing!J:J) -> -556021.2 | Y41: =-SUMIF(Financing!$A:$A,"TLP",Financing!K:K) -> -557821.95 | Z41: =-SUMIF(Financing!$A:$A,"TLP",Financing!L:L) -> -559545 | AA41: =-SUMIF(Financing!$A:$A,"TLP",Financing!M:M) -> -561516.9 | AB41: =-SUMIF(Financing!$A:$A,"TLP",Financing!N:N) -> -563372.25 | AC41: =-SUMIF(Financing!$A:$A,"TLP",Financing!O:O) -> -564977.7 | AD41: =-SUMIF(Financing!$A:$A,"TLP",Financing!P:P) -> -566658.75 | AE41: =-SUMIF(Financing!$A:$A,"TLP",Financing!Q:Q) -> -568383.9 | AF41: =-SUMIF(Financing!$A:$A,"TLP",Financing!R:R) -> -569975.7 | AG41: =-SUMIF(Financing!$A:$A,"TLP",Financing!S:S) -> -571643.1 | AH41: =-SUMIF(Financing!$A:$A,"TLP",Financing!T:T) -> -573243.3 | AI41: =-SUMIF(Financing!$A:$A,"TLP",Financing!U:U) -> -574877.1 | AJ41: =-SUMIF(Financing!$A:$A,"TLP",Financing!V:V) -> -576630.6 | AK41: =-SUMIF(Financing!$A:$A,"TLP",Financing!W:W) -> -578175.15 | AL41: =-SUMIF(Financing!$A:$A,"TLP",Financing!X:X) -> -579852 | AM41: =-SUMIF(Financing!$A:$A,"TLP",Financing!Y:Y) -> -581632.8 | AN41: =-SUMIF(Financing!$A:$A,"TLP",Financing!Z:Z) -> -583005.15 | AO41: =-SUMIF(Financing!$A:$A,"TLP",Financing!AA:AA) -> -584764.95 | AP41: =-SUMIF(Financing!$A:$A,"TLP",Financing!AB:AB) -> -586662.3 | AQ41: =-SUMIF(Financing!$A:$A,"TLP",Financing!AC:AC) -> -588354.9 | AR41: =-SUMIF(Financing!$A:$A,"TLP",Financing!AD:AD) -> -590177.7 | AS41: =-SUMIF(Financing!$A:$A,"TLP",Financing!AE:AE) -> -592111.8 | AT41: =-SUMIF(Financing!$A:$A,"TLP",Financing!AF:AF) -> -593865.3 | AU41: =-SUMIF(Financing!$A:$A,"TLP",Financing!AG:AG) -> -595726.95 | AV41: =-SUMIF(Financing!$A:$A,"TLP",Financing!AH:AH) -> -597603.3 | AW41: =-SUMIF(Financing!$A:$A,"TLP",Financing!AI:AI) -> -599473.35 | AX41: =-SUMIF(Financing!$A:$A,"TLP",Financing!AJ:AJ) -> -601533.45 | AY41: =-SUMIF(Financing!$A:$A,"TLP",Financing!AK:AK) -> -603247.05 | AZ41: =-SUMIF(Financing!$A:$A,"TLP",Financing!AL:AL) -> -605041.5 | BA41: =-SUMIF(Financing!$A:$A,"TLP",Financing!AM:AM) -> -606892.65 | BB41: =-SUMIF(Financing!$A:$A,"TLP",Financing!AN:AN) -> -739145.95 | BC41: =-SUMIF(Financing!$A:$A,"TLP",Financing!AO:AO) -> -740493.52 | BD41: =-SUMIF(Financing!$A:$A,"TLP",Financing!AP:AP) -> -741873.37 | BE41: =-SUMIF(Financing!$A:$A,"TLP",Financing!AQ:AQ) -> -743265.44 | BF41: =-SUMIF(Financing!$A:$A,"TLP",Financing!AR:AR) -> -744586.61 | BG41: =-SUMIF(Financing!$A:$A,"TLP",Financing!AS:AS) -> -746022.95 | BH41: =-SUMIF(Financing!$A:$A,"TLP",Financing!AT:AT) -> -747272.07 | BI41: =-SUMIF(Financing!$A:$A,"TLP",Financing!AU:AU) -> -748599.48 | BJ41: =-SUMIF(Financing!$A:$A,"TLP",Financing!AV:AV) -> -749957.31 | BK41: =-SUMIF(Financing!$A:$A,"TLP",Financing!AW:AW) -> -751240.6 | BL41: =-SUMIF(Financing!$A:$A,"TLP",Financing!AX:AX) -> -752501.82 | BM41: =-SUMIF(Financing!$A:$A,"TLP",Financing!AY:AY) -> -753867.93 | BN41: =-SUMIF(Financing!$A:$A,"TLP",Financing!AZ:AZ) -> -755059.06 | BO41: =-SUMIF(Financing!$A:$A,"TLP",Financing!BA:BA) -> -756319.23 | BP41: =-SUMIF(Financing!$A:$A,"TLP",Financing!BB:BB) -> -757655.44 | BQ41: =-SUMIF(Financing!$A:$A,"TLP",Financing!BC:BC) -> -758833.83 | BR41: =-SUMIF(Financing!$A:$A,"TLP",Financing!BD:BD) -> -760017.91 | BS41: =-SUMIF(Financing!$A:$A,"TLP",Financing!BE:BE) -> -761318.72 | BT41: =-SUMIF(Financing!$A:$A,"TLP",Financing!BF:BF) -> -762441.8 | BU41: =-SUMIF(Financing!$A:$A,"TLP",Financing!BG:BG) -> -763641.27 | BV41: =-SUMIF(Financing!$A:$A,"TLP",Financing!BH:BH) -> -764821.23 | BW41: =-SUMIF(Financing!$A:$A,"TLP",Financing!BI:BI) -> -766012.27 | BX41: =-SUMIF(Financing!$A:$A,"TLP",Financing!BJ:BJ) -> -767359.21 | BY41: =-SUMIF(Financing!$A:$A,"TLP",Financing!BK:BK) -> -768543.51 | BZ41: =-SUMIF(Financing!$A:$A,"TLP",Financing!BL:BL) -> 0 | CA41: =-SUMIF(Financing!$A:$A,"TLP",Financing!BM:BM) -> 0 | CB41: =-SUMIF(Financing!$A:$A,"TLP",Financing!BN:BN) -> 0 | CC41: =-SUMIF(Financing!$A:$A,"TLP",Financing!BO:BO) -> 0 | CD41: =-SUMIF(Financing!$A:$A,"TLP",Financing!BP:BP) -> 0 | CE41: =-SUMIF(Financing!$A:$A,"TLP",Financing!BQ:BQ) -> 0 | CF41: =-SUMIF(Financing!$A:$A,"TLP",Financing!BR:BR) -> 0 | CG41: =-SUMIF(Financing!$A:$A,"TLP",Financing!BS:BS) -> 0 | CH41: =-SUMIF(Financing!$A:$A,"TLP",Financing!BT:BT) -> 0 | CI41: =-SUMIF(Financing!$A:$A,"TLP",Financing!BU:BU) -> 0 | CJ41: =-SUMIF(Financing!$A:$A,"TLP",Financing!BV:BV) -> 0 | CK41: =-SUMIF(Financing!$A:$A,"TLP",Financing!BW:BW) -> 0 | CL41: =-SUMIF(Financing!$A:$A,"TLP",Financing!BX:BX) -> 0 | CM41: =-SUMIF(Financing!$A:$A,"TLP",Financing!BY:BY) -> 0 | CN41: =-SUMIF(Financing!$A:$A,"TLP",Financing!BZ:BZ) -> 0 | CO41: =-SUMIF(Financing!$A:$A,"TLP",Financing!CA:CA) -> 0 | CP41: =-SUMIF(Financing!$A:$A,"TLP",Financing!CB:CB) -> 0 | CQ41: =-SUMIF(Financing!$A:$A,"TLP",Financing!CC:CC) -> 0 | CR41: =-SUMIF(Financing!$A:$A,"TLP",Financing!CD:CD) -> 0 | CS41: =-SUMIF(Financing!$A:$A,"TLP",Financing!CE:CE) -> 0 | CT41: =-SUMIF(Financing!$A:$A,"TLP",Financing!CF:CF) -> 0 | CU41: =-SUMIF(Financing!$A:$A,"TLP",Financing!CG:CG) -> 0 | CV41: =-SUMIF(Financing!$A:$A,"TLP",Financing!CH:CH) -> 0 | CW41: =-SUMIF(Financing!$A:$A,"TLP",Financing!CI:CI) -> 0 | CX41: =-SUMIF(Financing!$A:$A,"TLP",Financing!CJ:CJ) -> 0 | CY41: =-SUMIF(Financing!$A:$A,"TLP",Financing!CK:CK) -> 0 | CZ41: =-SUMIF(Financing!$A:$A,"TLP",Financing!CL:CL) -> 0 | DA41: =-SUMIF(Financing!$A:$A,"TLP",Financing!CM:CM) -> 0 | DB41: =-SUMIF(Financing!$A:$A,"TLP",Financing!CN:CN) -> 0 | DC41: =-SUMIF(Financing!$A:$A,"TLP",Financing!CO:CO) -> 0 | DD41: =-SUMIF(Financing!$A:$A,"TLP",Financing!CP:CP) -> 0 | DE41: =-SUMIF(Financing!$A:$A,"TLP",Financing!CQ:CQ) -> 0 | DF41: =-SUMIF(Financing!$A:$A,"TLP",Financing!CR:CR) -> 0 | DG41: =-SUMIF(Financing!$A:$A,"TLP",Financing!CS:CS) -> 0 | DH41: =-SUMIF(Financing!$A:$A,"TLP",Financing!CT:CT) -> 0 | DI41: =-SUMIF(Financing!$A:$A,"TLP",Financing!CU:CU) -> 0 | DJ41: =-SUMIF(Financing!$A:$A,"TLP",Financing!CV:CV) -> 0 | DK41: =-SUMIF(Financing!$A:$A,"TLP",Financing!CW:CW) -> 0 | DL41: =-SUMIF(Financing!$A:$A,"TLP",Financing!CX:CX) -> 0 | DM41: =-SUMIF(Financing!$A:$A,"TLP",Financing!CY:CY) -> 0 | DN41: =-SUMIF(Financing!$A:$A,"TLP",Financing!CZ:CZ) -> 0 | DO41: =-SUMIF(Financing!$A:$A,"TLP",Financing!DA:DA) -> 0 | DP41: =-SUMIF(Financing!$A:$A,"TLP",Financing!DB:DB) -> 0 | DQ41: =-SUMIF(Financing!$A:$A,"TLP",Financing!DC:DC) -> 0 | DR41: =-SUMIF(Financing!$A:$A,"TLP",Financing!DD:DD) -> 0 | DS41: =-SUMIF(Financing!$A:$A,"TLP",Financing!DE:DE) -> 0 | DT41: =-SUMIF(Financing!$A:$A,"TLP",Financing!DF:DF) -> 0 | DU41: =-SUMIF(Financing!$A:$A,"TLP",Financing!DG:DG) -> 0 | DV41: =-SUMIF(Financing!$A:$A,"TLP",Financing!DH:DH) -> 0 | DW41: =-SUMIF(Financing!$A:$A,"TLP",Financing!DI:DI) -> 0 | DX41: =-SUMIF(Financing!$A:$A,"TLP",Financing!DJ:DJ) -> 0 | DY41: =-SUMIF(Financing!$A:$A,"TLP",Financing!DK:DK) -> 0 | DZ41: =-SUMIF(Financing!$A:$A,"TLP",Financing!DL:DL) -> 0 | EA41: =-SUMIF(Financing!$A:$A,"TLP",Financing!DM:DM) -> 0 | EB41: =-SUMIF(Financing!$A:$A,"TLP",Financing!DN:DN) -> 0 | EC41: =-SUMIF(Financing!$A:$A,"TLP",Financing!DO:DO) -> 0 | ED41: =-SUMIF(Financing!$A:$A,"TLP",Financing!DP:DP) -> 0 | EE41: =-SUMIF(Financing!$A:$A,"TLP",Financing!DQ:DQ) -> 0 | EF41: =-SUMIF(Financing!$A:$A,"TLP",Financing!DR:DR) -> 0 | EG41: =-SUMIF(Financing!$A:$A,"TLP",Financing!DS:DS) -> 0 | EH41: =-SUMIF(Financing!$A:$A,"TLP",Financing!DT:DT) -> 0 | EI41: =-SUMIF(Financing!$A:$A,"TLP",Financing!DU:DU) -> 0 | EJ41: =-SUMIF(Financing!$A:$A,"TLP",Financing!DV:DV) -> 0 | EK41: =-SUMIF(Financing!$A:$A,"TLP",Financing!DW:DW) -> 0 | EL41: =-SUMIF(Financing!$A:$A,"TLP",Financing!DX:DX) -> 0 | EM41: =-SUMIF(Financing!$A:$A,"TLP",Financing!DY:DY) -> 0 | EN41: =-SUMIF(Financing!$A:$A,"TLP",Financing!DZ:DZ) -> 0 | EO41: =-SUMIF(Financing!$A:$A,"TLP",Financing!EA:EA) -> 0 | EP41: =-SUMIF(Financing!$A:$A,"TLP",Financing!EB:EB) -> 0 | EQ41: =-SUMIF(Financing!$A:$A,"TLP",Financing!EC:EC) -> 0 | ER41: =-SUMIF(Financing!$A:$A,"TLP",Financing!ED:ED) -> 0 | ES41: =-SUMIF(Financing!$A:$A,"TLP",Financing!EE:EE) -> 0
A42: =SUM(C42:M42) -> -1.2280324e+08 | B42: Loan Payoff | D42: =SUMIF($R$2:$ES$2,D$2,$R42:$ES42) -> 0 | E42: =SUMIF($R$2:$ES$2,E$2,$R42:$ES42) -> 0 | F42: =SUMIF($R$2:$ES$2,F$2,$R42:$ES42) -> 0 | G42: =SUMIF($R$2:$ES$2,G$2,$R42:$ES42) -> 0 | H42: =SUMIF($R$2:$ES$2,H$2,$R42:$ES42) -> -1.2280324e+08 | I42: =SUMIF($R$2:$ES$2,I$2,$R42:$ES42) -> 0 | J42: =SUMIF($R$2:$ES$2,J$2,$R42:$ES42) -> 0 | K42: =SUMIF($R$2:$ES$2,K$2,$R42:$ES42) -> 0 | ... M42: =SUMIF($R$2:$ES$2,M$2,$R42:$ES42) -> 0 | O42: =SUM(Q42:ES42) -> -1.2280324e+08 | P42: Loan Payoff | R42: =SUMIF(Financing!$A:$A,"LP",Financing!D:D) -> 0 | S42: =SUMIF(Financing!$A:$A,"LP",Financing!E:E) -> 0 | T42: =SUMIF(Financing!$A:$A,"LP",Financing!F:F) -> 0 | U42: =SUMIF(Financing!$A:$A,"LP",Financing!G:G) -> 0 | V42: =SUMIF(Financing!$A:$A,"LP",Financing!H:H) -> 0 | W42: =SUMIF(Financing!$A:$A,"LP",Financing!I:I) -> 0 | X42: =SUMIF(Financing!$A:$A,"LP",Financing!J:J) -> 0 | Y42: =SUMIF(Financing!$A:$A,"LP",Financing!K:K) -> 0 | Z42: =SUMIF(Financing!$A:$A,"LP",Financing!L:L) -> 0 | AA42: =SUMIF(Financing!$A:$A,"LP",Financing!M:M) -> 0 | AB42: =SUMIF(Financing!$A:$A,"LP",Financing!N:N) -> 0 | AC42: =SUMIF(Financing!$A:$A,"LP",Financing!O:O) -> 0 | AD42: =SUMIF(Financing!$A:$A,"LP",Financing!P:P) -> 0 | AE42: =SUMIF(Financing!$A:$A,"LP",Financing!Q:Q) -> 0 | AF42: =SUMIF(Financing!$A:$A,"LP",Financing!R:R) -> 0 | AG42: =SUMIF(Financing!$A:$A,"LP",Financing!S:S) -> 0 | AH42: =SUMIF(Financing!$A:$A,"LP",Financing!T:T) -> 0 | AI42: =SUMIF(Financing!$A:$A,"LP",Financing!U:U) -> 0 | AJ42: =SUMIF(Financing!$A:$A,"LP",Financing!V:V) -> 0 | AK42: =SUMIF(Financing!$A:$A,"LP",Financing!W:W) -> 0 | AL42: =SUMIF(Financing!$A:$A,"LP",Financing!X:X) -> 0 | AM42: =SUMIF(Financing!$A:$A,"LP",Financing!Y:Y) -> 0 | AN42: =SUMIF(Financing!$A:$A,"LP",Financing!Z:Z) -> 0 | AO42: =SUMIF(Financing!$A:$A,"LP",Financing!AA:AA) -> 0 | AP42: =SUMIF(Financing!$A:$A,"LP",Financing!AB:AB) -> 0 | AQ42: =SUMIF(Financing!$A:$A,"LP",Financing!AC:AC) -> 0 | AR42: =SUMIF(Financing!$A:$A,"LP",Financing!AD:AD) -> 0 | AS42: =SUMIF(Financing!$A:$A,"LP",Financing!AE:AE) -> 0 | AT42: =SUMIF(Financing!$A:$A,"LP",Financing!AF:AF) -> 0 | AU42: =SUMIF(Financing!$A:$A,"LP",Financing!AG:AG) -> 0 | AV42: =SUMIF(Financing!$A:$A,"LP",Financing!AH:AH) -> 0 | AW42: =SUMIF(Financing!$A:$A,"LP",Financing!AI:AI) -> 0 | AX42: =SUMIF(Financing!$A:$A,"LP",Financing!AJ:AJ) -> 0 | AY42: =SUMIF(Financing!$A:$A,"LP",Financing!AK:AK) -> 0 | AZ42: =SUMIF(Financing!$A:$A,"LP",Financing!AL:AL) -> 0 | BA42: =SUMIF(Financing!$A:$A,"LP",Financing!AM:AM) -> 0 | BB42: =SUMIF(Financing!$A:$A,"LP",Financing!AN:AN) -> 0 | BC42: =SUMIF(Financing!$A:$A,"LP",Financing!AO:AO) -> 0 | BD42: =SUMIF(Financing!$A:$A,"LP",Financing!AP:AP) -> 0 | BE42: =SUMIF(Financing!$A:$A,"LP",Financing!AQ:AQ) -> 0 | BF42: =SUMIF(Financing!$A:$A,"LP",Financing!AR:AR) -> 0 | BG42: =SUMIF(Financing!$A:$A,"LP",Financing!AS:AS) -> 0 | BH42: =SUMIF(Financing!$A:$A,"LP",Financing!AT:AT) -> 0 | BI42: =SUMIF(Financing!$A:$A,"LP",Financing!AU:AU) -> 0 | BJ42: =SUMIF(Financing!$A:$A,"LP",Financing!AV:AV) -> 0 | BK42: =SUMIF(Financing!$A:$A,"LP",Financing!AW:AW) -> 0 | BL42: =SUMIF(Financing!$A:$A,"LP",Financing!AX:AX) -> 0 | BM42: =SUMIF(Financing!$A:$A,"LP",Financing!AY:AY) -> 0 | BN42: =SUMIF(Financing!$A:$A,"LP",Financing!AZ:AZ) -> 0 | BO42: =SUMIF(Financing!$A:$A,"LP",Financing!BA:BA) -> 0 | BP42: =SUMIF(Financing!$A:$A,"LP",Financing!BB:BB) -> 0 | BQ42: =SUMIF(Financing!$A:$A,"LP",Financing!BC:BC) -> 0 | BR42: =SUMIF(Financing!$A:$A,"LP",Financing!BD:BD) -> 0 | BS42: =SUMIF(Financing!$A:$A,"LP",Financing!BE:BE) -> 0 | BT42: =SUMIF(Financing!$A:$A,"LP",Financing!BF:BF) -> 0 | BU42: =SUMIF(Financing!$A:$A,"LP",Financing!BG:BG) -> 0 | BV42: =SUMIF(Financing!$A:$A,"LP",Financing!BH:BH) -> 0 | BW42: =SUMIF(Financing!$A:$A,"LP",Financing!BI:BI) -> 0 | BX42: =SUMIF(Financing!$A:$A,"LP",Financing!BJ:BJ) -> 0 | BY42: =SUMIF(Financing!$A:$A,"LP",Financing!BK:BK) -> -1.2280324e+08 | BZ42: =SUMIF(Financing!$A:$A,"LP",Financing!BL:BL) -> 0 | CA42: =SUMIF(Financing!$A:$A,"LP",Financing!BM:BM) -> 0 | CB42: =SUMIF(Financing!$A:$A,"LP",Financing!BN:BN) -> 0 | CC42: =SUMIF(Financing!$A:$A,"LP",Financing!BO:BO) -> 0 | CD42: =SUMIF(Financing!$A:$A,"LP",Financing!BP:BP) -> 0 | CE42: =SUMIF(Financing!$A:$A,"LP",Financing!BQ:BQ) -> 0 | CF42: =SUMIF(Financing!$A:$A,"LP",Financing!BR:BR) -> 0 | CG42: =SUMIF(Financing!$A:$A,"LP",Financing!BS:BS) -> 0 | CH42: =SUMIF(Financing!$A:$A,"LP",Financing!BT:BT) -> 0 | CI42: =SUMIF(Financing!$A:$A,"LP",Financing!BU:BU) -> 0 | CJ42: =SUMIF(Financing!$A:$A,"LP",Financing!BV:BV) -> 0 | CK42: =SUMIF(Financing!$A:$A,"LP",Financing!BW:BW) -> 0 | CL42: =SUMIF(Financing!$A:$A,"LP",Financing!BX:BX) -> 0 | CM42: =SUMIF(Financing!$A:$A,"LP",Financing!BY:BY) -> 0 | CN42: =SUMIF(Financing!$A:$A,"LP",Financing!BZ:BZ) -> 0 | CO42: =SUMIF(Financing!$A:$A,"LP",Financing!CA:CA) -> 0 | CP42: =SUMIF(Financing!$A:$A,"LP",Financing!CB:CB) -> 0 | CQ42: =SUMIF(Financing!$A:$A,"LP",Financing!CC:CC) -> 0 | CR42: =SUMIF(Financing!$A:$A,"LP",Financing!CD:CD) -> 0 | CS42: =SUMIF(Financing!$A:$A,"LP",Financing!CE:CE) -> 0 | CT42: =SUMIF(Financing!$A:$A,"LP",Financing!CF:CF) -> 0 | CU42: =SUMIF(Financing!$A:$A,"LP",Financing!CG:CG) -> 0 | CV42: =SUMIF(Financing!$A:$A,"LP",Financing!CH:CH) -> 0 | CW42: =SUMIF(Financing!$A:$A,"LP",Financing!CI:CI) -> 0 | CX42: =SUMIF(Financing!$A:$A,"LP",Financing!CJ:CJ) -> 0 | CY42: =SUMIF(Financing!$A:$A,"LP",Financing!CK:CK) -> 0 | CZ42: =SUMIF(Financing!$A:$A,"LP",Financing!CL:CL) -> 0 | DA42: =SUMIF(Financing!$A:$A,"LP",Financing!CM:CM) -> 0 | DB42: =SUMIF(Financing!$A:$A,"LP",Financing!CN:CN) -> 0 | DC42: =SUMIF(Financing!$A:$A,"LP",Financing!CO:CO) -> 0 | DD42: =SUMIF(Financing!$A:$A,"LP",Financing!CP:CP) -> 0 | DE42: =SUMIF(Financing!$A:$A,"LP",Financing!CQ:CQ) -> 0 | DF42: =SUMIF(Financing!$A:$A,"LP",Financing!CR:CR) -> 0 | DG42: =SUMIF(Financing!$A:$A,"LP",Financing!CS:CS) -> 0 | DH42: =SUMIF(Financing!$A:$A,"LP",Financing!CT:CT) -> 0 | DI42: =SUMIF(Financing!$A:$A,"LP",Financing!CU:CU) -> 0 | DJ42: =SUMIF(Financing!$A:$A,"LP",Financing!CV:CV) -> 0 | DK42: =SUMIF(Financing!$A:$A,"LP",Financing!CW:CW) -> 0 | DL42: =SUMIF(Financing!$A:$A,"LP",Financing!CX:CX) -> 0 | DM42: =SUMIF(Financing!$A:$A,"LP",Financing!CY:CY) -> 0 | DN42: =SUMIF(Financing!$A:$A,"LP",Financing!CZ:CZ) -> 0 | DO42: =SUMIF(Financing!$A:$A,"LP",Financing!DA:DA) -> 0 | DP42: =SUMIF(Financing!$A:$A,"LP",Financing!DB:DB) -> 0 | DQ42: =SUMIF(Financing!$A:$A,"LP",Financing!DC:DC) -> 0 | DR42: =SUMIF(Financing!$A:$A,"LP",Financing!DD:DD) -> 0 | DS42: =SUMIF(Financing!$A:$A,"LP",Financing!DE:DE) -> 0 | DT42: =SUMIF(Financing!$A:$A,"LP",Financing!DF:DF) -> 0 | DU42: =SUMIF(Financing!$A:$A,"LP",Financing!DG:DG) -> 0 | DV42: =SUMIF(Financing!$A:$A,"LP",Financing!DH:DH) -> 0 | DW42: =SUMIF(Financing!$A:$A,"LP",Financing!DI:DI) -> 0 | DX42: =SUMIF(Financing!$A:$A,"LP",Financing!DJ:DJ) -> 0 | DY42: =SUMIF(Financing!$A:$A,"LP",Financing!DK:DK) -> 0 | DZ42: =SUMIF(Financing!$A:$A,"LP",Financing!DL:DL) -> 0 | EA42: =SUMIF(Financing!$A:$A,"LP",Financing!DM:DM) -> 0 | EB42: =SUMIF(Financing!$A:$A,"LP",Financing!DN:DN) -> 0 | EC42: =SUMIF(Financing!$A:$A,"LP",Financing!DO:DO) -> 0 | ED42: =SUMIF(Financing!$A:$A,"LP",Financing!DP:DP) -> 0 | EE42: =SUMIF(Financing!$A:$A,"LP",Financing!DQ:DQ) -> 0 | EF42: =SUMIF(Financing!$A:$A,"LP",Financing!DR:DR) -> 0 | EG42: =SUMIF(Financing!$A:$A,"LP",Financing!DS:DS) -> 0 | EH42: =SUMIF(Financing!$A:$A,"LP",Financing!DT:DT) -> 0 | EI42: =SUMIF(Financing!$A:$A,"LP",Financing!DU:DU) -> 0 | EJ42: =SUMIF(Financing!$A:$A,"LP",Financing!DV:DV) -> 0 | EK42: =SUMIF(Financing!$A:$A,"LP",Financing!DW:DW) -> 0 | EL42: =SUMIF(Financing!$A:$A,"LP",Financing!DX:DX) -> 0 | EM42: =SUMIF(Financing!$A:$A,"LP",Financing!DY:DY) -> 0 | EN42: =SUMIF(Financing!$A:$A,"LP",Financing!DZ:DZ) -> 0 | EO42: =SUMIF(Financing!$A:$A,"LP",Financing!EA:EA) -> 0 | EP42: =SUMIF(Financing!$A:$A,"LP",Financing!EB:EB) -> 0 | EQ42: =SUMIF(Financing!$A:$A,"LP",Financing!EC:EC) -> 0 | ER42: =SUMIF(Financing!$A:$A,"LP",Financing!ED:ED) -> 0 | ES42: =SUMIF(Financing!$A:$A,"LP",Financing!EE:EE) -> 0
