Workbook
Name units: [1]Rents!$C$51
Name Units: Rent!$D$29

Sheet CFS-Main Page
B2: The Grove on Southlake | C2: Address: | D2: 7290 Southlake Parkway Morrow, GA, 30260
B3: Cashflow Statement - Main Page | C3: Units | D3: =Units -> 260
C4: Year Built/Reno | D4: 2001 | F4: Scenario | G4: 2 | M4: Tax rate info. | P4: County Link:
B5: Analysis Start Date | C5: 46173 | G5: =10925000 -> 10925000 | M5: Districts | N5: Jurisdictions | Q5: 2025 Rate
B6: Investment Assumptions/Summary | D6: Per Unit | F6: Pro forma Assumptions | I6: Key Metrics | M6: Clayton County | P6: Link | Q6: 3.8298
B7: Purchase Price | C7: =IF(OR(G4=0,G4=1),J8,K8)*1000000 -> 42700000 | D7: =C7/$D$3 -> 164230.77 | F7: Rent Increase (Y2 Onwards) | H7: 0.03 | I7: =B2 -> The Grove on Southlake | J7: 1 | K7: 2 | L7: Broker's Numbers
B8: NOI After Reserve | C8: =I66 -> 2133450.4 | D8: =C8/$D$3 -> 8205.5784 | F8: Other Income Increase (Y2) | H8: =H7 -> 0.03 | I8: Asking Price | J8: =IF(G4=2,"",L8) | K8: 42.7 | L8: 0
B9: All in Cost | C9: ='Sources & Usage'!C9 -> 43425900 | D9: =C9/$D$3 -> 167022.69 | F9: Expense Increase (Year 2 Onwards) | H9: 0.0275 | I9: Y1 NOI | J9: =IF(G4=2,"",I63) | K9: =IF(G4=1,"",I63) -> 2133450.4 | L9: =H63 -> 0
B10: PP Cap Rate | C10: =C8/C7 -> 0.04996371 | F10: Property Management Fee | H10: 0.0275 | I10: Cap rate | J10: =IF(G4=2,"",J9/(J8*1000000)) | K10: =IF(G4=1,"",K9/(K8*1000000)) -> 0.04996371 | L10: 0
B11: Total Rentable Square Feet | C11: =Rent!I29 -> 270332 | D11: =C11/$D$3 -> 1039.7385 | F11: Asset Management Fee | H11: 0 | I11: Levered COC | J11: =IF(G4=2,"",G76) | K11: =IF(G4=1,"",G76) -> 0.043197118 | L11: -
B12: Cash on Cash Return | C12: =I76 -> 0.038216749 | F12: Cost of Exit (Brokerage) | H12: 0.01 | I12: Levered IRR | J12: =IF(G4=2,"",G78) | K12: =IF(G4=1,"",G78) -> 0.049579896 | L12: -
B13: Exit Year | C13: 5 | F13: Replacement Reserve (Per Unit) | H13: 0 | I13: Y1 Yield on Cost | J13: =IF(G4=2,"",$I$63/(J8*1000000)) | K13: =IF(G4=1,"",$I$63/'Sources & Usage'!$C$23) -> 0.049128525 | L13: -
B14: Exit Cap Rate | C14: 0.06 | F14: Assesment Ratio | G14: 0.4 | H14: =G14*C7 -> 17080000 | I14: Appraisal happens every year and reflects the sale price on the next year of sale in Georgia.
B15: Exit NOI (After Reserve) | C15: =HLOOKUP($C$13+1,$I$46:$S$66,ROWS($I$46:$I$66)) -> 2610262.9 | D15: =C15/$D$3 -> 10039.473 | F15: Y1 Tax Reassessed | G15: =Q16 -> 0.038298 | H15: =G15*H14 -> 654129.84
B16: Exit Price | C16: =HLOOKUP($C$13,$I$46:$S$67,ROWS($I$46:$I$67)) -> 43069339 | D16: =C16/$D$3 -> 165651.3 | F16: Tax growth (Y2 Onwards) | H16: 0.03 | I16: Direct tax in last tax bill was $0. | N16: Millage Rate | Q16: =SUM(Q6:Q15)/100 -> 0.038298
B18: Rental Assumptions | D18: =Rent!D5 -> 46104 | F18: T3 | G18: T12 | H18: Broker Numbers | I18: 1 | J18: =IF(I18<$C$13+1,I18+1,"") -> 2 | K18: =IF(J18<$C$13+1,J18+1,"") -> 3 | L18: =IF(K18<$C$13+1,K18+1,"") -> 4 | M18: =IF(L18<$C$13+1,L18+1,"") -> 5 | N18: =IF(M18<$C$13+1,M18+1,"") -> 6 | O18: =IF(N18<$C$13+1,N18+1,"") | P18: =IF(O18<$C$13+1,O18+1,"") | Q18: =IF(P18<$C$13+1,P18+1,"") | ... AC18: =IF(AB18<$C$13+1,AB18+1,"")
B19: Loss to Lease | D19: =Rent!H32/Rent!H30 -> 0.019496639 | F19: =-F34/F33 -> 0.022239821 | G19: =-G34/G33 -> 0.013078285 | H19: =-H34/H33 -> #DIV/0! | I19: =-I34/I33 -> 0.019496639 | J19: 0.01 | K19: 0.01 | L19: 0.01 | M19: 0.01 | N19: =M19 -> 0.01 | O19: =N19 -> 0.01 | P19: =O19 -> 0.01 | Q19: =P19 -> 0.01 | R19: =Q19 -> 0.01 | S19: =R19 -> 0.01 | T19: =S19 -> 0.01 | U19: =T19 -> 0.01 | ... AB19: =AA19 -> 0.01
B20: Vacancy | D20: =1-Rent!H29 -> 0.080769231 | F20: =-F36/$G$35 -> 0.076333088 | G20: =-G36/$G$35 -> 0.065317102 | H20: =-H36/$H$35 -> #DIV/0! | I20: 0.05 | J20: 0.05 | K20: 0.05 | L20: 0.05 | M20: =L20 -> 0.05 | N20: =M20 -> 0.05 | O20: =N20 -> 0.05 | P20: =O20 -> 0.05 | Q20: =P20 -> 0.05 | R20: =Q20 -> 0.05 | S20: =R20 -> 0.05 | T20: =S20 -> 0.05 | ... AB20: =AA20 -> 0.05
B21: Concession/Discount | F21: =-F37/$G$35 -> 0.018401291 | G21: =-G37/$G$35 -> 0.011438724 | H21: =-H37/$H$35 -> #DIV/0! | I21: 0.01 | J21: 0.01 | K21: 0.01 | L21: 0.01 | M21: =L21 -> 0.01 | N21: =M21 -> 0.01 | O21: =N21 -> 0.01 | P21: =O21 -> 0.01 | Q21: =P21 -> 0.01 | R21: =Q21 -> 0.01 | S21: =R21 -> 0.01 | T21: =S21 -> 0.01 | ... AB21: =AA21 -> 0.01
B22: Bad Debt | F22: =-F38/$G$35 -> 0.041047311 | G22: =-G38/$G$35 -> 0.034963814 | H22: =-H38/$H$35 -> #DIV/0! | I22: 0.035 | J22: 0.02 | K22: =J22 -> 0.02 | L22: =K22 -> 0.02 | M22: =L22 -> 0.02 | N22: =M22 -> 0.02 | O22: =N22 -> 0.02 | P22: =O22 -> 0.02 | Q22: =P22 -> 0.02 | R22: =Q22 -> 0.02 | ... AB22: =AA22 -> 0.02
B23: Non Revenue Units | F23: =-F39/$G$35 -> 0.0053015073 | G23: =-G39/$G$35 -> 0.0061691074 | H23: =-H39/$H$35 -> #DIV/0! | I23: =G23 -> 0.0061691074 | J23: =I23 -> 0.0061691074 | K23: =J23 -> 0.0061691074 | L23: =K23 -> 0.0061691074 | M23: =L23 -> 0.0061691074 | N23: =M23 -> 0.0061691074 | O23: =N23 -> 0.0061691074 | P23: =O23 -> 0.0061691074 | Q23: =P23 -> 0.0061691074 | ... AB23: =AA23 -> 0.0061691074
D24: =Rent!H29 -> 0.91923077
B25: Average Rent (GRP) | F25: =F35/Units/12 -> 1407.0696 | G25: =G35/Units/12 -> 1396.9902 | H25: =H35/Units/12 -> 0 | I25: =I35/Units/12 -> 1419.6784 | J25: =IF(J$18="","",J35/Units/12) -> 1476.4315 | K25: =IF(K$18="","",K35/Units/12) -> 1520.7244 | L25: =IF(L$18="","",L35/Units/12) -> 1566.3462 | M25: =IF(M$18="","",M35/Units/12) -> 1613.3365 | N25: =IF(N$18="","",N35/Units/12) -> 1661.7366 | O25: =IF(O$18="","",O35/Units/12) | P25: =IF(P$18="","",P35/Units/12) | Q25: =IF(Q$18="","",Q35/Units/12) | ... AC25: =IF(AC$18="","",AC35/Units/12)
B26: GRP Increases | I26: =IF(I$18="","",I35/G35-1) -> 0.01624073 | J26: =IF(J$18="","",J35/I35-1) -> 0.039976037 | K26: =IF(K$18="","",K35/J35-1) -> 0.03 | L26: =IF(L$18="","",L35/K35-1) -> 0.03 | M26: =IF(M$18="","",M35/L35-1) -> 0.03 | N26: =IF(N$18="","",N35/M35-1) -> 0.03 | O26: =IF(O$18="","",O35/N35-1) | P26: =IF(P$18="","",P35/O35-1) | Q26: =IF(Q$18="","",Q35/P35-1) | ... AC26: =IF(AC$18="","",AC35/AB35-1)
B27: Economic Occupancy | F27: =IF(F$18="","",F40/F35) -> 0.85992744 | G27: =IF(G$18="","",G40/G35) -> 0.88211125 | H27: =IF(H$18="","",H40/H35) -> #DIV/0! | I27: =IF(I$18="","",I40/I35) -> 0.89883089 | J27: =IF(J$18="","",J40/J35) -> 0.91383089 | K27: =IF(K$18="","",K40/K35) -> 0.91383089 | L27: =IF(L$18="","",L40/L35) -> 0.91383089 | M27: =IF(M$18="","",M40/M35) -> 0.91383089 | ... AC27: =IF(AC$18="","",AC40/AC35)
B28: GEI Increases | I28: =IF(I$18="","",I40/G40-1) -> 0.035502676 | J28: =IF(J$18="","",J40/I40-1) -> 0.057331516 | K28: =IF(K$18="","",K40/J40-1) -> 0.03 | L28: =IF(L$18="","",L40/K40-1) -> 0.03 | M28: =IF(M$18="","",M40/L40-1) -> 0.03 | N28: =IF(N$18="","",N40/M40-1) -> 0.03 | O28: =IF(O$18="","",O40/N40-1) | P28: =IF(P$18="","",P40/O40-1) | Q28: =IF(Q$18="","",Q40/P40-1) | ... AC28: =IF(AC$18="","",AC40/AB40-1)
B30: Income | D30: Per Unit (T12) | E30: Per Unit Y1 | F30: =F18 -> T3 | G30: T12 | H30: Broker's Numbers | I30: 1 | J30: =IF(I30<$C$13+1,I30+1,"") -> 2 | K30: =IF(J30<$C$13+1,J30+1,"") -> 3 | L30: =IF(K30<$C$13+1,K30+1,"") -> 4 | M30: =IF(L30<$C$13+1,L30+1,"") -> 5 | N30: =IF(M30<$C$13+1,M30+1,"") -> 6 | O30: =IF(N30<$C$13+1,N30+1,"") | P30: =IF(O30<$C$13+1,O30+1,"") | Q30: =IF(P30<$C$13+1,P30+1,"") | ... AC30: =IF(AB30<$C$13+1,AB30+1,"")
B31: Market Rent Potential | D31: =G31/Units -> 15336.954 | E31: =I31/Units -> 17374.892 | F31: ='Historical Analysis'!X9 -> 4061152 | G31: ='Historical Analysis'!W9 -> 3987608 | H31: 0 | I31: {=(SUMPRODUCT(Rent!$K$9:$K$28*(Rent!$L$9:$L$28=Rent!$K$8),Rent!$D$9:$D$28)+SUMPRODUCT(Rent!$J$9:$J$28*(Rent!$L$9:$L$28=Rent!$J$8),Rent!$D$9:$D$28))*12} -> 4517472 | J31: =IF(J$30>$C$13+1,"",I$31*(1+$H$7)) -> 4652996.2 | K31: =IF(K$30>$C$13+1,"",J$31*(1+$H$7)) -> 4792586 | L31: =IF(L$30>$C$13+1,"",K$31*(1+$H$7)) -> 4936363.6 | M31: =IF(M$30>$C$13+1,"",L$31*(1+$H$7)) -> 5084454.5 | N31: =IF(N$30>$C$13+1,"",M$31*(1+$H$7)) -> 5236988.2 | O31: =IF(O$30>$C$13+1,"",N$31*(1+$H$7)) | P31: =IF(P$30>$C$13+1,"",O$31*(1+$H$7)) | Q31: =IF(Q$30>$C$13+1,"",P$31*(1+$H$7)) | ... AC31: =IF(AC$30>$C$13+1,"",AB$31*(1+$H$7))
B32: Renovation Premium | D32: =G32/Units -> 1649.0769 | E32: =I32/Units -> 0 | F32: ='Historical Analysis'!X10 -> 428760 | G32: ='Historical Analysis'!W10 -> 428760 | H32: 0 | I32: =Rent!I57*12/3 -> 0 | J32: =IF(J30<=$C$13+1,(Rent!I57*12/3)+I32*(1+$H$7),"") -> 0 | K32: =IF(K30<=$C$13+1,(Rent!I57*12/3)+J32*(1+$H$7),"") -> 0 | L32: =IF(L30<=$C$13+1,K32*(1+$H$7),"") -> 0 | M32: =IF(M30<=$C$13+1,L32*(1+$H$7),"") -> 0 | N32: =IF(N30<=$C$13+1,M32*(1+$H$7),"") -> 0 | O32: =IF(O30<=$C$13+1,N32*(1+$H$7),"") | P32: =IF(P30<=$C$13+1,O32*(1+$H$7),"") | Q32: =IF(Q30<=$C$13+1,P32*(1+$H$7),"") | R32: =IF(R30<=$C$13+1,Q32*(1+$H$7),"") | S32: =IF(S30<=$C$13+1,R32*(1+$H$7),"") | ... AC32: =IF(AC30<=$C$13+1,AB32*(1+$H$7),"")
B33: Total Market Rent Potential | D33: =G33/Units -> 16986.031 | E33: =I33/Units -> 17374.892 | F33: =F31+F32 -> 4489912 | G33: =G31+G32 -> 4416368 | H33: =SUM(H31:H32) -> 0 | I33: =IF(I$30<=$C$13+1,I31+I32,"") -> 4517472 | J33: =IF(J$30<=$C$13+1,J31+J32,"") -> 4652996.2 | K33: =IF(K$30<=$C$13+1,K31+K32,"") -> 4792586 | L33: =IF(L$30<=$C$13+1,L31+L32,"") -> 4936363.6 | M33: =IF(M$30<=$C$13+1,M31+M32,"") -> 5084454.5 | N33: =IF(N$30<=$C$13+1,N31+N32,"") -> 5236988.2 | O33: =IF(O$30<=$C$13+1,O31+O32,"") | P33: =IF(P$30<=$C$13+1,P31+P32,"") | ... AC33: =IF(AC$30<=$C$13+1,AC31+AC32,"")
B34: Loss to Lease | D34: =G34/Units -> -222.14815 | E34: =I34/Units -> -338.752 | F34: ='Historical Analysis'!X12 -> -99854.84 | G34: ='Historical Analysis'!W12 -> -57758.52 | H34: 0 | I34: =IF(I$30<=$C$13+1,I35-I33,"") -> -88075.519 | J34: =IF(J$30<=$C$13+1,-J19*J33,"") -> -46529.962 | K34: =IF(K$30<=$C$13+1,-K19*K33,"") -> -47925.86 | L34: =IF(L$30<=$C$13+1,-L19*L33,"") -> -49363.636 | M34: =IF(M$30<=$C$13+1,-M19*M33,"") -> -50844.545 | N34: =IF(N$30<=$C$13+1,-N19*N33,"") -> -52369.882 | O34: =IF(O$30<=$C$13+1,-O19*O33,"") | P34: =IF(P$30<=$C$13+1,-P19*P33,"") | Q34: =IF(Q$30<=$C$13+1,-Q19*Q33,"") | ... AC34: =IF(AC$30<=$C$13+1,-AC19*AC33,"")
B35: Scheduled Rental Income | D35: =G35/Units -> 16763.883 | E35: =I35/Units -> 17036.14 | F35: =F33+F34 -> 4390057.2 | G35: =G33+G34 -> 4358609.5 | H35: =SUM(H33:H34) -> 0 | I35: =IF(I$30<=$C$13+1,Rent!N29*12,"") -> 4429396.5 | J35: =IF(J$30<=$C$13+1,J33+J34,"") -> 4606466.2 | K35: =IF(K$30<=$C$13+1,K33+K34,"") -> 4744660.2 | L35: =IF(L$30<=$C$13+1,L33+L34,"") -> 4887000 | M35: =IF(M$30<=$C$13+1,M33+M34,"") -> 5033610 | N35: =IF(N$30<=$C$13+1,N33+N34,"") -> 5184618.3 | O35: =IF(O$30<=$C$13+1,O33+O34,"") | P35: =IF(P$30<=$C$13+1,P33+P34,"") | Q35: =IF(Q$30<=$C$13+1,Q33+Q34,"") | ... AC35: =IF(AC$30<=$C$13+1,AC33+AC34,"")
B36: Vacancy | D36: =G36/Units -> -1094.9682 | E36: =I36/Units -> -851.80702 | F36: ='Historical Analysis'!X14 -> -332706.12 | G36: ='Historical Analysis'!W14 -> -284691.74 | H36: 0 | I36: =IF(I$30<=$C$13+1,-I$35*I20,"") -> -221469.82 | J36: =IF(J$30<=$C$13+1,-J$35*J20,"") -> -230323.31 | K36: =IF(K$30<=$C$13+1,-K$35*K20,"") -> -237233.01 | L36: =IF(L$30<=$C$13+1,-L$35*L20,"") -> -244350 | M36: =IF(M$30<=$C$13+1,-M$35*M20,"") -> -251680.5 | N36: =IF(N$30<=$C$13+1,-N$35*N20,"") -> -259230.91 | O36: =IF(O$30<=$C$13+1,-O$35*O20,"") | P36: =IF(P$30<=$C$13+1,-P$35*P20,"") | ... AC36: =IF(AC$30<=$C$13+1,-AC$35*AC20,"")
B37: Concession/Discount | D37: =G37/Units -> -191.75742 | E37: =I37/Units -> -170.3614 | F37: ='Historical Analysis'!X15 -> -80204.04 | G37: ='Historical Analysis'!W15 -> -49856.93 | H37: 0 | I37: =IF(I$30<=$C$13+1,-I$35*I21,"") -> -44293.965 | J37: =IF(J$30<=$C$13+1,-J$35*J21,"") -> -46064.662 | K37: =IF(K$30<=$C$13+1,-K$35*K21,"") -> -47446.602 | L37: =IF(L$30<=$C$13+1,-L$35*L21,"") -> -48870 | M37: =IF(M$30<=$C$13+1,-M$35*M21,"") -> -50336.1 | N37: =IF(N$30<=$C$13+1,-N$35*N21,"") -> -51846.183 | O37: =IF(O$30<=$C$13+1,-O$35*O21,"") | P37: =IF(P$30<=$C$13+1,-P$35*P21,"") | ... AC37: =IF(AC$30<=$C$13+1,-AC$35*AC21,"")
B38: Bad Debt | D38: =G38/Units -> -586.12927 | E38: =I38/Units -> -596.26491 | F38: ='Historical Analysis'!X16 -> -178909.2 | G38: ='Historical Analysis'!W16 -> -152393.61 | H38: 0 | I38: =IF(I$30<=$C$13+1,-I$35*I22,"") -> -155028.88 | J38: =IF(J$30<=$C$13+1,-J$35*J22,"") -> -92129.324 | K38: =IF(K$30<=$C$13+1,-K$35*K22,"") -> -94893.204 | L38: =IF(L$30<=$C$13+1,-L$35*L22,"") -> -97740 | M38: =IF(M$30<=$C$13+1,-M$35*M22,"") -> -100672.2 | N38: =IF(N$30<=$C$13+1,-N$35*N22,"") -> -103692.37 | O38: =IF(O$30<=$C$13+1,-O$35*O22,"") | P38: =IF(P$30<=$C$13+1,-P$35*P22,"") | ... AC38: =IF(AC$30<=$C$13+1,-AC$35*AC22,"")
B39: Non Revenue Units | D39: =G39/Units -> -103.41819 | E39: =I39/Units -> -105.09778 | F39: ='Historical Analysis'!X17 -> -23107.2 | G39: ='Historical Analysis'!W17 -> -26888.73 | H39: 0 | I39: =IF(I$30<=$C$13+1,-I$35*I23,"") -> -27325.423 | J39: =IF(J$30<=$C$13+1,-J$35*J23,"") -> -28417.785 | K39: =IF(K$30<=$C$13+1,-K$35*K23,"") -> -29270.318 | L39: =IF(L$30<=$C$13+1,-L$35*L23,"") -> -30148.428 | M39: =IF(M$30<=$C$13+1,-M$35*M23,"") -> -31052.881 | N39: =IF(N$30<=$C$13+1,-N$35*N23,"") -> -31984.467 | O39: =IF(O$30<=$C$13+1,-O$35*O23,"") | P39: =IF(P$30<=$C$13+1,-P$35*P23,"") | ... Z39: =IF(Z$30<=$C$13+1,-Z$35*Z23,"") | AA39: =IF(AA$30<=$C$13+1,Z39*(1+$H$7),"") | AB39: =IF(AB$30<=$C$13+1,AA39*(1+$H$7),"") | AC39: =IF(AC$30<=$C$13+1,AB39*(1+$H$7),"")
B40: Gross Effective Income | D40: =G40/Units -> 14787.61 | E40: =I40/Units -> 15312.609 | F40: =F35+SUM(F36:F39) -> 3775130.6 | G40: =G35+SUM(G36:G39) -> 3844778.5 | H40: =SUM(H35:H39) -> 0 | I40: =IF(I$30<=$C$13+1,SUM(I35:I39),"") -> 3981278.4 | J40: =IF(J$30<=$C$13+1,SUM(J35:J39),"") -> 4209531.1 | K40: =IF(K$30<=$C$13+1,SUM(K35:K39),"") -> 4335817.1 | L40: =IF(L$30<=$C$13+1,SUM(L35:L39),"") -> 4465891.6 | M40: =IF(M$30<=$C$13+1,SUM(M35:M39),"") -> 4599868.3 | N40: =IF(N$30<=$C$13+1,SUM(N35:N39),"") -> 4737864.4 | O40: =IF(O$30<=$C$13+1,SUM(O35:O39),"") | P40: =IF(P$30<=$C$13+1,SUM(P35:P39),"") | ... AC40: =IF(AC$30<=$C$13+1,SUM(AC35:AC39),"")
B41: Utility Reimbursements | D41: =G41/Units -> 661.22465 | E41: 660 | F41: ='Historical Analysis'!X19 -> 178771.76 | G41: ='Historical Analysis'!W19 -> 171918.41 | H41: 0 | I41: =IF(I$46="","",E41*Units) -> 171600 | J41: =IF(J$46="","",I41*(1+$H$9)) -> 176319 | K41: =IF(K$46="","",J41*(1+$H$9)) -> 181167.77 | L41: =IF(L$46="","",K41*(1+$H$9)) -> 186149.89 | M41: =IF(M$46="","",L41*(1+$H$9)) -> 191269.01 | N41: =IF(N$46="","",M41*(1+$H$9)) -> 196528.91 | O41: =IF(O$46="","",N41*(1+$H$9)) | P41: =IF(P$46="","",O41*(1+$H$9)) | Q41: =IF(Q$46="","",P41*(1+$H$9)) | ... AC41: =IF(AC$46="","",AB41*(1+$H$9))
B42: Other Reimbursements | D42: =G42/Units -> 386.01715 | E42: 390 | F42: ='Historical Analysis'!X20 -> 106408.96 | G42: ='Historical Analysis'!W20 -> 100364.46 | H42: 0 | I42: =IF(I$46="","",E42*Units) -> 101400 | J42: =IF(J$30="","",(I42*(1+$H$9))) -> 104188.5 | K42: =IF(K$46="","",J42*(1+$H$9)) -> 107053.68 | L42: =IF(L$46="","",K42*(1+$H$9)) -> 109997.66 | M42: =IF(M$46="","",L42*(1+$H$9)) -> 113022.6 | N42: =IF(N$46="","",M42*(1+$H$9)) -> 116130.72 | O42: =IF(O$46="","",N42*(1+$H$9)) | P42: =IF(P$46="","",O42*(1+$H$9)) | Q42: =IF(Q$46="","",P42*(1+$H$9)) | R42: =IF(R$46="","",Q42*(1+$H$9)) | ... AC42: =IF(AC$46="","",AB42*(1+$H$9))
B43: Other Income | D43: =G43/Units -> 765.68281 | E43: 770 | F43: ='Historical Analysis'!X21 -> 240180.48 | G43: ='Historical Analysis'!W21 -> 199077.53 | H43: 0 | I43: =IF(I$46="","",E43*Units) -> 200200 | J43: =IF(J$46="","",I43*(1+$H$8)) -> 206206 | K43: =IF(K$46="","",J43*(1+$H$8)) -> 212392.18 | L43: =IF(L$46="","",K43*(1+$H$8)) -> 218763.95 | M43: =IF(M$46="","",L43*(1+$H$8)) -> 225326.86 | N43: =IF(N$46="","",M43*(1+$H$8)) -> 232086.67 | O43: =IF(O$46="","",N43*(1+$H$8)) | P43: =IF(P$46="","",O43*(1+$H$8)) | Q43: =IF(Q$46="","",P43*(1+$H$8)) | ... AC43: =IF(AC$46="","",AB43*(1+$H$8))
...

Sheet Rent
B2: ='CFS-Main Page'!B2 -> The Grove on Southlake | D2: ='CFS-Main Page'!C2 -> Address: | E2: ='CFS-Main Page'!D2 -> 7290 Southlake Parkway Morrow, GA, 30260
B3: Rent Roll Analysis | D3: ='CFS-Main Page'!C3 -> Units | E3: ='CFS-Main Page'!D3 -> 260
B4: ='CFS-Main Page'!B4 -> 0 | D4: ='CFS-Main Page'!C4 -> Year Built/Reno | E4: ='CFS-Main Page'!D4 -> 2001
C5: Rent Roll as on | D5: 46104 | E5: Avg Rent | F5: 1x1 | G5: {=-SUMPRODUCT(-($B$9:$B$28=F5),$E$9:$E$28,$J$9:$J$28)/SUMIF($B$9:$B$28,"="&F5,$E$9:$E$28)} -> 1292.2824 | H5: 2x2 | I5: {=-SUMPRODUCT(-($B$9:$B$28=H5),$E$9:$E$28,$J$9:$J$28)/SUMIF($B$9:$B$28,"="&H5,$E$9:$E$28)} -> 1487.558 | J5: 3x3 | K5: {=-SUMPRODUCT(-($B$9:$B$28=J5),$E$9:$E$28,$J$9:$J$28)/SUMIF($B$9:$B$28,"="&J5,$E$9:$E$28)} -> 1643.8853
C6: Rent Schedule
B8: Beds X Baths | C8: Type | D8: Units | E8: Occupied | F8: Vacant/Model | G8: Unit Mix % | H8: Occupancy % | I8: Square Feet | J8: MR - Based on RR | K8: MR - Based on Comps | L8: RR/Comps | M8: Effective Rent | N8: GRP | O8: GRP/unit
B9: 1x1 | C9: E1 | D9: =IF(C9="","",COUNTIF($D$62:$D$997,"="&C9)) -> 29 | E9: =IF(C9="","",COUNTIF($I$62:$I$997,"="&C9)) -> 26 | F9: =IFERROR(D9-E9,0) -> 3 | G9: =IFERROR(D9/$D$29,0) -> 0.11153846 | H9: =IFERROR(E9/D9,0) -> 0.89655172 | I9: =IFERROR(SUMIF($D$62:$D$997,"="&C9,$E$62:$E$997)/D9,0) -> 583 | J9: =IFERROR(SUMIF($D$62:$D$997,"="&C9,$G$62:$G$997)/D9,0) -> 1128.7241 | K9: 1454 | L9: MR - Based on RR | M9: =IFERROR(SUMIF($D$62:$D$997,"="&C9,$H$62:$H$997)/E9,0) -> 1082.9231 | N9: =IFERROR((M9*E9)+(F9*J9),0) -> 31542.172 | O9: =IFERROR(N9/D9,0) -> 1087.6611
B10: 1x1 | C10: E1-L2 | D10: =IF(C10="","",COUNTIF($D$62:$D$997,"="&C10)) -> 1 | E10: =IF(C10="","",COUNTIF($I$62:$I$997,"="&C10)) -> 1 | F10: =IFERROR(D10-E10,0) -> 0 | G10: =IFERROR(D10/$D$29,0) -> 0.0038461538 | H10: =IFERROR(E10/D10,0) -> 1 | I10: =IFERROR(SUMIF($D$62:$D$997,"="&C10,$E$62:$E$997)/D10,0) -> 583 | J10: =IFERROR(SUMIF($D$62:$D$997,"="&C10,$G$62:$G$997)/D10,0) -> 1134 | K10: 1454 | L10: MR - Based on RR | M10: =IFERROR(SUMIF($D$62:$D$997,"="&C10,$H$62:$H$997)/E10,0) -> 1242 | N10: =IFERROR((M10*E10)+(F10*J10),0) -> 1242 | O10: =IFERROR(N10/D10,0) -> 1242
B11: 1x1 | C11: A1 | D11: =IF(C11="","",COUNTIF($D$62:$D$997,"="&C11)) -> 26 | E11: =IF(C11="","",COUNTIF($I$62:$I$997,"="&C11)) -> 23 | F11: =IFERROR(D11-E11,0) -> 3 | G11: =IFERROR(D11/$D$29,0) -> 0.1 | H11: =IFERROR(E11/D11,0) -> 0.88461538 | I11: =IFERROR(SUMIF($D$62:$D$997,"="&C11,$E$62:$E$997)/D11,0) -> 825 | J11: =IFERROR(SUMIF($D$62:$D$997,"="&C11,$G$62:$G$997)/D11,0) -> 1201.8462 | K11: 1744 | L11: MR - Based on RR | M11: =IFERROR(SUMIF($D$62:$D$997,"="&C11,$H$62:$H$997)/E11,0) -> 1195.913 | N11: =IFERROR((M11*E11)+(F11*J11),0) -> 31111.538 | O11: =IFERROR(N11/D11,0) -> 1196.5976
B12: 1x1 | C12: A1-L2 | D12: =IF(C12="","",COUNTIF($D$62:$D$997,"="&C12)) -> 42 | E12: =IF(C12="","",COUNTIF($I$62:$I$997,"="&C12)) -> 41 | F12: =IFERROR(D12-E12,0) -> 1 | G12: =IFERROR(D12/$D$29,0) -> 0.16153846 | H12: =IFERROR(E12/D12,0) -> 0.97619048 | I12: =IFERROR(SUMIF($D$62:$D$997,"="&C12,$E$62:$E$997)/D12,0) -> 825 | J12: =IFERROR(SUMIF($D$62:$D$997,"="&C12,$G$62:$G$997)/D12,0) -> 1450.5952 | K12: 1744 | L12: MR - Based on RR | M12: =IFERROR(SUMIF($D$62:$D$997,"="&C12,$H$62:$H$997)/E12,0) -> 1374.122 | N12: =IFERROR((M12*E12)+(F12*J12),0) -> 57789.595 | O12: =IFERROR(N12/D12,0) -> 1375.9427
B13: 2x2 | C13: B1 | D13: =IF(C13="","",COUNTIF($D$62:$D$997,"="&C13)) -> 26 | E13: =IF(C13="","",COUNTIF($I$62:$I$997,"="&C13)) -> 25 | F13: =IFERROR(D13-E13,0) -> 1 | G13: =IFERROR(D13/$D$29,0) -> 0.1 | H13: =IFERROR(E13/D13,0) -> 0.96153846 | I13: =IFERROR(SUMIF($D$62:$D$997,"="&C13,$E$62:$E$997)/D13,0) -> 1127 | J13: =IFERROR(SUMIF($D$62:$D$997,"="&C13,$G$62:$G$997)/D13,0) -> 1309.1154 | K13: 2045 | L13: MR - Based on RR | M13: =IFERROR(SUMIF($D$62:$D$997,"="&C13,$H$62:$H$997)/E13,0) -> 1335.44 | N13: =IFERROR((M13*E13)+(F13*J13),0) -> 34695.115 | O13: =IFERROR(N13/D13,0) -> 1334.4275
B14: 2x2 | C14: B1-L2 | D14: =IF(C14="","",COUNTIF($D$62:$D$997,"="&C14)) -> 80 | E14: =IF(C14="","",COUNTIF($I$62:$I$997,"="&C14)) -> 70 | F14: =IFERROR(D14-E14,0) -> 10 | G14: =IFERROR(D14/$D$29,0) -> 0.30769231 | H14: =IFERROR(E14/D14,0) -> 0.875 | I14: =IFERROR(SUMIF($D$62:$D$997,"="&C14,$E$62:$E$997)/D14,0) -> 1127 | J14: =IFERROR(SUMIF($D$62:$D$997,"="&C14,$G$62:$G$997)/D14,0) -> 1551.2875 | K14: 2045 | L14: MR - Based on RR | M14: =IFERROR(SUMIF($D$62:$D$997,"="&C14,$H$62:$H$997)/E14,0) -> 1474.6429 | N14: =IFERROR((M14*E14)+(F14*J14),0) -> 118737.88 | O14: =IFERROR(N14/D14,0) -> 1484.2234
B15: 3x3 | C15: C1 | D15: =IF(C15="","",COUNTIF($D$62:$D$997,"="&C15)) -> 17 | E15: =IF(C15="","",COUNTIF($I$62:$I$997,"="&C15)) -> 17 | F15: =IFERROR(D15-E15,0) -> 0 | G15: =IFERROR(D15/$D$29,0) -> 0.065384615 | H15: =IFERROR(E15/D15,0) -> 1 | I15: =IFERROR(SUMIF($D$62:$D$997,"="&C15,$E$62:$E$997)/D15,0) -> 1380 | J15: =IFERROR(SUMIF($D$62:$D$997,"="&C15,$G$62:$G$997)/D15,0) -> 1489.7059 | K15: 1454 | L15: MR - Based on RR | M15: =IFERROR(SUMIF($D$62:$D$997,"="&C15,$H$62:$H$997)/E15,0) -> 1529.8824 | N15: =IFERROR((M15*E15)+(F15*J15),0) -> 26008 | O15: =IFERROR(N15/D15,0) -> 1529.8824
B16: 3x3 | C16: C1-L2 | D16: =IF(C16="","",COUNTIF($D$62:$D$997,"="&C16)) -> 39 | E16: =IF(C16="","",COUNTIF($I$62:$I$997,"="&C16)) -> 36 | F16: =IFERROR(D16-E16,0) -> 3 | G16: =IFERROR(D16/$D$29,0) -> 0.15 | H16: =IFERROR(E16/D16,0) -> 0.92307692 | I16: =IFERROR(SUMIF($D$62:$D$997,"="&C16,$E$62:$E$997)/D16,0) -> 1380 | J16: =IFERROR(SUMIF($D$62:$D$997,"="&C16,$G$62:$G$997)/D16,0) -> 1716.6923 | K16: 1454 | L16: MR - Based on RR | M16: =IFERROR(SUMIF($D$62:$D$997,"="&C16,$H$62:$H$997)/E16,0) -> 1745.5556 | N16: =IFERROR((M16*E16)+(F16*J16),0) -> 67990.077 | O16: =IFERROR(N16/D16,0) -> 1743.3353
D17: =IF(C17="","",COUNTIF($D$62:$D$997,"="&C17)) | E17: =IF(C17="","",COUNTIF($I$62:$I$997,"="&C17)) | F17: =IFERROR(D17-E17,0) -> 0 | G17: =IFERROR(D17/$D$29,0) -> 0 | H17: =IFERROR(E17/D17,0) -> 0 | I17: =IFERROR(SUMIF($D$62:$D$997,"="&C17,$E$62:$E$997)/D17,0) -> 0 | J17: =IFERROR(SUMIF($D$62:$D$997,"="&C17,$G$62:$G$997)/D17,0) -> 0 | K17: 0 | M17: =IFERROR(SUMIF($D$62:$D$997,"="&C17,$H$62:$H$997)/E17,0) -> 0 | N17: =IFERROR((M17*E17)+(F17*J17),0) -> 0 | O17: =IFERROR(N17/D17,0) -> 0
D18: =IF(C18="","",COUNTIF($D$62:$D$997,"="&C18)) | E18: =IF(C18="","",COUNTIF($I$62:$I$997,"="&C18)) | F18: =IFERROR(D18-E18,0) -> 0 | G18: =IFERROR(D18/$D$29,0) -> 0 | H18: =IFERROR(E18/D18,0) -> 0 | I18: =IFERROR(SUMIF($D$62:$D$997,"="&C18,$E$62:$E$997)/D18,0) -> 0 | J18: =IFERROR(SUMIF($D$62:$D$997,"="&C18,$G$62:$G$997)/D18,0) -> 0 | K18: 0 | M18: =IFERROR(SUMIF($D$62:$D$997,"="&C18,$H$62:$H$997)/E18,0) -> 0 | N18: =IFERROR((M18*E18)+(F18*J18),0) -> 0 | O18: =IFERROR(N18/D18,0) -> 0
D19: =IF(C19="","",COUNTIF($D$62:$D$997,"="&C19)) | E19: =IF(C19="","",COUNTIF($I$62:$I$997,"="&C19)) | F19: =IFERROR(D19-E19,0) -> 0 | G19: =IFERROR(D19/$D$29,0) -> 0 | H19: =IFERROR(E19/D19,0) -> 0 | I19: =IFERROR(SUMIF($D$62:$D$997,"="&C19,$E$62:$E$997)/D19,0) -> 0 | J19: =IFERROR(SUMIF($D$62:$D$997,"="&C19,$G$62:$G$997)/D19,0) -> 0 | K19: 0 | M19: =IFERROR(SUMIF($D$62:$D$997,"="&C19,$H$62:$H$997)/E19,0) -> 0 | N19: =IFERROR((M19*E19)+(F19*J19),0) -> 0 | O19: =IFERROR(N19/D19,0) -> 0
D20: =IF(C20="","",COUNTIF($D$62:$D$997,"="&C20)) | E20: =IF(C20="","",COUNTIF($I$62:$I$997,"="&C20)) | F20: =IFERROR(D20-E20,0) -> 0 | G20: =IFERROR(D20/$D$29,0) -> 0 | H20: =IFERROR(E20/D20,0) -> 0 | I20: =IFERROR(SUMIF($D$62:$D$997,"="&C20,$E$62:$E$997)/D20,0) -> 0 | J20: =IFERROR(SUMIF($D$62:$D$997,"="&C20,$G$62:$G$997)/D20,0) -> 0 | K20: 0 | M20: =IFERROR(SUMIF($D$62:$D$997,"="&C20,$H$62:$H$997)/E20,0) -> 0 | N20: =IFERROR((M20*E20)+(F20*J20),0) -> 0 | O20: =IFERROR(N20/D20,0) -> 0
D21: =IF(C21="","",COUNTIF($D$62:$D$997,"="&C21)) | E21: =IF(C21="","",COUNTIF($I$62:$I$997,"="&C21)) | F21: =IFERROR(D21-E21,0) -> 0 | G21: =IFERROR(D21/$D$29,0) -> 0 | H21: =IFERROR(E21/D21,0) -> 0 | I21: =IFERROR(SUMIF($D$62:$D$997,"="&C21,$E$62:$E$997)/D21,0) -> 0 | J21: =IFERROR(SUMIF($D$62:$D$997,"="&C21,$G$62:$G$997)/D21,0) -> 0 | K21: 0 | M21: =IFERROR(SUMIF($D$62:$D$997,"="&C21,$H$62:$H$997)/E21,0) -> 0 | N21: =IFERROR((M21*E21)+(F21*J21),0) -> 0 | O21: =IFERROR(N21/D21,0) -> 0
D22: =IF(C22="","",COUNTIF($D$62:$D$997,"="&C22)) | E22: =IF(C22="","",COUNTIF($I$62:$I$997,"="&C22)) | F22: =IFERROR(D22-E22,0) -> 0 | G22: =IFERROR(D22/$D$29,0) -> 0 | H22: =IFERROR(E22/D22,0) -> 0 | I22: =IFERROR(SUMIF($D$62:$D$997,"="&C22,$E$62:$E$997)/D22,0) -> 0 | J22: =IFERROR(SUMIF($D$62:$D$997,"="&C22,$G$62:$G$997)/D22,0) -> 0 | K22: 0 | M22: =IFERROR(SUMIF($D$62:$D$997,"="&C22,$H$62:$H$997)/E22,0) -> 0 | N22: =IFERROR((M22*E22)+(F22*J22),0) -> 0 | O22: =IFERROR(N22/D22,0) -> 0
D23: =IF(C23="","",COUNTIF($D$62:$D$997,"="&C23)) | E23: =IF(C23="","",COUNTIF($I$62:$I$997,"="&C23)) | F23: =IFERROR(D23-E23,0) -> 0 | G23: =IFERROR(D23/$D$29,0) -> 0 | H23: =IFERROR(E23/D23,0) -> 0 | I23: =IFERROR(SUMIF($D$62:$D$997,"="&C23,$E$62:$E$997)/D23,0) -> 0 | J23: =IFERROR(SUMIF($D$62:$D$997,"="&C23,$G$62:$G$997)/D23,0) -> 0 | K23: 0 | M23: =IFERROR(SUMIF($D$62:$D$997,"="&C23,$H$62:$H$997)/E23,0) -> 0 | N23: =IFERROR((M23*E23)+(F23*J23),0) -> 0 | O23: =IFERROR(N23/D23,0) -> 0
D24: =IF(C24="","",COUNTIF($D$62:$D$997,"="&C24)) | E24: =IF(C24="","",COUNTIF($I$62:$I$997,"="&C24)) | F24: =IFERROR(D24-E24,0) -> 0 | G24: =IFERROR(D24/$D$29,0) -> 0 | H24: =IFERROR(E24/D24,0) -> 0 | I24: =IFERROR(SUMIF($D$62:$D$997,"="&C24,$E$62:$E$997)/D24,0) -> 0 | J24: =IFERROR(SUMIF($D$62:$D$997,"="&C24,$G$62:$G$997)/D24,0) -> 0 | K24: 0 | M24: =IFERROR(SUMIF($D$62:$D$997,"="&C24,$H$62:$H$997)/E24,0) -> 0 | N24: =IFERROR((M24*E24)+(F24*J24),0) -> 0 | O24: =IFERROR(N24/D24,0) -> 0
D25: =IF(C25="","",COUNTIF($D$62:$D$997,"="&C25)) | E25: =IF(C25="","",COUNTIF($I$62:$I$997,"="&C25)) | F25: =IFERROR(D25-E25,0) -> 0 | G25: =IFERROR(D25/$D$29,0) -> 0 | H25: =IFERROR(E25/D25,0) -> 0 | I25: =IFERROR(SUMIF($D$62:$D$997,"="&C25,$E$62:$E$997)/D25,0) -> 0 | J25: =IFERROR(SUMIF($D$62:$D$997,"="&C25,$G$62:$G$997)/D25,0) -> 0 | K25: 0 | M25: =IFERROR(SUMIF($D$62:$D$997,"="&C25,$H$62:$H$997)/E25,0) -> 0 | N25: =IFERROR((M25*E25)+(F25*J25),0) -> 0 | O25: =IFERROR(N25/D25,0) -> 0
D26: =IF(C26="","",COUNTIF($D$62:$D$997,"="&C26)) | E26: =IF(C26="","",COUNTIF($I$62:$I$997,"="&C26)) | F26: =IFERROR(D26-E26,0) -> 0 | G26: =IFERROR(D26/$D$29,0) -> 0 | H26: =IFERROR(E26/D26,0) -> 0 | I26: =IFERROR(SUMIF($D$62:$D$997,"="&C26,$E$62:$E$997)/D26,0) -> 0 | J26: =IFERROR(SUMIF($D$62:$D$997,"="&C26,$G$62:$G$997)/D26,0) -> 0 | K26: 0 | M26: =IFERROR(SUMIF($D$62:$D$997,"="&C26,$H$62:$H$997)/E26,0) -> 0 | N26: =IFERROR((M26*E26)+(F26*J26),0) -> 0 | O26: =IFERROR(N26/D26,0) -> 0
D27: =IF(C27="","",COUNTIF($D$62:$D$997,"="&C27)) | E27: =IF(C27="","",COUNTIF($I$62:$I$997,"="&C27)) | F27: =IFERROR(D27-E27,0) -> 0 | G27: =IFERROR(D27/$D$29,0) -> 0 | H27: =IFERROR(E27/D27,0) -> 0 | I27: =IFERROR(SUMIF($D$62:$D$997,"="&C27,$E$62:$E$997)/D27,0) -> 0 | J27: =IFERROR(SUMIF($D$62:$D$997,"="&C27,$G$62:$G$997)/D27,0) -> 0 | K27: 0 | M27: =IFERROR(SUMIF($D$62:$D$997,"="&C27,$H$62:$H$997)/E27,0) -> 0 | N27: =IFERROR((M27*E27)+(F27*J27),0) -> 0 | O27: =IFERROR(N27/D27,0) -> 0
D28: =IF(C28="","",COUNTIF($D$62:$D$997,"="&C28)) | E28: =IF(C28="","",COUNTIF($I$62:$I$997,"="&C28)) | F28: =IFERROR(D28-E28,0) -> 0 | G28: =IFERROR(D28/$D$29,0) -> 0 | H28: =IFERROR(E28/D28,0) -> 0 | I28: =IFERROR(SUMIF($D$62:$D$997,"="&C28,$E$62:$E$997)/D28,0) -> 0 | J28: =IFERROR(SUMIF($D$62:$D$997,"="&C28,$G$62:$G$997)/D28,0) -> 0 | K28: 0 | M28: =IFERROR(SUMIF($D$62:$D$997,"="&C28,$H$62:$H$997)/E28,0) -> 0 | N28: =IFERROR((M28*E28)+(F28*J28),0) -> 0 | O28: =IFERROR(N28/D28,0) -> 0
C29: Total | D29: =SUM(D9:D28) -> 260 | E29: =SUM(E9:E28) -> 239 | F29: =SUM(F9:F28) -> 21 | G29: =SUM(G9:G28) -> 1 | H29: =E29/Units -> 0.91923077 | I29: =SUMPRODUCT($D$9:$D$28,I9:I28) -> 270332 | J29: =SUMPRODUCT($D$9:$D$28,J9:J28) -> 376456 | K29: =SUMPRODUCT($D$9:$D$28,K9:K28) -> 460406 | M29: =SUMPRODUCT(E9:E28,M9:M28) -> 338702 | N29: =SUM(N9:N28) -> 369116.37
G30: MRP | H30: =J29*12 -> 4517472 | I30: Rent per Unit | J30: =SUMPRODUCT(D9:D28,J9:J28)/D29 -> 1447.9077 | K30: =SUMPRODUCT(D9:D28,K9:K28)/D29 -> 1770.7923 | M30: =SUMPRODUCT(E9:E28,M9:M28)/E29 -> 1417.1632
G31: GRP | H31: =N29*12 -> 4429396.5 | I31: Rent per Sq ft | J31: =J30/J32 -> 1.3925691 | K31: =K30/K32 -> 1.7031132 | M31: =M30/(SUMPRODUCT(E9:E28,I9:I28)/E29) -> 1.361638
G32: Loss/(Gain) to lease | H32: =H30-H31 -> 88075.519 | I32: Average sq ft | J32: =SUMPRODUCT(D9:D28,I9:I28)/D29 -> 1039.7385 | K32: =SUMPRODUCT(D9:D28,I9:I28)/D29 -> 1039.7385 | M32: =SUMPRODUCT(E9:E28,I9:I28)/E29 -> 1040.7782
C35: Renovation Rent Premium and Cost Schdule
C36: Type | D36: Units | G36: Cost Per Unit | H36: Total Cost | I36: Premium Per Unit
C37: =IF(C9="","",C9) -> E1 | D37: =D9 -> 29 | G37: 0 | H37: =IFERROR(G37*D37,0) -> 0 | I37: 0
C38: =IF(C10="","",C10) -> E1-L2 | D38: =D10 -> 1 | G38: 0 | H38: =IFERROR(G38*D38,0) -> 0 | I38: 0
C39: =IF(C11="","",C11) -> A1 | D39: =D11 -> 26 | G39: 0 | H39: =IFERROR(G39*D39,0) -> 0 | I39: 0
C40: =IF(C12="","",C12) -> A1-L2 | D40: =D12 -> 42 | G40: 0 | H40: =IFERROR(G40*D40,0) -> 0 | I40: 0
C41: =IF(C13="","",C13) -> B1 | D41: =D13 -> 26 | G41: 0 | H41: =IFERROR(G41*D41,0) -> 0 | I41: 0
C42: =IF(C14="","",C14) -> B1-L2 | D42: =D14 -> 80 | G42: 0 | H42: =IFERROR(G42*D42,0) -> 0 | I42: 0
C43: =IF(C15="","",C15) -> C1 | D43: =D15 -> 17 | G43: 0 | H43: =IFERROR(G43*D43,0) -> 0 | I43: 0
C44: =IF(C16="","",C16) -> C1-L2 | D44: =D16 -> 39 | G44: 0 | H44: =IFERROR(G44*D44,0) -> 0 | I44: 0
...

Sheet Sources & Usage
B2: =Loan!B2 -> The Grove on Southlake | C2: ='CFS-Main Page'!C2 -> Address: | D2: ='CFS-Main Page'!D2 -> 7290 Southlake Parkway Morrow, GA, 30260
B3: Sources & Usage | C3: ='CFS-Main Page'!C3 -> Units | D3: ='CFS-Main Page'!D3 -> 260
B4: =Loan!B4 -> 0 | C4: ='CFS-Main Page'!C4 -> Year Built/Reno | D4: ='CFS-Main Page'!D4 -> 2001
B6: Source of Funding (Pre Refinance) | C6: Amount | D6: Per Unit
B7: Debt | C7: =IF(Loan!C9=0,Loan!C30,Loan!$C$9) -> 29890000 | D7: =C7/Units -> 114961.54 | E7: =C7/$C$9 -> 0.68829892
B8: Equity | C8: =C23-C7 -> 13535900 | D8: =C8/Units -> 52061.154 | E8: =C8/$C$9 -> 0.31170108
B9: Total | C9: =SUM(C7:C8) -> 43425900 | D9: =SUM(D7:D8) -> 167022.69 | E9: =SUM(E7:E8) -> 1
B11: Usage of Funding | C11: Amount | D11: Per Unit
B12: Purchase Price | C12: ='CFS-Main Page'!C7 -> 42700000 | D12: =C12/Units -> 164230.77 | E12: =C12/$C$23 -> 0.98328417
B13: Loan Processing Fees | C13: =C7*F13 -> 298900 | D13: =C13/Units -> 1149.6154 | E13: =C13/$C$23 -> 0.0068829892 | F13: 0.01
B14: Acquisition Fees | C14: =F14*C12 -> 427000 | D14: =C14/Units -> 1642.3077 | E14: =C14/$C$23 -> 0.0098328417 | F14: 0.01
B15: Renovation Cost | C15: =Rent!H57 -> 0 | D15: =C15/Units -> 0 | E15: =C15/$C$23 -> 0
B16: Additional Capex | C16: 0 | D16: =C16/Units -> 0 | E16: =C16/$C$23 -> 0
B17: Equity Fees | C17: 0 | D17: =C17/Units -> 0 | E17: =C17/$C$23 -> 0
B18: Legal | C18: 0 | D18: =C18/Units -> 0 | E18: =C18/$C$23 -> 0
B19: Other Closing Cost | C19: 0 | D19: =C19/Units -> 0 | E19: =C19/$C$23 -> 0
B20: Other Closing Cost | C20: 0 | D20: =C20/Units -> 0 | E20: =C20/$C$23 -> 0
B21: Other Closing Cost | C21: 0 | D21: =C21/Units -> 0 | E21: =C21/$C$23 -> 0
B22: Other Closing Cost | C22: =C12*F22 -> 0 | D22: =C22/Units -> 0 | E22: =C22/$C$23 -> 0 | F22: 0
B23: Total | C23: =SUM(C12:C22) -> 43425900 | D23: =SUM(D12:D22) -> 167022.69 | E23: 1

Sheet Loan
B2: =Rent!B2 -> The Grove on Southlake | C2: ='CFS-Main Page'!C2 -> Address: | D2: ='CFS-Main Page'!D2 -> 7290 Southlake Parkway Morrow, GA, 30260
B3: Loan Schedule | C3: ='CFS-Main Page'!C3 -> Units | D3: ='CFS-Main Page'!D3 -> 260
B4: =Rent!B4 -> 0 | C4: ='CFS-Main Page'!C4 -> Year Built/Reno | D4: ='CFS-Main Page'!D4 -> 2001
B6: Loan Assumptions - Acquisition Loan
B7: Project Cost | C7: ='Sources & Usage'!C23 -> 43425900
B8: LTV | C8: 0.7 | D8: =C9/C7 -> 0.68829892
B9: Loan Amount | C9: =IF(C12>0,ROUND('CFS-Main Page'!C7*C8,-4),0) -> 29890000
B10: Processing Fees | C10: =C9*D10 -> 298900 | D10: ='Sources & Usage'!F13 -> 0.01
B11: Amortization Period (Years) | C11: 30
B12: Loan Termination for Refinance | C12: ='CFS-Main Page'!C13 -> 5 | D12: ← Input 0 if not using
B13: Interest Rate | C13: =4.007%+1.4% -> 0.05407
B14: I/O Period | C14: 3
B15: Debt Service Constant | C15: =-PMT(C13/12,C11*12,1)*12 -> 0.067436139
B16: Annual Payment Constant | C16: =C15*C9 -> 2015666.2
B17: Loan Schedule (First) | D17: 0 | E17: 1 | F17: 2 | G17: 3 | H17: 4 | I17: 5 | J17: 6 | K17: 7 | L17: 8 | M17: 9 | N17: 10
B18: Loan Amount BB | E18: =D23 -> 29890000 | F18: =E23 -> 29890000 | G18: =F23 -> 29890000 | H18: =G23 -> 29890000 | I18: =H23 -> 29490486 | J18: =I23 -> 0 | K18: =J23 -> 0 | L18: =K23 -> 0 | ... N18: =M23 -> 0
B19: Interest Payment | E19: =IF(E17>$C$12,0,E18*$C$13) -> 1616152.3 | F19: =IF(F17>$C$12,0,F18*$C$13) -> 1616152.3 | G19: =IF(G17>$C$12,0,G18*$C$13) -> 1616152.3 | H19: =IF(H17>$C$12,0,H18*$C$13) -> 1616152.3 | I19: =IF(I17>$C$12,0,I18*$C$13) -> 1594550.6 | J19: =IF(J17>$C$12,0,J18*$C$13) -> 0 | K19: =IF(K17>$C$12,0,K18*$C$13) -> 0 | L19: =IF(L17>$C$12,0,L18*$C$13) -> 0 | ... N19: =IF(N17>$C$12,0,N18*$C$13) -> 0
B20: Principal Payment | E20: =IF(OR(E17<=$C$14,E17>$C$12),0,$C$16-E19) -> 0 | F20: =IF(OR(F17<=$C$14,F17>$C$12),0,$C$16-F19) -> 0 | G20: =IF(OR(G17<=$C$14,G17>$C$12),0,$C$16-G19) -> 0 | H20: =IF(OR(H17<=$C$14,H17>$C$12),0,$C$16-H19) -> 399513.9 | I20: =IF(OR(I17<=$C$14,I17>$C$12),0,$C$16-I19) -> 421115.62 | J20: =IF(OR(J17<=$C$14,J17>$C$12),0,$C$16-J19) -> 0 | K20: =IF(OR(K17<=$C$14,K17>$C$12),0,$C$16-K19) -> 0 | L20: =IF(OR(L17<=$C$14,L17>$C$12),0,$C$16-L19) -> 0 | ... N20: =IF(OR(N17<=$C$14,N17>$C$12),0,$C$16-N19) -> 0
B21: Loan Payoff | E21: =IF(E17=$C$12,E18-E20,0) -> 0 | F21: =IF(F17=$C$12,F18-F20,0) -> 0 | G21: =IF(G17=$C$12,G18-G20,0) -> 0 | H21: =IF(H17=$C$12,H18-H20,0) -> 0 | I21: =IF(I17=$C$12,I18-I20,0) -> 29069370 | J21: =IF(J17=$C$12,J18-J20,0) -> 0 | K21: =IF(K17=$C$12,K18-K20,0) -> 0 | L21: =IF(L17=$C$12,L18-L20,0) -> 0 | ... N21: =IF(N17=$C$12,N18-N20,0) -> 0
B22: Total Debt Payment | E22: =SUM(E19:E20) -> 1616152.3 | F22: =SUM(F19:F20) -> 1616152.3 | G22: =SUM(G19:G20) -> 1616152.3 | H22: =SUM(H19:H20) -> 2015666.2 | I22: =SUM(I19:I20) -> 2015666.2 | J22: =SUM(J19:J20) -> 0 | K22: =SUM(K19:K20) -> 0 | L22: =SUM(L19:L20) -> 0 | ... N22: =SUM(N19:N20) -> 0
B23: Loan Balance End of Year | D23: =C9 -> 29890000 | E23: =E18-E20-E21 -> 29890000 | F23: =F18-F20-F21 -> 29890000 | G23: =G18-G20-G21 -> 29890000 | H23: =H18-H20-H21 -> 29490486 | I23: =I18-I20-I21 -> 0 | J23: =J18-J20-J21 -> 0 | K23: =K18-K20-K21 -> 0 | L23: =L18-L20-L21 -> 0 | ... N23: =N18-N20-N21 -> 0
B25: Loan Assumptions - Refinance | G25: Refinancing assumptions
B26: Total cost | C26: ='Sources & Usage'!C23 -> 43425900 | G26: Year of Refinance | H26: =C12 -> 5
G27: =CONCATENATE("Year ", H26," NOI") -> Year 5 NOI | H27: {=IF(H26<1,0,INDEX('CFS-Main Page'!I63:S63,Loan!$H$26))} -> 2530775.9
B28: LTV | C28: 0.8 | G28: DCR Sizing | H28: 1.25
B29: LTC | C29: =C30/C26 -> 0
B30: Loan Amount | C30: 0 | D30: ← Input 0 if not using Refinance and Loan amount can be Hardcoded. =ROUND(IF(H26=0,C28*C26,H33),-4) | G30: Constant | H30: =-PMT(C33/12,C31*12,1)*12 -> 0.075848163
B31: Amortization Period (Years) | C31: 30 | G31: Debt Service | H31: =IF(H26=0,C30*H30,H27/H28) -> 2024620.7
B32: Loan Term (Years)_Holding | C32: =IF(H26>0,MIN('CFS-Main Page'!C13+$H$26,N35),'CFS-Main Page'!C13) -> 10 | G32: Max Proceed | H32: =ROUND(H31/H30,-4) -> 26690000
B33: Interest Rate | C33: 0.065 | G33: Bridge Loan payoff | H33: =SUM(E21:N21) -> 29069370
B34: I/O Period | C34: 10
B35: Loan Schedule (Refinance) | D35: 0 | E35: 1 | F35: 2 | G35: 3 | H35: 4 | I35: 5 | J35: 6 | K35: 7 | L35: 8 | M35: 9 | N35: 10
B36: Loan Amount BB | E36: =IF($H$26>0,IF(E$35=$H$26+1,$C$30,IF(E$35>=$H$26,D$41,0)),IF(E$35=1,$C$30,D$41)) -> 0 | F36: =IF($H$26>0,IF(F$35=$H$26+1,$C$30,IF(F$35>=$H$26,E$41,0)),IF(F$35=1,$C$30,E$41)) -> 0 | G36: =IF($H$26>0,IF(G$35=$H$26+1,$C$30,IF(G$35>=$H$26,F$41,0)),IF(G$35=1,$C$30,F$41)) -> 0 | H36: =IF($H$26>0,IF(H$35=$H$26+1,$C$30,IF(H$35>=$H$26,G$41,0)),IF(H$35=1,$C$30,G$41)) -> 0 | I36: =IF($H$26>0,IF(I$35=$H$26+1,$C$30,IF(I$35>=$H$26,H$41,0)),IF(I$35=1,$C$30,H$41)) -> 0 | J36: =IF($H$26>0,IF(J$35=$H$26+1,$C$30,IF(J$35>=$H$26,I$41,0)),IF(J$35=1,$C$30,I$41)) -> 0 | K36: =IF($H$26>0,IF(K$35=$H$26+1,$C$30,IF(K$35>=$H$26,J$41,0)),IF(K$35=1,$C$30,J$41)) -> 0 | L36: =IF($H$26>0,IF(L$35=$H$26+1,$C$30,IF(L$35>=$H$26,K$41,0)),IF(L$35=1,$C$30,K$41)) -> 0 | ... N36: =IF($H$26>0,IF(N$35=$H$26+1,$C$30,IF(N$35>=$H$26,M$41,0)),IF(N$35=1,$C$30,M$41)) -> 0
B37: Interest Payment | E37: =IF(E35>$C$32,0,E36*$C$33) -> 0 | F37: =IF(F35>$C$32,0,F36*$C$33) -> 0 | G37: =IF(G35>$C$32,0,G36*$C$33) -> 0 | H37: =IF(H35>$C$32,0,H36*$C$33) -> 0 | I37: =IF(I35>$C$32,0,I36*$C$33) -> 0 | J37: =IF(J35>$C$32,0,J36*$C$33) -> 0 | K37: =IF(K35>$C$32,0,K36*$C$33) -> 0 | L37: =IF(L35>$C$32,0,L36*$C$33) -> 0 | ... N37: =IF(N35>$C$32,0,N36*$C$33) -> 0
B38: Principal | E38: =IF(E36>0,IF(OR(E35<=$C$34,E35>$C$32),0,$H$31-E37),0) -> 0 | F38: =IF(F36>0,IF(OR(F35<=$C$34,F35>$C$32),0,$H$31-F37),0) -> 0 | G38: =IF(G36>0,IF(OR(G35<=$C$34,G35>$C$32),0,$H$31-G37),0) -> 0 | H38: =IF(H36>0,IF(OR(H35<=$C$34,H35>$C$32),0,$H$31-H37),0) -> 0 | I38: =IF(I36>0,IF(OR(I35<=$C$34,I35>$C$32),0,$H$31-I37),0) -> 0 | J38: =IF(J36>0,IF(OR(J35<=$C$34,J35>$C$32),0,$H$31-J37),0) -> 0 | K38: =IF(K36>0,IF(OR(K35<=$C$34,K35>$C$32),0,$H$31-K37),0) -> 0 | L38: =IF(L36>0,IF(OR(L35<=$C$34,L35>$C$32),0,$H$31-L37),0) -> 0 | ... N38: =IF(N36>0,IF(OR(N35<=$C$34,N35>$C$32),0,$H$31-N37),0) -> 0
B39: Loan Payoff | E39: =IF(E35=$C$32,E36-E38,0) -> 0 | F39: =IF(F35=$C$32,F36-F38,0) -> 0 | G39: =IF(G35=$C$32,G36-G38,0) -> 0 | H39: =IF(H35=$C$32,H36-H38,0) -> 0 | I39: =IF(I35=$C$32,I36-I38,0) -> 0 | J39: =IF(J35=$C$32,J36-J38,0) -> 0 | K39: =IF(K35=$C$32,K36-K38,0) -> 0 | L39: =IF(L35=$C$32,L36-L38,0) -> 0 | ... N39: =IF(N35=$C$32,N36-N38,0) -> 0
B40: Total Debt Payment | E40: =E37+E38 -> 0 | F40: =F37+F38 -> 0 | G40: =G37+G38 -> 0 | H40: =H37+H38 -> 0 | I40: =I37+I38 -> 0 | J40: =J37+J38 -> 0 | K40: =K37+K38 -> 0 | L40: =L37+L38 -> 0 | ... N40: =N37+N38 -> 0
B41: Loan Balance End of Year | D41: =IF(H26>0,0,C30) -> 0 | E41: =E$36-E$38-E$39 -> 0 | F41: =F$36-F$38-F$39 -> 0 | G41: =G$36-G$38-G$39 -> 0 | H41: =H$36-H$38-H$39 -> 0 | I41: =I$36-I$38-I$39 -> 0 | J41: =J$36-J$38-J$39 -> 0 | K41: =K$36-K$38-K$39 -> 0 | L41: =L$36-L$38-L$39 -> 0 | ... N41: =N$36-N$38-N$39 -> 0
B43: Total Principal Payment | E43: =E20+E38 -> 0 | F43: =F20+F38 -> 0 | G43: =G20+G38 -> 0 | H43: =H20+H38 -> 399513.9 | I43: =I20+I38 -> 421115.62 | J43: =J20+J38 -> 0 | K43: =K20+K38 -> 0 | L43: =L20+L38 -> 0 | ... N43: =N20+N38 -> 0
B44: Total Loan Payoff | E44: =E21+E39-(IF(E21>0,F36,0)) -> 0 | F44: =F21+F39-(IF(F21>0,G36,0)) -> 0 | G44: =G21+G39-(IF(G21>0,H36,0)) -> 0 | H44: =H21+H39-(IF(H21>0,I36,0)) -> 0 | I44: =I21+I39-(IF(I21>0,J36,0)) -> 29069370 | J44: =J21+J39-(IF(J21>0,K36,0)) -> 0 | K44: =K21+K39-(IF(K21>0,L36,0)) -> 0 | L44: =L21+L39-(IF(L21>0,M36,0)) -> 0 | ... N44: =N21+N39-(IF(N21>0,O36,0)) -> 0
...

Sheet Historical Analysis
B2: ='Sources & Usage'!B2 -> The Grove on Southlake
B3: Historical Analysis
B4: ='Sources & Usage'!B4 -> 0
D5: =1 -> 1 | E5: =D5+1 -> 2 | F5: =E5+1 -> 3 | G5: =F5+1 -> 4 | H5: =G5+1 -> 5 | I5: =H5+1 -> 6 | J5: =I5+1 -> 7 | K5: =J5+1 -> 8 | L5: =K5+1 -> 9 | ... O5: =N5+1 -> 12
C6: ="T12 ending "&TEXT(O6,"mmm-yy") -> T12 ending Feb-26 | D6: 45741 | E6: =EOMONTH(D6,1) -> 45777 | F6: =EOMONTH(E6,1) -> 45808 | G6: =EOMONTH(F6,1) -> 45838 | H6: =EOMONTH(G6,1) -> 45869 | I6: =EOMONTH(H6,1) -> 45900 | J6: =EOMONTH(I6,1) -> 45930 | K6: =EOMONTH(J6,1) -> 45961 | L6: =EOMONTH(K6,1) -> 45991 | ... O6: =EOMONTH(N6,1) -> 46081 | Q6: T12 | R6: T3 | T6: Category | V6: Summary
Q8: =SUM(D8:O8) -> 0 | R8: =SUM(M8:O8)*4 -> 0 | T8: 1 - Market Rent Potential | V8: Operating Incomes | W8: T12 | X8: T3
C9: NET RENTAL INCOME | Q9: =SUM(D9:O9) -> 0 | R9: =SUM(M9:O9)*4 -> 0 | T9: 2 - Increase in Rent from Renovation | U9: 1 | V9: Market Rent Potential | W9: =SUMIF($B$1:$B$495,U9,$Q$1:$Q$495) -> 3987608 | X9: =SUMIF($B$1:$B$495,U9,$R$1:$R$495) -> 4061152
C10: OPERATING INCOME | Q10: =SUM(D10:O10) -> 0 | R10: =SUM(M10:O10)*4 -> 0 | T10: 3 - Loss to Lease | U10: 2 | V10: Increase in Market Rent Potential from Renovation | W10: =SUMIF($B$1:$B$495,U10,$Q$1:$Q$495) -> 428760 | X10: =SUMIF($B$1:$B$495,U10,$R$1:$R$495) -> 428760
B11: 1 | C11: Gross Market Rent | D11: 312251 | E11: 321492 | F11: 334334 | G11: 328058 | H11: 318037 | I11: 342488 | J11: 353457 | K11: 332518 | L11: 329685 | M11: 338583 | N11: 337971 | O11: 338734 | Q11: =SUM(D11:O11) -> 3987608 | R11: =SUM(M11:O11)*4 -> 4061152 | T11: 4 - Vacancy | V11: Total Market Rent Potential | W11: =SUM(W9:W10) -> 4416368 | X11: =SUM(X9:X10) -> 4489912
B12: 2 | C12: Upgrade Premium | D12: 35730 | E12: 35730 | F12: 35730 | G12: 35730 | H12: 35730 | I12: 35730 | J12: 35730 | K12: 35730 | L12: 35730 | M12: 35730 | N12: 35730 | O12: 35730 | Q12: =SUM(D12:O12) -> 428760 | R12: =SUM(M12:O12)*4 -> 428760 | T12: 5 - Concession/Discount | U12: 3 | V12: Loss to Lease | W12: =SUMIF($B$1:$B$495,U12,$Q$1:$Q$495) -> -57758.52 | X12: =SUMIF($B$1:$B$495,U12,$R$1:$R$495) -> -99854.84 | Y12: =W12/W11 -> -0.013078285
B13: 3 | C13: Contract Gain(Loss) to Lease | D13: 10090.7 | E13: 2003.51 | F13: -7972.21 | G13: -708.97 | H13: 6320.44 | I13: -14318.55 | J13: -23464.62 | K13: -5737.09 | L13: 991.98 | M13: -8705.69 | N13: -6768.6 | O13: -9489.42 | Q13: =SUM(D13:O13) -> -57758.52 | R13: =SUM(M13:O13)*4 -> -99854.84 | T13: 6 - Bad Debt | V13: Gross Rent Potential | W13: =W11+W12 -> 4358609.5 | X13: =X11+X12 -> 4390057.2
C14: TOTAL GROSS POTENTIAL RENT | D14: 358071.7 | E14: 359225.51 | F14: 362091.79 | G14: 363079.03 | H14: 360087.44 | I14: 363899.45 | J14: 365722.38 | K14: 362510.91 | L14: 366406.98 | M14: 365607.31 | N14: 366932.4 | O14: 364974.58 | Q14: =SUM(D14:O14) -> 4358609.5 | R14: =SUM(M14:O14)*4 -> 4390057.2 | T14: 7 - Non Revenue Units | U14: 4 | V14: Vacancy | W14: =SUMIF($B$1:$B$495,U14,$Q$1:$Q$495) -> -284691.74 | X14: =SUMIF($B$1:$B$495,U14,$R$1:$R$495) -> -332706.12
C15: RENTAL INCOME | Q15: =SUM(D15:O15) -> 0 | R15: =SUM(M15:O15)*4 -> 0 | T15: 8 - Utility Reimbursements | U15: 5 | V15: Concession/Discount | W15: =SUMIF($B$1:$B$495,U15,$Q$1:$Q$495) -> -49856.93 | X15: =SUMIF($B$1:$B$495,U15,$R$1:$R$495) -> -80204.04
B16: 6 | C16: Bad Debt | D16: -296.42 | E16: 6249.18 | F16: -6877.02 | G16: -11615.73 | H16: -8123.55 | I16: -18144.7 | J16: -24348.84 | K16: -34087.66 | L16: -6803.95 | M16: -15375.68 | N16: -18411.01 | O16: -13287.59 | Q16: =SUM(D16:O16) -> -151122.97 | R16: =SUM(M16:O16)*4 -> -188297.12 | T16: 9 - Other Reimbursements | U16: 6 | V16: Bad Debt | W16: =SUMIF($B$1:$B$495,U16,$Q$1:$Q$495) -> -152393.61 | X16: =SUMIF($B$1:$B$495,U16,$R$1:$R$495) -> -178909.2
B17: 5 | C17: Conc - Miscellaneous | D17: -51.79 | E17: -3166.98 | F17: -300 | G17: 0 | H17: -150 | I17: -280 | J17: 0 | K17: 0 | L17: -624 | M17: -0.17 | N17: 0 | O17: -200 | Q17: =SUM(D17:O17) -> -4772.94 | R17: =SUM(M17:O17)*4 -> -800.68 | T17: 10 - Other Income | U17: 7 | V17: Non Revenue Units | W17: =SUMIF($B$1:$B$495,U17,$Q$1:$Q$495) -> -26888.73 | X17: =SUMIF($B$1:$B$495,U17,$R$1:$R$495) -> -23107.2
B18: 5 | C18: Conc - Move-in Special | D18: 0 | E18: -4650 | F18: -3500 | G18: -3000 | H18: -1150 | I18: 650.01 | J18: -500 | K18: -145.16 | L18: -500 | M18: -6704.84 | N18: -3250 | O18: -5750 | Q18: =SUM(D18:O18) -> -28499.99 | R18: =SUM(M18:O18)*4 -> -62819.36 | T18: 11 - Repair & Maintenance | V18: Gross Effective Income | W18: =SUM(W13:W17) -> 3844778.5 | X18: =SUM(X13:X17) -> 3775130.6
B19: 7 | C19: Down Units | D19: 973.29 | E19: -1394.02 | F19: -1443 | G19: -1408.35 | H19: -8759 | I19: 7445.15 | J19: 0 | K19: 0 | L19: 0 | M19: 0 | N19: 0 | O19: 0 | Q19: =SUM(D19:O19) -> -4585.93 | R19: =SUM(M19:O19)*4 -> 0 | T19: 12 - Cleaning & Decorating | U19: 8 | V19: Utility Reimbursements | W19: =SUMIF($B$1:$B$495,U19,$Q$1:$Q$495) -> 171918.41 | X19: =SUMIF($B$1:$B$495,U19,$R$1:$R$495) -> 178771.76
B20: 7 | C20: Employee Units | D20: -319.2 | E20: -331.6 | F20: -331.6 | G20: -331.6 | H20: -331.6 | I20: -331.6 | J20: -331.6 | K20: -331.6 | L20: -331.6 | M20: -331.6 | N20: -331.6 | O20: -331.6 | Q20: =SUM(D20:O20) -> -3966.8 | R20: =SUM(M20:O20)*4 -> -3979.2 | T20: 13 - Contract & Services | U20: 9 | V20: Other Reimbursements | W20: =SUMIF($B$1:$B$495,U20,$Q$1:$Q$495) -> 100364.46 | X20: =SUMIF($B$1:$B$495,U20,$R$1:$R$495) -> 106408.96
B21: 5 | C21: Courtesy Officer Discounts | D21: -1382 | E21: -1382 | F21: -1382 | G21: -1382 | H21: -1382 | I21: -1382 | J21: -1382 | K21: -1382 | L21: -1382 | M21: -1382 | N21: -1382 | O21: -1382 | Q21: =SUM(D21:O21) -> -16584 | R21: =SUM(M21:O21)*4 -> -16584 | T21: 14 - Utility- Electricity | U21: 10 | V21: Other Income | W21: =SUMIF($B$1:$B$495,U21,$Q$1:$Q$495) -> 199077.53 | X21: =SUMIF($B$1:$B$495,U21,$R$1:$R$495) -> 240180.48
B22: 7 | C22: Model Units/Admin | D22: -1439 | E22: -1465 | F22: -1486 | G22: -1453 | H22: -1363 | I22: -1514 | J22: -1663 | K22: -1588 | L22: -1583 | M22: -1626 | N22: -1594 | O22: -1562 | Q22: =SUM(D22:O22) -> -18336 | R22: =SUM(M22:O22)*4 -> -19128 | T22: 15 - Utility- Water | V22: Total Operating Revenue | W22: =SUM(W18:W21) -> 4316138.9 | X22: =SUM(X18:X21) -> 4300491.8
B23: 4 | C23: Vacancy Loss | D23: -32417.72 | E23: -16143.49 | F23: -15296.34 | G23: -12228.07 | H23: -12060.08 | I23: -25726.27 | J23: -25076.24 | K23: -31859.51 | L23: -30707.49 | M23: -29595.46 | N23: -28208.17 | O23: -25372.9 | Q23: =SUM(D23:O23) -> -284691.74 | R23: =SUM(M23:O23)*4 -> -332706.12 | T23: 16 - Utility- Others
C24: TOTAL RENTAL INCOME | D24: -34932.84 | E24: -22283.91 | F24: -30615.96 | G24: -31418.75 | H24: -33319.23 | I24: -39283.41 | J24: -53301.68 | K24: -69393.93 | L24: -41932.04 | M24: -55015.75 | N24: -53176.78 | O24: -47886.09 | Q24: =SUM(D24:O24) -> -512560.37 | R24: =SUM(M24:O24)*4 -> -624314.48 | T24: 17 - Marketing | V24: Operating Expenses | W24: T12 | X24: T3
C25: NET RENTAL INCOME | D25: 323138.86 | E25: 336941.6 | F25: 331475.83 | G25: 331660.28 | H25: 326768.21 | I25: 324616.04 | J25: 312420.7 | K25: 293116.98 | L25: 324474.94 | M25: 310591.56 | N25: 313755.62 | O25: 317088.49 | Q25: =SUM(D25:O25) -> 3846049.1 | R25: =SUM(M25:O25)*4 -> 3765742.7 | T25: 18 - Payroll | U25: 11 | V25: Repair & Maintenance | W25: =SUMIF($B$1:$B$495,U25,$Q$1:$Q$495) -> 106218.29 | X25: =SUMIF($B$1:$B$495,U25,$R$1:$R$495) -> 121923.72
C26: OTHER PROPERTY INCOME | Q26: =SUM(D26:O26) -> 0 | R26: =SUM(M26:O26)*4 -> 0 | T26: 19 - RE Taxes | U26: 12 | V26: Cleaning & Decorating | W26: =SUMIF($B$1:$B$495,U26,$Q$1:$Q$495) -> 68078.69 | X26: =SUMIF($B$1:$B$495,U26,$R$1:$R$495) -> 47325.28
B27: 6 | C27: Bad Debt - Other | D27: 108.27 | E27: 1693.9 | F27: -1050.23 | G27: -1926.41 | H27: -1168.72 | I27: -3644.99 | J27: -3686.14 | K27: 4637.34 | L27: 975.91 | M27: -1101.99 | N27: -2911.4 | O27: 6981.99 | Q27: =SUM(D27:O27) -> -1092.47 | R27: =SUM(M27:O27)*4 -> 11874.4 | T27: 20 - Insurance | U27: 13 | V27: Contract & Services | W27: =SUMIF($B$1:$B$495,U27,$Q$1:$Q$495) -> 324765.62 | X27: =SUMIF($B$1:$B$495,U27,$R$1:$R$495) -> 344526.68
B28: 10 | C28: Administrative Fees | D28: 1600 | E28: 1600 | F28: 1400 | G28: 600 | H28: 1000 | I28: 600 | J28: 400 | K28: 1200 | L28: 1800 | M28: 600 | N28: 1000 | O28: 1400 | Q28: =SUM(D28:O28) -> 13200 | R28: =SUM(M28:O28)*4 -> 12000 | T28: 21 - Property Mangement fees | U28: 14 | V28: Utility | W28: =SUMIF($B$1:$B$495,U28,$Q$1:$Q$495) -> 55412.34 | X28: =SUMIF($B$1:$B$495,U28,$R$1:$R$495) -> 64601.52
B29: 10 | C29: Amenity Fee Income | D29: 0 | E29: 0 | F29: 0 | G29: 0 | H29: 0 | I29: 30 | J29: 0 | K29: 0 | L29: 0 | M29: 0 | N29: 0 | O29: 0 | Q29: =SUM(D29:O29) -> 30 | R29: =SUM(M29:O29)*4 -> 0 | T29: 22 - General & Administrative Expenses | U29: 15 | V29: Utility- Water | W29: =SUMIF($B$1:$B$495,U29,$Q$1:$Q$495) -> 156412.9 | X29: =SUMIF($B$1:$B$495,U29,$R$1:$R$495) -> 177613.48
B30: 10 | C30: Application Fees | D30: 3700 | E30: 2200 | F30: 1100 | G30: 2100 | H30: 1900 | I30: 1400 | J30: 300 | K30: 1400 | L30: 1100 | M30: 1200 | N30: 900 | O30: 1200 | Q30: =SUM(D30:O30) -> 18500 | R30: =SUM(M30:O30)*4 -> 13200 | T30: 23 - Other taxes/Permit license fees | U30: 16 | V30: Utility- Others | W30: =SUMIF($B$1:$B$495,U30,$Q$1:$Q$495) -> 15004.14 | X30: =SUMIF($B$1:$B$495,U30,$R$1:$R$495) -> 14451.04
B31: 6 | C31: Bad Debt Recovery | D31: 2086.62 | E31: 0 | F31: 978.74 | G31: -379.17 | H31: 1047.6 | I31: -315.02 | J31: -1716.32 | K31: -794.2 | L31: -464.8 | M31: 0 | N31: -567.86 | O31: -53.76 | Q31: =SUM(D31:O31) -> -178.17 | R31: =SUM(M31:O31)*4 -> -2486.48 | T31: 24 - NOI | U31: 17 | V31: Marketing | W31: =SUMIF($B$1:$B$495,U31,$Q$1:$Q$495) -> 99450.99 | X31: =SUMIF($B$1:$B$495,U31,$R$1:$R$495) -> 110734.28
B32: 10 | C32: Carport/Garages/Parking Income | D32: 580 | E32: 580 | F32: 612.26 | G32: 683.22 | H32: 680 | I32: 847.74 | J32: 920 | K32: 980 | L32: 931.67 | M32: 1000.97 | N32: 910.64 | O32: 1030 | Q32: =SUM(D32:O32) -> 9756.5 | R32: =SUM(M32:O32)*4 -> 11766.44 | T32: 1 - Market Rent Potential | U32: 18 | V32: Payroll | W32: =SUMIF($B$1:$B$495,U32,$Q$1:$Q$495) -> 452335.06 | X32: =SUMIF($B$1:$B$495,U32,$R$1:$R$495) -> 478699.88
B33: 10 | C33: Damages Income | D33: 556.83 | E33: 80 | F33: 65 | G33: 1296 | H33: 2646.24 | I33: 937.38 | J33: 64.21 | K33: 3050.93 | L33: 2.93 | M33: 1260 | N33: 781.59 | O33: 640 | Q33: =SUM(D33:O33) -> 11381.11 | R33: =SUM(M33:O33)*4 -> 10726.36 | T33: 2 - Increase in Rent from Renovation | U33: 19 | V33: RE Taxes | W33: =SUMIF($B$1:$B$495,U33,$Q$1:$Q$495) -> 517420.94 | X33: =SUMIF($B$1:$B$495,U33,$R$1:$R$495) -> 515612.56
B34: 10 | C34: Interest Income | D34: 2.88 | E34: 4.13 | F34: 3.45 | G34: 6.18 | H34: 8.75 | I34: 5.67 | J34: 4.14 | K34: 4.97 | L34: 7.75 | M34: 8.44 | N34: 3.63 | O34: 2.69 | Q34: =SUM(D34:O34) -> 62.68 | R34: =SUM(M34:O34)*4 -> 59.04 | T34: 3 - Loss to Lease | U34: 20 | V34: Insurance | W34: =SUMIF($B$1:$B$495,U34,$Q$1:$Q$495) -> 287361.82 | X34: =SUMIF($B$1:$B$495,U34,$R$1:$R$495) -> 285043.88
B35: 10 | C35: Key & Access Card Income | D35: 385 | E35: 300 | F35: 150 | G35: 150 | H35: 30 | I35: 0 | J35: 60 | K35: 0 | L35: 30 | M35: 0 | N35: 60 | O35: 0 | Q35: =SUM(D35:O35) -> 1165 | R35: =SUM(M35:O35)*4 -> 240 | T35: 4 - Vacancy | U35: 21 | V35: Property Mangement fees | W35: =SUMIF($B$1:$B$495,U35,$Q$1:$Q$495) -> 108042.23 | X35: =SUMIF($B$1:$B$495,U35,$R$1:$R$495) -> 107512.8 | Y35: =W35/W18 -> 0.028101029
B36: 10 | C36: Late Charges | D36: 3581.7 | E36: 4964.95 | F36: 5837.64 | G36: 6769.3 | H36: 5249.24 | I36: 6326.63 | J36: 7986.49 | K36: 5945.33 | L36: 6359.74 | M36: 6228.59 | N36: 5930.84 | O36: 6711.39 | Q36: =SUM(D36:O36) -> 71891.84 | R36: =SUM(M36:O36)*4 -> 75483.28 | T36: 5 - Concession/Discount | U36: 22 | V36: General & Administrative Expenses | W36: =SUMIF($B$1:$B$495,U36,$Q$1:$Q$495) -> 95425.62 | X36: =SUMIF($B$1:$B$495,U36,$R$1:$R$495) -> 120435.84
B37: 10 | C37: Lease Violation Income | D37: 2804.02 | E37: 150 | F37: 25.01 | G37: 0 | H37: 194.52 | I37: 3382 | J37: 0 | K37: 5234.9 | L37: -626 | M37: 4867.38 | N37: 2754 | O37: 3277 | Q37: =SUM(D37:O37) -> 22062.83 | R37: =SUM(M37:O37)*4 -> 43593.52 | T37: 6 - Bad Debt | U37: 23 | V37: Other taxes/Permit license fees | W37: =SUMIF($B$1:$B$495,U37,$Q$1:$Q$495) -> 20020.2 | X37: =SUMIF($B$1:$B$495,U37,$R$1:$R$495) -> 36049.12
B38: 10 | C38: Legal & Collections | D38: 60 | E38: 367.81 | F38: 700 | G38: 400 | H38: 525 | I38: 935 | J38: 672.87 | K38: 1137.13 | L38: 2345 | M38: 2470 | N38: 2910 | O38: 3180.63 | Q38: =SUM(D38:O38) -> 15703.44 | R38: =SUM(M38:O38)*4 -> 34242.52 | T38: 7 - Non Revenue Units | V38: Operating Expenses | W38: =SUM(W25:W37) -> 2305948.8 | X38: =SUM(X25:X37) -> 2424530.1
B39: 10 | C39: Miscellaneous Income | D39: 297.58 | E39: -325.33 | F39: 200 | G39: 0 | H39: 878.02 | I39: 0 | J39: 0 | K39: 0 | L39: 0 | M39: 0 | N39: 0 | O39: 0 | Q39: =SUM(D39:O39) -> 1050.27 | R39: =SUM(M39:O39)*4 -> 0 | T39: 8 - Utility Reimbursements
B40: 10 | C40: NSF Check Fees | D40: -50 | E40: 0 | F40: 50 | G40: 100 | H40: 50 | I40: 100 | J40: 50 | K40: 0 | L40: 300 | M40: 250 | N40: 200 | O40: 0 | Q40: =SUM(D40:O40) -> 1050 | R40: =SUM(M40:O40)*4 -> 1800 | T40: 9 - Other Reimbursements | V40: Net Operating Income (NOI) | W40: =W22-W38 -> 2010190 | X40: =X22-X38 -> 1875961.7
B41: 10 | C41: Pet Fees | D41: 400 | E41: 400 | F41: 0 | G41: 0 | H41: 400 | I41: 400 | J41: 0 | K41: 0 | L41: 400 | M41: 800 | N41: 0 | O41: 0 | Q41: =SUM(D41:O41) -> 2800 | R41: =SUM(M41:O41)*4 -> 3200 | T41: 10 - Other Income | U41: 25 | V41: Replacement Reserve | W41: =SUMIF($B$1:$B$495,U41,$Q$1:$Q$495) -> 0 | X41: =SUMIF($B$1:$B$495,U41,$R$1:$R$495) -> 0
B42: 10 | C42: Pet Rent | D42: 405.18 | E42: 405 | F42: 420.33 | G42: 439.17 | H42: 463.06 | I42: 483.23 | J42: 499.17 | K42: 457.42 | L42: 355.81 | M42: 482.5 | N42: 492.9 | O42: 541.61 | Q42: =SUM(D42:O42) -> 5445.38 | R42: =SUM(M42:O42)*4 -> 6068.04 | T42: 11 - Repair & Maintenance | U42: 24 | V42: NOI as per T 12 | W42: =SUMIF($B$1:$B$495,U42,$Q$1:$Q$495) -> 2010190 | X42: =SUMIF($B$1:$B$495,U42,$R$1:$R$495) -> 1875961.7
...

Sheet Rent Comp
A1: Property Id | B1: Map # | C1: Building Name | D1: Link to Website | E1: Address | F1: Rating | G1: Apartments.com Ad Level | H1: Common View Last 60 Days | I1: % Overlap with Subject Property | J1: Units | K1: Stories | L1: Yr Blt/Ren | M1: Avg SF | N1: mi Away | O1: Rent/SF | P1: Rent/Unit | Q1: Studio | R1: 1 bed | S1: SqFt | T1: Rent psf | U1: 2 Beds | V1: SqFt | W1: Rent psf | X1: 3 beds | Y1: SqFt | Z1: Rent psf | AA1: Occ % | AB1: Concess % | AE1: #3 Beds | AF1: Neighborhood
C6: Subject Property | O6: Actual rents from Rent Roll
C7: ='CFS-Main Page'!B2 -> The Grove on Southlake | D7: Link | E7: ='CFS-Main Page'!D2 -> 7290 Southlake Parkway Morrow, GA, 30260 | J7: =Units -> 260 | L7: ='CFS-Main Page'!D4 -> 2001 | O7: =Rent!J31 -> 1.3925691 | P7: =Rent!J30 -> 1447.9077 | R7: =Rent!G5 -> 1292.2824 | S7: =AVERAGE(Rent!I9:I10,Rent!I15:I16) -> 981.5 | T7: =R7/S7 -> 1.3166402 | U7: =Rent!I5 -> 1487.558 | V7: =AVERAGE(Rent!I11:I12) -> 825 | W7: =U7/V7 -> 1.8031006 | X7: =Rent!K5 -> 1643.8853 | Y7: =AVERAGE(Rent!I13:I14) -> 1127 | Z7: =X7/Y7 -> 1.4586383 | AA7: =Rent!H29 -> 0.91923077
C9: Comps
A10: 1 | C10: Fieldstone By Trion Living | D10: Link | E10: 2615 Mount Zion Parkway Jonesboro, GA 30236 | J10: 216 | L10: 2003 | N10: 1.75 | R10: 1288 | S10: 757 | T10: =R10/S10 -> 1.7014531 | U10: 1532 | V10: 1085 | W10: =U10/V10 -> 1.4119816 | X10: 1952 | Y10: 1341 | Z10: =X10/Y10 -> 1.4556301 | AA10: 0.958
A11: =A10+1 -> 2 | C11: Battle Creek Village Townhomes | D11: Link | E11: 1174 Battle Creek Road Jonesboro, GA 30236 | J11: 250 | L11: 2003 | N11: 1.07 | U11: 1715 | V11: 1216 | W11: =U11/V11 -> 1.4103618 | X11: 1850 | Y11: 1363 | Z11: =X11/Y11 -> 1.3573001 | AA11: 0.996
A12: =A11+1 -> 3 | C12: Novo Stockbridge | D12: Link | E12: 3151 Mount Zion Road Stockbridge, GA 30281 | J12: 294 | L12: 2023 | N12: 2.71 | R12: 1554 | S12: 756 | T12: =R12/S12 -> 2.0555556 | U12: 1790 | V12: 1176 | W12: =U12/V12 -> 1.5221088 | X12: 2160 | Y12: 1248 | Z12: =X12/Y12 -> 1.7307692 | AA12: 0.956
A13: =A12+1 -> 4 | C13: Rovena at Mt. Zion | D13: Link | E13: 7135 Mount Zion Circle Morrow, GA 30260 | J13: 384 | L13: 2025 | N13: 0.49 | R13: 1469 | S13: 693 | T13: =R13/S13 -> 2.1197691 | U13: 1774 | V13: 1024 | W13: =U13/V13 -> 1.7324219 | AA13: 0.904
A14: =A13+1 -> 5 | C14: Story Mt. Zion | D14: Link | E14: 2465 Richardson Parkway Morrow, GA 30260 | J14: 300 | L14: 2024 | N14: 1.35 | R14: 1503 | S14: 784 | T14: =R14/S14 -> 1.9170918 | U14: 1910 | V14: 1171 | W14: =U14/V14 -> 1.6310845 | X14: 2217 | Y14: 1248 | Z14: =X14/Y14 -> 1.7764423 | AA14: 0.957
Q28: Studio | R28: 1 Beds | S28: Sqft | T28: PSF | U28: 2 Beds | V28: Sqft | W28: PSF | X28: 3 Beds | Y28: Sqft | Z28: PSF
M29: A. | N29: Avg Rent of Comps | Q29: =AVERAGE(Q10:Q26) -> #DIV/0! | R29: =AVERAGE(R10:R26) -> 1453.5 | S29: =AVERAGE(S10:S26) -> 747.5 | T29: =AVERAGE(T10:T26) -> 1.9484674 | U29: =AVERAGE(U10:U26) -> 1744.2 | V29: =AVERAGE(V10:V26) -> 1134.4 | W29: =AVERAGE(W10:W26) -> 1.5415917 | X29: =AVERAGE(X10:X26) -> 2044.75 | ... Z29: =AVERAGE(Z10:Z26) -> 1.5800354
M30: B. | N30: Subject Prop Rent | Q30: =Q7 -> 0 | R30: =R7 -> 1292.2824 | S30: =S7 -> 981.5 | T30: =T7 -> 1.3166402 | U30: =U7 -> 1487.558 | V30: =V7 -> 825 | W30: =W7 -> 1.8031006 | X30: =X7 -> 1643.8853 | ... Z30: =Z7 -> 1.4586383
M32: C. | N32: C=A-B | Q32: =Q29-Q30 -> #DIV/0! | R32: =R29-R30 -> 161.21765 | T32: =T29-T30 -> 0.63182721 | U32: =U29-U30 -> 256.642 | W32: =W29-W30 -> -0.26150887 | X32: =X29-X30 -> 400.86466 | Z32: =Z29-Z30 -> 0.12139716
M33: *Source - Hello Data

Sheet Quick Comps
B1: Comp 1 | I1: Comp 2 | P1: Comp 3 | W1: Comp 4 | AD1: Comp 5 | AK1: Comp 6
B2: Units | D2: PIN/Parcel ID | I2: Units | K2: PIN/Parcel ID | P2: Units | R2: PIN/Parcel ID | W2: Units | Y2: PIN/Parcel ID | AD2: Units | AF2: PIN/Parcel ID | AK2: Units | AM2: PIN/Parcel ID
B3: Built in: | D3: Last Sales Date | I3: Built in: | K3: Last Sales Date | P3: Built in: | R3: Last Sales Date | W3: Built in: | Y3: Last Sales Date | AD3: Built in: | AF3: Last Sales Date | AK3: Built in: | AM3: Last Sales Date
B4: Managed By: | D4: Price / Unit | I4: Managed By: | K4: Price / Unit | P4: Managed By: | R4: Price / | W4: Managed By: | Y4: Price / | AD4: Managed By: | AF4: Price / | AK4: Managed By: | AM4: Price / Unit
B5: Rent Survey Date: | D5: Year Assessed | F5: Per Unit | I5: Rent Survey Date: | K5: Year Assessed | M5: Per Unit | P5: Rent Survey Date: | R5: Year Assessed | T5: Per Unit | W5: Rent Survey Date: | Y5: Year Assessed | AA5: Per Unit | AD5: Rent Survey Date: | AF5: Year Assessed | AH5: Per Unit | AK5: Rent Survey Date: | AM5: Year Assessed | AO5: Per Unit
B6: Occupancy: | D6: Land | F6: =E6/C2 -> #DIV/0! | I6: Occupancy: | K6: Land | M6: =L6/J2 -> #DIV/0! | P6: Occupancy: | R6: Land | T6: =S6/Q2 -> #DIV/0! | W6: Occupancy: | Y6: Land | AA6: =Z6/X2 -> #DIV/0! | AD6: Occupancy: | AF6: Land | AH6: =AG6/AE2 -> #DIV/0! | AK6: Occupancy: | AM6: Land | AO6: =AN6/AL2 -> #DIV/0!
B7: Last Rent Increase: | D7: Improvements | F7: =E7/C2 -> #DIV/0! | I7: Last Rent Increase: | K7: Improvements | M7: =L7/J2 -> #DIV/0! | P7: Last Rent Increase: | R7: Improvements | T7: =S7/Q2 -> #DIV/0! | W7: Last Rent Increase: | Y7: Improvements | AA7: =Z7/X2 -> #DIV/0! | AD7: Last Rent Increase: | AF7: Improvements | AH7: =AG7/AE2 -> #DIV/0! | AK7: Last Rent Increase: | AM7: Improvements | AO7: =AN7/AL2 -> #DIV/0!
B8: Concessions? | D8: Total | E8: =SUM(E6:E7) -> 0 | F8: =SUM(F6:F7) -> #DIV/0! | I8: Concessions? | K8: Total | L8: =SUM(L6:L7) -> 0 | M8: =SUM(M6:M7) -> #DIV/0! | P8: Concessions? | R8: Total | S8: =SUM(S6:S7) -> 0 | T8: =SUM(T6:T7) -> #DIV/0! | W8: Concessions? | Y8: Total | Z8: =SUM(Z6:Z7) -> 0 | AA8: =SUM(AA6:AA7) -> #DIV/0! | AD8: Concessions? | AF8: Total | AG8: =SUM(AG6:AG7) -> 0 | AH8: =SUM(AH6:AH7) -> #DIV/0! | AK8: Concessions? | AM8: Total | AN8: =SUM(AN6:AN7) -> 0 | AO8: =SUM(AO6:AO7) -> #DIV/0!
B9: Income Restricted? | D9: Tax District | I9: Income Restricted? | K9: Tax District | P9: Income Restricted? | R9: Tax District | W9: Income Restricted? | Y9: Tax District | AD9: Income Restricted? | AF9: Tax District | AK9: Income Restricted? | AM9: Tax District
B10: Tax Credit? | D10: Zoning | I10: Tax Credit? | K10: Zoning | P10: Tax Credit? | R10: Zoning | W10: Tax Credit? | Y10: Zoning | AD10: Tax Credit? | AF10: Zoning | AK10: Tax Credit? | AM10: Zoning
B11: Building Style | D11: Acres | I11: Building Style | K11: Acres | P11: Building Style | R11: Acres | W11: Building Style | Y11: Acres | AD11: Building Style | AF11: Acres | AK11: Building Style | AM11: Acres
