Workbook

Sheet Global
A1: =TEXT(C7,"") -> 607 Cedar St
A2: Global Assumptions
B6: Global Assumptions
B7: Property Name | C7: 607 Cedar St
B8: Project Type | C8: 4-Story SP
B9: Market | C9: Raleigh-Durham
B10: Submarket | C10: Cary
B11: Address | C11: 607 Cedar St
B12: City, State | C12: Cary, NC
B13: ZIP Code | C13: 27511
B14: County | C14: Wake
B16: Circuit Breaker | C16: Off
B19: Underwriting Notes & Assumptions
B21: Rent Comps
B22: 1. We have used the Nearest comp (0.7 miles) as the subject property to find Rent comps from Hello Data and added the screenshot for the rent comps as well.
B23: 2. Unit counts were not available so they are kept blank.
B25: Expenses
B26: 1. We have changed the Impact Fees assumption to $8,880/unit as per the new prompt shared by Austin. We have used Gemini as we had the Pro subscription for it.
B27: 2. We have taken the 4 story (Non Costal) assumption for Insurance costs.
B28: Taxes
B29: 1. Millage rate has been taken from the 2025 tax bill of our property.
B30: 2. Comp 1 'Meridian East Chatham' is built in 2025 so we believe the full Assessed value wasn't shown in Tax bill 2025. We've taken 2026 AV as per GIS.
B31: 3. For Comp 2 (The Walker) and 3 (Allisson at Fenton) there were Original and Adjusted Assessed values, we have taken the Adjusted values as they are used for Tax calculation as well. We've also verified with the Tax bill.
B32: Question to the team Catalyst
... B35: 3. The Broker has told us that the property status is "Under-Contract".
B36: 4. Upon additional research we found out that the property might've been sold already at $26.7MM. | G36: Source

Sheet Unit Mix_vm
A1: =TEXT(Global!$C$7,"") -> 607 Cedar St
A2: Unit Mix (Vetting Model Only)
B4: Total Units | D4: 500
B6: Floorplan | C6: Type | D6: # | E6: % | F6: SF | G6: $ | H6: PSF
B7: Studio | C7: Studio | D7: =ROUND($D$4*E7,0) -> 0 | E7: 0 | F7: 0 | G7: 0 | H7: =IFERROR(G7/F7,0) -> 0 | K7: 1) Meridian East Chatham
B8: 1 Bedroom | C8: 1 Bedroom | D8: =ROUND($D$4*E8,0) -> 300 | E8: 0.6 | F8: 800 | G8: 2150 | H8: =IFERROR(G8/F8,0) -> 2.6875 | K8: Type | L8: # | M8: % | N8: SF | O8: Rent | P8: Rent PSF | R8: Type | S8: Multifamily
B9: 2 Bedroom | C9: 2 Bedroom | D9: =ROUND($D$4*E9,0) -> 200 | E9: 0.4 | F9: 1050 | G9: 3050 | H9: =IFERROR(G9/F9,0) -> 2.9047619 | K9: Studio | M9: =L9/$L$14 -> #DIV/0! | N9: 640 | O9: 1920 | P9: =IFERROR(O9/N9,"-") -> 3 | R9: Year Built | S9: 2025
B10: 3 Bedroom | C10: 3 Bedroom | D10: =ROUND($D$4*E10,0) -> 0 | E10: 0 | F10: 0 | G10: 0 | H10: =IFERROR(G10/F10,0) -> 0 | K10: 1 BR | M10: =L10/$L$14 -> #DIV/0! | N10: 800 | O10: 2336 | P10: =IFERROR(O10/N10,"-") -> 2.92 | R10: Vacancy | S10: 0.605
B11: Townhouse | C11: Townhouse | D11: =ROUND($D$4*E11,0) -> 0 | E11: 0 | F11: 0 | G11: 0 | H11: =IFERROR(G11/F11,0) -> 0 | K11: 2 BR | M11: =L11/$L$14 -> #DIV/0! | N11: 1214 | O11: 3312 | P11: =IFERROR(O11/N11,"-") -> 2.7281713 | R11: Developer
E12: 0 | H12: =IFERROR(G12/F12,0) -> 0 | K12: 3 BR | M12: =L12/$L$14 -> #DIV/0! | N12: 1527 | O12: 4339 | P12: =IFERROR(O12/N12,"-") -> 2.8415193 | R12: Owner | S12: MERIDIAN EAST CHATHAM LLC
E13: 0 | H13: =IFERROR(G13/F13,0) -> 0 | K13: TH | M13: =L13/$L$14 -> #DIV/0! | P13: =IFERROR(O13/N13,"-") -> - | R13: Link to Website | S13: Link
E14: 0 | H14: =IFERROR(G14/F14,0) -> 0 | K14: Total | L14: =SUM(L9:L13) -> 0 | M14: =SUM(M9:M13) -> #DIV/0! | N14: =SUMPRODUCT(N9:N13,L9:L13)/L14 -> #DIV/0! | O14: =SUMPRODUCT(O9:O13,$L$9:$L$13)/$L$14 -> #DIV/0! | P14: =IFERROR(O14/N14,"-") -> -
B15: Total | D15: =+SUM(D7:D14) -> 500 | E15: =+SUM(E7:E14) -> 1 | F15: =IFERROR(SUMPRODUCT(F7:F14,D7:D14)/D15,0) -> 900 | G15: =IFERROR(SUMPRODUCT(G7:G14,E7:E14)/E15,0) -> 2510 | H15: =IFERROR(G15/F15,0) -> 2.7888889
K16: 2) The Walker
B17: Studio | D17: =SUMIF($C$7:$C$14,$B17,D$7:D$14) -> 0 | E17: =IFERROR(D17/D$22,0) -> 0 | F17: {=IFERROR(SUMPRODUCT(($C$7:$C$14=$B17)*($D$7:$D$14)*($F$7:$F$14))/$D17,0)} -> 0 | G17: {=IFERROR(SUMPRODUCT(($C$7:$C$14=$B17)*($D$7:$D$14)*($G$7:$G$14))/$D17,0)} -> 0 | H17: =IFERROR(G17/F17,0) -> 0 | K17: Type | L17: # | M17: % | N17: SF | O17: Rent | P17: Rent PSF | R17: Type | S17: Multifamily
B18: 1 Bedroom | D18: =SUMIF($C$7:$C$14,$B18,D$7:D$14) -> 300 | E18: =IFERROR(D18/D$22,0) -> 0.6 | F18: {=IFERROR(SUMPRODUCT(($C$7:$C$14=$B18)*($D$7:$D$14)*($F$7:$F$14))/$D18,0)} -> 800 | G18: {=IFERROR(SUMPRODUCT(($C$7:$C$14=$B18)*($D$7:$D$14)*($G$7:$G$14))/$D18,0)} -> 2150 | H18: =IFERROR(G18/F18,0) -> 2.6875 | K18: Studio | M18: =L18/$L$14 -> #DIV/0! | N18: 514 | O18: 1775 | P18: =IFERROR(O18/N18,"-") -> 3.4533074 | R18: Year Built | S18: 2021
B19: 2 Bedroom | D19: =SUMIF($C$7:$C$14,$B19,D$7:D$14) -> 200 | E19: =IFERROR(D19/D$22,0) -> 0.4 | F19: {=IFERROR(SUMPRODUCT(($C$7:$C$14=$B19)*($D$7:$D$14)*($F$7:$F$14))/$D19,0)} -> 1050 | G19: {=IFERROR(SUMPRODUCT(($C$7:$C$14=$B19)*($D$7:$D$14)*($G$7:$G$14))/$D19,0)} -> 3050 | H19: =IFERROR(G19/F19,0) -> 2.9047619 | K19: 1 BR | M19: =L19/$L$14 -> #DIV/0! | N19: 860 | O19: 2072 | P19: =IFERROR(O19/N19,"-") -> 2.4093023 | R19: Vacancy | S19: 0.026
B20: 3 Bedroom | D20: =SUMIF($C$7:$C$14,$B20,D$7:D$14) -> 0 | E20: =IFERROR(D20/D$22,0) -> 0 | F20: {=IFERROR(SUMPRODUCT(($C$7:$C$14=$B20)*($D$7:$D$14)*($F$7:$F$14))/$D20,0)} -> 0 | G20: {=IFERROR(SUMPRODUCT(($C$7:$C$14=$B20)*($D$7:$D$14)*($G$7:$G$14))/$D20,0)} -> 0 | H20: =IFERROR(G20/F20,0) -> 0 | K20: 2 BR | M20: =L20/$L$14 -> #DIV/0! | N20: 1322 | O20: 3073 | P20: =IFERROR(O20/N20,"-") -> 2.3245083 | R20: Developer
B21: Townhouse | D21: =SUMIF($C$7:$C$14,$B21,D$7:D$14) -> 0 | E21: =IFERROR(D21/D$22,0) -> 0 | F21: {=IFERROR(SUMPRODUCT(($C$7:$C$14=$B21)*($D$7:$D$14)*($F$7:$F$14))/$D21,0)} -> 0 | G21: {=IFERROR(SUMPRODUCT(($C$7:$C$14=$B21)*($D$7:$D$14)*($G$7:$G$14))/$D21,0)} -> 0 | H21: =IFERROR(G21/F21,0) -> 0 | K21: 3 BR | M21: =L21/$L$14 -> #DIV/0! | P21: =IFERROR(O21/N21,"-") -> - | R21: Owner | S21: Academy Park Cary Llc
B22: Total | D22: =SUM(D17:D21) -> 500 | E22: =SUM(E17:E21) -> 1 | F22: =IFERROR(SUMPRODUCT(F17:F21,$D17:$D21)/$D22,0) -> 900 | G22: =IFERROR(SUMPRODUCT(G17:G21,$D17:$D21)/$D22,0) -> 2510 | H22: =IFERROR(G22/F22,0) -> 2.7888889 | K22: TH | M22: =L22/$L$14 -> #DIV/0! | P22: =IFERROR(O22/N22,"-") -> - | R22: Link to Website | S22: Link
K23: Total | L23: =SUM(L18:L22) -> 0 | M23: =SUM(M18:M22) -> #DIV/0! | N23: =SUMPRODUCT(N18:N22,$L$18:$L$22)/$L$23 -> #DIV/0! | O23: =SUMPRODUCT(O18:O22,$L$18:$L$22)/$L$23 -> #DIV/0! | P23: =IFERROR(O23/N23,"-") -> -
K25: 3) Keystone at James Landing
K26: Type | L26: # | M26: % | N26: SF | O26: Rent | P26: Rent PSF | R26: Type | S26: Multifamily
K27: Studio | M27: =L27/$L$14 -> #DIV/0! | N27: 588 | O27: 1549 | P27: =IFERROR(O27/N27,"-") -> 2.6343537 | R27: Year Built | S27: 2022
K28: 1 BR | M28: =L28/$L$14 -> #DIV/0! | N28: 772 | O28: 1897 | P28: =IFERROR(O28/N28,"-") -> 2.4572539 | R28: Vacancy | S28: 0.059
K29: 2 BR | M29: =L29/$L$14 -> #DIV/0! | N29: 1086 | O29: 2614 | P29: =IFERROR(O29/N29,"-") -> 2.4069982 | R29: Developer
K30: 3 BR | M30: =L30/$L$14 -> #DIV/0! | P30: =IFERROR(O30/N30,"-") -> - | R30: Owner | S30: Usef Hcg Fenton Llc
K31: TH | M31: =L31/$L$14 -> #DIV/0! | P31: =IFERROR(O31/N31,"-") -> - | R31: Link to Website | S31: Link
K32: Total | L32: =SUM(L27:L31) -> 0 | M32: =SUM(M27:M31) -> #DIV/0! | N32: =SUMPRODUCT(N27:N31,$L$27:$L$31)/$L$32 -> #DIV/0! | O32: =SUMPRODUCT(O27:O31,$L$27:$L$31)/$L$32 -> #DIV/0! | P32: =IFERROR(O32/N32,"-") -> -

Sheet Budget_vm
A1: =TEXT(Global!$C$7,"") -> 607 Cedar St
A2: Budget (Vetting Model Only)
B6: Budget | C6: Cost Type | D6: $ | E6: Per Unit | F6: Per NRSF | G6: % of Total
B7: Land | M7: Soruces & Uses | N7: $ | O7: Per Unit | P7: Per NRSF | Q7: % of Total
B8: Land Acquisition | C8: Land | D8: =E8*'Unit Mix_vm'!$D$15 -> 26700000 | E8: 53400 | F8: =IFERROR(E8/'Unit Mix_vm'!$F$15,0) -> 59.333333 | G8: =+IFERROR(D8/D$86,0) -> 0.18746404 | M8: Sources:
M9: JV Equity | N9: =N41 -> 56970927 | O9: =IFERROR(N9/'Unit Mix_vm'!$D$15,0) -> 113941.85 | P9: =IFERROR(O9/'Unit Mix_vm'!$F$15,0) -> 126.60206 | Q9: =IFERROR(N9/N$12,0) -> 0.4
B10: Financing Costs | M10: Preferred Equity | N10: =+N36 -> 0 | O10: =IFERROR(N10/'Unit Mix_vm'!$D$15,0) -> 0 | P10: =IFERROR(O10/'Unit Mix_vm'!$F$15,0) -> 0 | Q10: =IFERROR(N10/N$12,0) -> 0
B11: Construction Loan Broker Fee | C11: Soft Costs | D11: =+IF(Global!$C$16="On",0,I11*$N$11) -> 427281.95 | E11: =IFERROR(D11/'Unit Mix_vm'!$D$15,0) -> 854.56391 | F11: =IFERROR(E11/'Unit Mix_vm'!$F$15,0) -> 0.94951545 | G11: =+IFERROR(D11/D$86,0) -> 0.003 | I11: 0.005 | J11: < % of Loan Commitment | M11: Construction Loan | N11: =+N23 -> 85456391 | O11: =IFERROR(N11/'Unit Mix_vm'!$D$15,0) -> 170912.78 | P11: =IFERROR(O11/'Unit Mix_vm'!$F$15,0) -> 189.90309 | Q11: =IFERROR(N11/N$12,0) -> 0.6
B12: Construction Loan Origination Fee | C12: Soft Costs | D12: =+IF(Global!$C$16="On",0,I12*$N$11) -> 640922.93 | E12: =IFERROR(D12/'Unit Mix_vm'!$D$15,0) -> 1281.8459 | F12: =IFERROR(E12/'Unit Mix_vm'!$F$15,0) -> 1.4242732 | G12: =+IFERROR(D12/D$86,0) -> 0.0045 | I12: 0.0075 | J12: < % of Loan Commitment | M12: Total Sources | N12: =SUM(N9:N11) -> 1.4242732e+08 | O12: =SUM(O9:O11) -> 284854.64 | P12: =SUM(P9:P11) -> 316.50515 | Q12: =SUM(Q9:Q11) -> 1
B13: Misc Construction Loan Fees | C13: Soft Costs | D13: 0 | E13: =IFERROR(D13/'Unit Mix_vm'!$D$15,0) -> 0 | F13: =IFERROR(E13/'Unit Mix_vm'!$F$15,0) -> 0 | G13: =+IFERROR(D13/D$86,0) -> 0
B14: Preferred Equity Broker Fee | C14: Soft Costs | D14: =+IF(Global!$C$16="On",0,I14*$N$10) -> 0 | E14: =IFERROR(D14/'Unit Mix_vm'!$D$15,0) -> 0 | F14: =IFERROR(E14/'Unit Mix_vm'!$F$15,0) -> 0 | G14: =+IFERROR(D14/D$86,0) -> 0 | I14: 0.01 | J14: < % of Pref Equity | M14: Uses:
B15: Preferred Equity Origination Fee | C15: Soft Costs | D15: =+IF(Global!$C$16="On",0,I15*$N$10) -> 0 | E15: =IFERROR(D15/'Unit Mix_vm'!$D$15,0) -> 0 | F15: =IFERROR(E15/'Unit Mix_vm'!$F$15,0) -> 0 | G15: =+IFERROR(D15/D$86,0) -> 0 | I15: 0.01 | J15: < % of Pref Equity | M15: Land | N15: =+SUMIF($C$8:$C$86,$M15,$D$8:$D$86) -> 26700000 | O15: =IFERROR(N15/'Unit Mix_vm'!$D$15,0) -> 53400 | P15: =IFERROR(O15/'Unit Mix_vm'!$F$15,0) -> 59.333333 | Q15: =IFERROR(N15/N$18,0) -> 0.18746404
B16: Misc Preferred Equity Fees | C16: Soft Costs | D16: 0 | E16: =IFERROR(D16/'Unit Mix_vm'!$D$15,0) -> 0 | F16: =IFERROR(E16/'Unit Mix_vm'!$F$15,0) -> 0 | G16: =+IFERROR(D16/D$86,0) -> 0 | M16: Hard Costs | N16: =+SUMIF($C$8:$C$86,$M16,$D$8:$D$86) -> 90000000 | O16: =IFERROR(N16/'Unit Mix_vm'!$D$15,0) -> 180000 | P16: =IFERROR(O16/'Unit Mix_vm'!$F$15,0) -> 200 | Q16: =IFERROR(N16/N$18,0) -> 0.63190125
B17: JV Equity Broker Fee | C17: Soft Costs | D17: =+IF(Global!$C$16="On",0,I17*$N$44) -> 0 | E17: =IFERROR(D17/'Unit Mix_vm'!$D$15,0) -> 0 | F17: =IFERROR(E17/'Unit Mix_vm'!$F$15,0) -> 0 | G17: =+IFERROR(D17/D$86,0) -> 0 | I17: 0 | J17: < % of LP Equity | M17: Soft Costs | N17: =+SUMIF($C$8:$C$86,$M17,$D$8:$D$86) -> 25727318 | O17: =IFERROR(N17/'Unit Mix_vm'!$D$15,0) -> 51454.635 | P17: =IFERROR(O17/'Unit Mix_vm'!$F$15,0) -> 57.171817 | Q17: =IFERROR(N17/N$18,0) -> 0.18063471
B18: JV Equity Origination Fee | C18: Soft Costs | D18: =+IF(Global!$C$16="On",0,I18*$N$44) -> 0 | E18: =IFERROR(D18/'Unit Mix_vm'!$D$15,0) -> 0 | F18: =IFERROR(E18/'Unit Mix_vm'!$F$15,0) -> 0 | G18: =+IFERROR(D18/D$86,0) -> 0 | I18: 0 | J18: < % of LP Equity | M18: Total Uses | N18: =SUM(N15:N17) -> 1.4242732e+08 | O18: =SUM(O15:O17) -> 284854.64 | P18: =SUM(P15:P17) -> 316.50515 | Q18: =SUM(Q15:Q17) -> 1
B19: Misc JV Equity Fees | C19: Soft Costs | D19: 0 | E19: =IFERROR(D19/'Unit Mix_vm'!$D$15,0) -> 0 | F19: =IFERROR(E19/'Unit Mix_vm'!$F$15,0) -> 0 | G19: =+IFERROR(D19/D$86,0) -> 0
B20: Operating Deficit | C20: Soft Costs | D20: 300000 | E20: =IFERROR(D20/'Unit Mix_vm'!$D$15,0) -> 600 | F20: =IFERROR(E20/'Unit Mix_vm'!$F$15,0) -> 0.66666667 | G20: =+IFERROR(D20/D$86,0) -> 0.0021063375
B21: RE Taxes During Construction | C21: Soft Costs | D21: 300000 | E21: =IFERROR(D21/'Unit Mix_vm'!$D$15,0) -> 600 | F21: =IFERROR(E21/'Unit Mix_vm'!$F$15,0) -> 0.66666667 | G21: =+IFERROR(D21/D$86,0) -> 0.0021063375 | M21: Financing Assumptions
B22: Interest Reserve | C22: Soft Costs | D22: =E22*'Unit Mix_vm'!$D$15 -> 3000000 | E22: 6000 | F22: =IFERROR(E22/'Unit Mix_vm'!$F$15,0) -> 6.6666667 | G22: =+IFERROR(D22/D$86,0) -> 0.021063375 | M22: Construction Loan
B23: Misc Financing Costs | C23: Soft Costs | D23: 0 | E23: =IFERROR(D23/'Unit Mix_vm'!$D$15,0) -> 0 | F23: =IFERROR(E23/'Unit Mix_vm'!$F$15,0) -> 0 | G23: =+IFERROR(D23/D$86,0) -> 0 | M23: Construction Loan | N23: =D86*N24 -> 85456391
B24: Total Financing Costs | D24: =+SUM(D11:D23) -> 4668204.9 | E24: =SUM(E11:E23) -> 9336.4098 | F24: =SUM(F11:F23) -> 10.373789 | G24: =SUM(G11:G23) -> 0.03277605 | M24: Loan-to-Cost | N24: 0.6
M25: Debt Yield (Untrended) | N25: =IFERROR('Pro-Forma_vm'!$C$39/Budget_vm!N23,0) -> 0.12927574
B26: Fees
B27: Development Fee | C27: Soft Costs | D27: =I27*(D86-D8) -> 3471819.5 | E27: =IFERROR(D27/'Unit Mix_vm'!$D$15,0) -> 6943.6391 | F27: =IFERROR(E27/'Unit Mix_vm'!$F$15,0) -> 7.7151545 | G27: =+IFERROR(D27/D$86,0) -> 0.024376079 | I27: 0.03 | J27: < % of Total Costs | M27: SOFR | N27: 0.04
B28: Construction Management Fee | C28: Soft Costs | D28: =+I28*SUM(D67:D68) -> 900000 | E28: =IFERROR(D28/'Unit Mix_vm'!$D$15,0) -> 1800 | F28: =IFERROR(E28/'Unit Mix_vm'!$F$15,0) -> 2 | G28: =+IFERROR(D28/D$86,0) -> 0.0063190125 | I28: 0.01 | J28: < % of Construction Costs | M28: Spread | N28: 0.03
B29: Acquisition Fee | C29: Soft Costs | D29: 300000 | E29: =IFERROR(D29/'Unit Mix_vm'!$D$15,0) -> 600 | F29: =IFERROR(E29/'Unit Mix_vm'!$F$15,0) -> 0.66666667 | G29: =+IFERROR(D29/D$86,0) -> 0.0021063375 | M29: All-In Rate | N29: =SUM(N27:N28) -> 0.07
B30: Total Fees | D30: =+SUM(D27:D29) -> 4671819.5 | E30: =SUM(E27:E29) -> 9343.6391 | F30: =SUM(F27:F29) -> 10.381821 | G30: =SUM(G27:G29) -> 0.032801429
M31: Months from First Draw to 1.0x DSCR | N31: 21
B32: Legal & Closing | M32: Average Loan Funded % | N32: 0.5
B33: Marketing / Start-Up | C33: Soft Costs | D33: 300000 | E33: =IFERROR(D33/'Unit Mix_vm'!$D$15,0) -> 600 | F33: =IFERROR(E33/'Unit Mix_vm'!$F$15,0) -> 0.66666667 | G33: =+IFERROR(D33/D$86,0) -> 0.0021063375 | M33: Interest Reserve Required | N33: =+N23*N29*N31*N32/12 -> 5234203.9
B34: Legal | C34: Soft Costs | D34: 400000 | E34: =IFERROR(D34/'Unit Mix_vm'!$D$15,0) -> 800 | F34: =IFERROR(E34/'Unit Mix_vm'!$F$15,0) -> 0.88888889 | G34: =+IFERROR(D34/D$86,0) -> 0.00280845 | U34: BR Insurance Calc:
B35: Debt Recording Fee | C35: Soft Costs | D35: =+IF(Global!C16="On",0,I35*N11) -> 0 | E35: =IFERROR(D35/'Unit Mix_vm'!$D$15,0) -> 0 | F35: =IFERROR(E35/'Unit Mix_vm'!$F$15,0) -> 0 | G35: =+IFERROR(D35/D$86,0) -> 0 | I35: 0 | J35: < % of Loan Commitment | M35: Preferred Equity | U35: Rate | V35: 0.45
B36: Closing Costs | C36: Soft Costs | D36: 50000 | E36: =IFERROR(D36/'Unit Mix_vm'!$D$15,0) -> 100 | F36: =IFERROR(E36/'Unit Mix_vm'!$F$15,0) -> 0.11111111 | G36: =+IFERROR(D36/D$86,0) -> 0.00035105625 | M36: Preferred Equity | N36: =D86*N37-N23 -> 0
B37: Title Insurance | C37: Soft Costs | D37: =I37*D86 -> 98274.849 | E37: =IFERROR(D37/'Unit Mix_vm'!$D$15,0) -> 196.5497 | F37: =IFERROR(E37/'Unit Mix_vm'!$F$15,0) -> 0.21838855 | G37: =+IFERROR(D37/D$86,0) -> 0.00069 | I37: 0.00069 | J37: < % of Total Costs | M37: Last-Dollar-to-Cost | N37: =+N24 -> 0.6 | U37: HC | V37: =N16 -> 90000000
B38: Builder's Risk Insurance | C38: Soft Costs | D38: =(((V40/100)*V35)*2)+60000 -> 1237085.9 | E38: =IFERROR(D38/'Unit Mix_vm'!$D$15,0) -> 2474.1717 | F38: =IFERROR(E38/'Unit Mix_vm'!$F$15,0) -> 2.7490797 | G38: =+IFERROR(D38/D$86,0) -> 0.0086857344 | M38: Pref Debt Yield (Untrended) | N38: =IFERROR('Pro-Forma_vm'!$C$39/SUM(N36,N23),0) -> 0.12927574 | U38: SC | V38: =N17 -> 25727318
B39: General Liability Insurance | C39: Soft Costs | D39: =((V45/1000)*V43)+30000 -> 275566.67 | E39: =IFERROR(D39/'Unit Mix_vm'!$D$15,0) -> 551.13334 | F39: =IFERROR(E39/'Unit Mix_vm'!$F$15,0) -> 0.61237038 | G39: =+IFERROR(D39/D$86,0) -> 0.001934788 | U39: Y0 Total Rent | V39: ='Unit Mix_vm'!D15*'Unit Mix_vm'!G15*12 -> 15060000
B40: Re-Zoning | C40: Soft Costs | D40: 0 | E40: =IFERROR(D40/'Unit Mix_vm'!$D$15,0) -> 0 | F40: =IFERROR(E40/'Unit Mix_vm'!$F$15,0) -> 0 | G40: =+IFERROR(D40/D$86,0) -> 0 | M40: JV Equity | U40: Total | V40: =SUM(V37:V39) -> 1.3078732e+08
B41: Travel Expenses | C41: Soft Costs | D41: 50000 | E41: =IFERROR(D41/'Unit Mix_vm'!$D$15,0) -> 100 | F41: =IFERROR(E41/'Unit Mix_vm'!$F$15,0) -> 0.11111111 | G41: =+IFERROR(D41/D$86,0) -> 0.00035105625 | M41: Total JV Equity | N41: =D86-N23-N36 -> 56970927
B42: Misc Legal & Closing | C42: Soft Costs | D42: 0 | E42: =IFERROR(D42/'Unit Mix_vm'!$D$15,0) -> 0 | F42: =IFERROR(E42/'Unit Mix_vm'!$F$15,0) -> 0 | G42: =+IFERROR(D42/D$86,0) -> 0 | U42: GL Insurance Calc:
B43: Total Legal & Closing | D43: =+SUM(D33:D42) -> 2410927.4 | E43: =SUM(E33:E42) -> 4821.8548 | F43: =SUM(F33:F42) -> 5.3576164 | G43: =SUM(G33:G42) -> 0.016927422 | M43: GP Co-Invest | N43: =+N41*0.1 -> 5697092.7 | O43: =+N43/N41 -> 0.1 | U43: Rate | V43: 1.1
...

Sheet Pro-Forma_vm
A1: =TEXT(Global!$C$7,"") -> 607 Cedar St
A2: Pro-Forma
C6: Untrended
C7: $ | D7: Per Unit / % | F7: Untrended RETAX | I7: RETAX Comps | J7: Link | K7: Units | L7: Year Built | M7: Tax Year | N7: AV | O7: AV / Unit | P7: Millage | Q7: Direct | R7: Direct / Unit | S7: Total | T7: Total / Unit
F8: Assessed Value | G8: =G9*'Unit Mix_vm'!$D$15 -> 204000000 | I8: Meridian East Chatham | J8: Link | K8: 220 | L8: 2025 | M8: 2025 | N8: 63558280 | O8: =N8/$K8 -> 288901.27 | P8: =0.34+0.5171 -> 0.8571 | Q8: 0 | R8: =Q8/$K8 -> 0 | S8: =N8*P8/100+Q8 -> 544758.02 | T8: =S8/$K8 -> 2476.1728
B9: Gross Potential Rent | C9: =+D9*'Unit Mix_vm'!D15*12 -> 15060000 | D9: =+'Unit Mix_vm'!G15 -> 2510 | F9: Assessed Value / Unit | G9: 408000 | I9: The Walker | J9: Link | K9: 153 | L9: 2021 | M9: 2025 | N9: 56715691 | O9: =N9/$K9 -> 370690.79 | P9: =0.34+0.5171 -> 0.8571 | Q9: 3060 | R9: =Q9/$K9 -> 20 | S9: =N9*P9/100+Q9 -> 489170.19 | T9: =S9/$K9 -> 3197.1908
B10: Concessions | C10: =-D10*C9 -> -150600 | D10: 0.01 | I10: The Allison at Fenton | J10: Link | K10: 357 | L10: 2022 | M10: 2025 | N10: 201461895 | O10: =N10/$K10 -> 564319.03 | P10: =0.34+0.5171 -> 0.8571 | Q10: 7140 | R10: =Q10/$K10 -> 20 | S10: =N10*P10/100+Q10 -> 1733869.9 | T10: =S10/$K10 -> 4856.7784
B11: Non-Revenue Units | C11: =-D11*C9 -> -30120 | D11: =1/'Unit Mix_vm'!$D$15 -> 0.002 | F11: Millage Rate | G11: =0.34+0.5171 -> 0.8571
B12: Adj. Gross Potential Rent | C12: =SUM(C9:C11) -> 14879280 | D12: =IFERROR(C12/'Unit Mix_vm'!$D$15/12,0) -> 2479.88 | F12: Direct Assessments | G12: =G13*'Unit Mix_vm'!$D$15 -> 10000
F13: Direct Assessments / Unit | G13: 20
B14: Other Income | C14: =+D14*'Unit Mix_vm'!$D$15*12 -> 1173120 | D14: =$N$57 -> 195.52 | F14: Pre-Payment Discount | G14: 0 | I14: Controllable Expenses | L14: Input | M14: Total | N14: Per Unit
B15: Commercial Income | C15: 0 | D15: =IFERROR(C15/'Unit Mix_vm'!$D$15/12,0) -> 0 | I15: Contract Services
B16: Gross Potential Income | C16: =SUM(C14:C15,C12) -> 16052400 | D16: =IFERROR(C16/'Unit Mix_vm'!$D$15/12,0) -> 2675.4 | F16: Gross RETAX | G16: =(G11*G8/100+G12)*(1-G14) -> 1758484 | I16: Landscaping | L16: 4000 | M16: =L16*12 -> 48000 | N16: =M16/'Unit Mix_vm'!$D$15 -> 96
F17: Gross RETAX / Unit | G17: =+G16/'Unit Mix_vm'!$D$15 -> 3516.968 | I17: Pest Control | L17: 3 | M17: =L17*'Unit Mix_vm'!$D$15*12 -> 18000 | N17: =M17/'Unit Mix_vm'!$D$15 -> 36
B18: Vacancy | C18: =-D18*SUM(C9,C14) -> -811656 | D18: 0.05 | I18: Janitorial | L18: 2000 | M18: =L18*12 -> 24000 | N18: =M18/'Unit Mix_vm'!$D$15 -> 48
B19: Credit Loss | C19: =-D19*SUM(C9,C14,C18) -> 0 | D19: 0 | F19: Adjustments | G19: 0 | I19: Valet Trash | L19: 10 | M19: =L19*'Unit Mix_vm'!$D$15*12 -> 60000 | N19: =M19/'Unit Mix_vm'!$D$15 -> 120
B20: Effective Gross Income | C20: =SUM(C18:C19,C16) -> 15240744 | D20: =IFERROR(C20/#REF!/12,0) -> 0 | I20: Cable / WiFi | L20: 30 | M20: =L20*'Unit Mix_vm'!$D$15*12 -> 180000 | N20: =M20/'Unit Mix_vm'!$D$15 -> 360
F21: Net RETAX | G21: =+G16+G19 -> 1758484 | I21: Alarms & Monitoring | L21: 500 | M21: =L21*12 -> 6000 | N21: =M21/'Unit Mix_vm'!$D$15 -> 12
B22: Management Fee | C22: =D22*C20 -> 419120.46 | D22: 0.0275 | F22: Net RETAX / Unit | G22: =+G21/'Unit Mix_vm'!$D$15 -> 3516.968 | I22: Elevators | L22: 1500 | M22: =L22*12 -> 18000 | N22: =M22/'Unit Mix_vm'!$D$15 -> 36
B23: Real Estate Taxes | C23: =G21 -> 1758484 | D23: =IFERROR(C23/'Unit Mix_vm'!$D$15,0) -> 3516.968 | I23: Other | L23: 0 | M23: =L23*12 -> 0 | N23: =M23/'Unit Mix_vm'!$D$15 -> 0
B24: Insurance | C24: =+D24*'Unit Mix_vm'!$D$15 -> 300000 | D24: 600 | F24: RETAX Gut Check: | I24: Total Contract Services | M24: =SUM(M16:M23) -> 354000 | N24: =M24/'Unit Mix_vm'!$D$15 -> 708
B25: HOA/POA | C25: =+D25*'Unit Mix_vm'!$D$15 -> 0 | D25: 0 | F25: Land | G25: =Budget_vm!E8 -> 53400 | I25: Utilities
B26: Other Non-Controllable Expenses | C26: =+D26*'Unit Mix_vm'!$D$15 -> 0 | D26: 0 | F26: Hard Costs | G26: =Budget_vm!E67 -> 180000 | I26: Electric - Vacant | L26: 50 | M26: =L26*'Unit Mix_vm'!$D$15*12*5% -> 15000 | N26: =M26/'Unit Mix_vm'!$D$15 -> 30
B27: Utilities | C27: =+D27*'Unit Mix_vm'!$D$15 -> 255900 | D27: =N32 -> 511.8 | F27: Total | G27: =SUM(G25:G26) -> 233400 | I27: Electric - Model | L27: 75 | M27: =L27*12 -> 900 | N27: =M27/'Unit Mix_vm'!$D$15 -> 1.8
B28: Contract Services | C28: =+D28*'Unit Mix_vm'!$D$15 -> 354000 | D28: =N24 -> 708 | F28: % of Total | G28: =G27/G9 -> 0.57205882 | I28: Electric - Common Areas | L28: 5000 | M28: =L28*12 -> 60000 | N28: =M28/'Unit Mix_vm'!$D$15 -> 120
B29: Make-Ready / Turnover | C29: =+D29*'Unit Mix_vm'!$D$15 -> 125000 | D29: 250 | I29: Water / Sewer | L29: 30 | M29: =L29*'Unit Mix_vm'!$D$15*12 -> 180000 | N29: =M29/'Unit Mix_vm'!$D$15 -> 360
B30: Repairs & Maintenance | C30: =+D30*'Unit Mix_vm'!$D$15 -> 137500 | D30: 275 | I30: Trash Removal | L30: 0 | M30: =L30*'Unit Mix_vm'!$D$15*12*5% -> 0 | N30: =M30/'Unit Mix_vm'!$D$15 -> 0
B31: Amenities | C31: =+D31*'Unit Mix_vm'!$D$15 -> 15000 | D31: 30 | I31: Other | L31: 0 | M31: =L31*12 -> 0 | N31: =M31/'Unit Mix_vm'!$D$15 -> 0
B32: Marketing | C32: =+D32*'Unit Mix_vm'!$D$15 -> 175000 | D32: 350 | I32: Total Utilities | M32: =SUM(M26:M31) -> 255900 | N32: =M32/'Unit Mix_vm'!$D$15 -> 511.8
B33: Payroll | C33: =+D33*'Unit Mix_vm'!$D$15 -> 478301.04 | D33: =N46 -> 956.60208 | I33: Payroll
B34: Office Expenses | C34: =+D34*'Unit Mix_vm'!$D$15 -> 100000 | D34: 200 | I34: Community Manager | K34: 35 | L34: 2080 | M34: =K34*L34 -> 72800 | N34: =M34/'Unit Mix_vm'!$D$15 -> 145.6
B35: General & Administrative | C35: =+D35*'Unit Mix_vm'!$D$15 -> 75000 | D35: 150 | I35: Bonus | L35: 0.2 | M35: =M34*L35 -> 14560 | N35: =M35/'Unit Mix_vm'!$D$15 -> 29.12
B36: Other Controllable Expenses | C36: =+D36*'Unit Mix_vm'!$D$15 -> 0 | D36: 0 | I36: Assistant Manager | K36: 25 | L36: 2080 | M36: =K36*L36 -> 52000 | N36: =M36/'Unit Mix_vm'!$D$15 -> 104
B37: Total Operating Expenses | C37: =+SUM(C22:C36) -> 4193305.5 | D37: =IFERROR(C37/'Unit Mix_vm'!$D$15,0) -> 8386.611 | I37: Bonus | L37: 0 | M37: =M36*L37 -> 0 | N37: =M37/'Unit Mix_vm'!$D$15 -> 0
I38: Leasing Consultant #1 | K38: 20 | L38: 2080 | M38: =K38*L38 -> 41600 | N38: =M38/'Unit Mix_vm'!$D$15 -> 83.2
B39: Net Operating Income | C39: =+C20-C37 -> 11047438 | D39: =IFERROR(C39/#REF!,0) -> 0 | I39: Leasing Consultant #2 | K39: 0 | L39: 0 | M39: =K39*L39 -> 0 | N39: =M39/'Unit Mix_vm'!$D$15 -> 0
B40: NOI Margin | C40: =IFERROR(C39/C20,0) -> 0.72486215 | I40: Service Supervisor | K40: 32 | L40: 2080 | M40: =K40*L40 -> 66560 | N40: =M40/'Unit Mix_vm'!$D$15 -> 133.12
I41: Bonus | L41: 0.1 | M41: =M40*L41 -> 6656 | N41: =M41/'Unit Mix_vm'!$D$15 -> 13.312
B42: Return on Cost | C42: =C39/Budget_vm!D86 -> 0.077565447 | I42: Maintenance Tech #1 | K42: 20 | L42: 2080 | M42: =K42*L42 -> 41600 | N42: =M42/'Unit Mix_vm'!$D$15 -> 83.2
I43: Maintenance Tech #2 | K43: 0 | L43: 0 | M43: =K43*L43 -> 0 | N43: =M43/'Unit Mix_vm'!$D$15 -> 0
...

Sheet >> Full Model >>
B2: FULL MODEL

Sheet >> Reforecast + Dispo >> 
B2: REFORECAST + DISPO
B3: MODEL

Sheet Reforecast
A1: =TEXT(Global!$C$7,"") -> 607 Cedar St
A2: Budget Reforecast
C6: Current Budget | D6: Drawn to Date | E6: Current Remaining | F6: Future Re-Allocations | G6: Revised Budget | H6: Revised Remaining | I6: Future Draws | J6: Final Outstanding | K6: Final Remaining | M6: 45382 | N6: =EOMONTH(M6,1) -> 45412 | O6: =EOMONTH(N6,1) -> 45443 | P6: =EOMONTH(O6,1) -> 45473 | Q6: =EOMONTH(P6,1) -> 45504 | R6: =EOMONTH(Q6,1) -> 45535 | S6: =EOMONTH(R6,1) -> 45565 | T6: =EOMONTH(S6,1) -> 45596 | U6: =EOMONTH(T6,1) -> 45626 | ... BT6: =EOMONTH(BS6,1) -> 47177
B8: Status | M8: Actual | N8: Actual | O8: Actual | P8: Actual | Q8: Actual | R8: Actual | S8: Actual | T8: Actual | U8: Actual | V8: Actual | W8: Actual | X8: Actual | Y8: Actual | Z8: Actual | AA8: Actual | AB8: Actual | AC8: Actual | AD8: Actual | AE8: Actual | AF8: Actual | AG8: Actual | AH8: Actual | AI8: Actual | AJ8: Actual | AK8: Actual | AL8: Actual | AM8: Actual | AN8: Actual | AO8: Actual | AP8: Actual | AQ8: Actual | AR8: Actual | AS8: Actual | AT8: Actual | AU8: Actual | AV8: Actual | AW8: Actual | AX8: Actual | AY8: Actual | AZ8: Actual | BA8: Actual | BB8: Actual | BC8: Actual | BD8: Actual | BE8: Actual | BF8: Actual | BG8: Actual | BH8: Actual | BI8: Actual | BJ8: Actual | BK8: Actual | BL8: Actual | BM8: Actual | BN8: Actual | BO8: Actual | BP8: Actual | BQ8: Actual | BR8: Actual | BS8: Actual | BT8: Actual
B10: Sources
B11: GP Equity | C11: 0 | D11: 0 | E11: =+C11-D11 -> 0 | F11: 0 | G11: =+SUM(C11,F11) -> 0 | H11: =G11-D11 -> 0 | I11: =SUM(M11:BT11) -> 0 | J11: =SUM(D11,I11) -> 0 | K11: =G11-J11 -> 0 | M11: 0 | N11: 0 | O11: 0 | P11: 0 | Q11: 0 | R11: 0 | S11: 0 | T11: 0 | U11: 0 | V11: 0 | W11: 0 | X11: 0 | Y11: 0 | Z11: 0 | AA11: 0 | AB11: 0 | AC11: 0 | AD11: 0 | AE11: 0 | AF11: 0 | AG11: 0 | AH11: 0 | AI11: 0 | AJ11: 0 | AK11: 0 | AL11: 0 | AM11: 0 | AN11: 0 | AO11: 0 | AP11: 0 | AQ11: 0 | AR11: 0 | AS11: 0 | AT11: 0 | AU11: 0 | AV11: 0 | AW11: 0 | AX11: 0 | AY11: 0 | AZ11: 0 | BA11: 0 | BB11: 0 | BC11: 0 | BD11: 0 | BE11: 0 | BF11: 0 | BG11: 0 | BH11: 0 | BI11: 0 | BJ11: 0 | BK11: 0 | BL11: 0 | BM11: 0 | BN11: 0 | BO11: 0 | BP11: 0 | BQ11: 0 | BR11: 0 | BS11: 0 | BT11: 0
B12: LP Equity | C12: 0 | D12: 0 | E12: =+C12-D12 -> 0 | F12: 0 | G12: =+SUM(C12,F12) -> 0 | H12: =G12-D12 -> 0 | I12: =SUM(M12:BT12) -> 0 | J12: =SUM(D12,I12) -> 0 | K12: =G12-J12 -> 0 | M12: 0 | N12: 0 | O12: 0 | P12: 0 | Q12: 0 | R12: 0 | S12: 0 | T12: 0 | U12: 0 | V12: 0 | W12: 0 | X12: 0 | Y12: 0 | Z12: 0 | AA12: 0 | AB12: 0 | AC12: 0 | AD12: 0 | AE12: 0 | AF12: 0 | AG12: 0 | AH12: 0 | AI12: 0 | AJ12: 0 | AK12: 0 | AL12: 0 | AM12: 0 | AN12: 0 | AO12: 0 | AP12: 0 | AQ12: 0 | AR12: 0 | AS12: 0 | AT12: 0 | AU12: 0 | AV12: 0 | AW12: 0 | AX12: 0 | AY12: 0 | AZ12: 0 | BA12: 0 | BB12: 0 | BC12: 0 | BD12: 0 | BE12: 0 | BF12: 0 | BG12: 0 | BH12: 0 | BI12: 0 | BJ12: 0 | BK12: 0 | BL12: 0 | BM12: 0 | BN12: 0 | BO12: 0 | BP12: 0 | BQ12: 0 | BR12: 0 | BS12: 0 | BT12: 0
B13: Construction Loan | C13: 0 | D13: 0 | E13: =+C13-D13 -> 0 | F13: 0 | G13: =+SUM(C13,F13) -> 0 | H13: =G13-D13 -> 0 | I13: =SUM(M13:BT13) -> 0 | J13: =SUM(D13,I13) -> 0 | K13: =G13-J13 -> 0 | M13: 0 | N13: 0 | O13: 0 | P13: 0 | Q13: 0 | R13: 0 | S13: 0 | T13: 0 | U13: 0 | V13: 0 | W13: 0 | X13: 0 | Y13: 0 | Z13: 0 | AA13: 0 | AB13: 0 | AC13: 0 | AD13: 0 | AE13: 0 | AF13: 0 | AG13: 0 | AH13: 0 | AI13: 0 | AJ13: 0 | AK13: 0 | AL13: 0 | AM13: 0 | AN13: 0 | AO13: 0 | AP13: 0 | AQ13: 0 | AR13: 0 | AS13: 0 | AT13: 0 | AU13: 0 | AV13: 0 | AW13: 0 | AX13: 0 | AY13: 0 | AZ13: 0 | BA13: 0 | BB13: 0 | BC13: 0 | BD13: 0 | BE13: 0 | BF13: 0 | BG13: 0 | BH13: 0 | BI13: 0 | BJ13: 0 | BK13: 0 | BL13: 0 | BM13: 0 | BN13: 0 | BO13: 0 | BP13: 0 | BQ13: 0 | BR13: 0 | BS13: 0 | BT13: 0
C14: 0 | D14: 0 | E14: =+C14-D14 -> 0 | F14: 0 | G14: =+SUM(C14,F14) -> 0 | H14: =G14-D14 -> 0 | I14: =SUM(M14:BT14) -> 0 | J14: =SUM(D14,I14) -> 0 | K14: =G14-J14 -> 0 | M14: 0 | N14: 0 | O14: 0 | P14: 0 | Q14: 0 | R14: 0 | S14: 0 | T14: 0 | U14: 0 | V14: 0 | W14: 0 | X14: 0 | Y14: 0 | Z14: 0 | AA14: 0 | AB14: 0 | AC14: 0 | AD14: 0 | AE14: 0 | AF14: 0 | AG14: 0 | AH14: 0 | AI14: 0 | AJ14: 0 | AK14: 0 | AL14: 0 | AM14: 0 | AN14: 0 | AO14: 0 | AP14: 0 | AQ14: 0 | AR14: 0 | AS14: 0 | AT14: 0 | AU14: 0 | AV14: 0 | AW14: 0 | AX14: 0 | AY14: 0 | AZ14: 0 | BA14: 0 | BB14: 0 | BC14: 0 | BD14: 0 | BE14: 0 | BF14: 0 | BG14: 0 | BH14: 0 | BI14: 0 | BJ14: 0 | BK14: 0 | BL14: 0 | BM14: 0 | BN14: 0 | BO14: 0 | BP14: 0 | BQ14: 0 | BR14: 0 | BS14: 0 | BT14: 0
C15: 0 | D15: 0 | E15: =+C15-D15 -> 0 | F15: 0 | G15: =+SUM(C15,F15) -> 0 | H15: =G15-D15 -> 0 | I15: =SUM(M15:BT15) -> 0 | J15: =SUM(D15,I15) -> 0 | K15: =G15-J15 -> 0 | M15: 0 | N15: 0 | O15: 0 | P15: 0 | Q15: 0 | R15: 0 | S15: 0 | T15: 0 | U15: 0 | V15: 0 | W15: 0 | X15: 0 | Y15: 0 | Z15: 0 | AA15: 0 | AB15: 0 | AC15: 0 | AD15: 0 | AE15: 0 | AF15: 0 | AG15: 0 | AH15: 0 | AI15: 0 | AJ15: 0 | AK15: 0 | AL15: 0 | AM15: 0 | AN15: 0 | AO15: 0 | AP15: 0 | AQ15: 0 | AR15: 0 | AS15: 0 | AT15: 0 | AU15: 0 | AV15: 0 | AW15: 0 | AX15: 0 | AY15: 0 | AZ15: 0 | BA15: 0 | BB15: 0 | BC15: 0 | BD15: 0 | BE15: 0 | BF15: 0 | BG15: 0 | BH15: 0 | BI15: 0 | BJ15: 0 | BK15: 0 | BL15: 0 | BM15: 0 | BN15: 0 | BO15: 0 | BP15: 0 | BQ15: 0 | BR15: 0 | BS15: 0 | BT15: 0
C16: 0 | D16: 0 | E16: =+C16-D16 -> 0 | F16: 0 | G16: =+SUM(C16,F16) -> 0 | H16: =G16-D16 -> 0 | I16: =SUM(M16:BT16) -> 0 | J16: =SUM(D16,I16) -> 0 | K16: =G16-J16 -> 0 | M16: 0 | N16: 0 | O16: 0 | P16: 0 | Q16: 0 | R16: 0 | S16: 0 | T16: 0 | U16: 0 | V16: 0 | W16: 0 | X16: 0 | Y16: 0 | Z16: 0 | AA16: 0 | AB16: 0 | AC16: 0 | AD16: 0 | AE16: 0 | AF16: 0 | AG16: 0 | AH16: 0 | AI16: 0 | AJ16: 0 | AK16: 0 | AL16: 0 | AM16: 0 | AN16: 0 | AO16: 0 | AP16: 0 | AQ16: 0 | AR16: 0 | AS16: 0 | AT16: 0 | AU16: 0 | AV16: 0 | AW16: 0 | AX16: 0 | AY16: 0 | AZ16: 0 | BA16: 0 | BB16: 0 | BC16: 0 | BD16: 0 | BE16: 0 | BF16: 0 | BG16: 0 | BH16: 0 | BI16: 0 | BJ16: 0 | BK16: 0 | BL16: 0 | BM16: 0 | BN16: 0 | BO16: 0 | BP16: 0 | BQ16: 0 | BR16: 0 | BS16: 0 | BT16: 0
B17: Total Sources | C17: =SUM(C11:C16) -> 0 | D17: =SUM(D11:D16) -> 0 | E17: =SUM(E11:E16) -> 0 | F17: =SUM(F11:F16) -> 0 | G17: =SUM(G11:G16) -> 0 | H17: =SUM(H11:H16) -> 0 | I17: =SUM(I11:I16) -> 0 | J17: =SUM(J11:J16) -> 0 | K17: =SUM(K11:K16) -> 0 | M17: =SUM(M11:M16) -> 0 | N17: =SUM(N11:N16) -> 0 | O17: =SUM(O11:O16) -> 0 | P17: =SUM(P11:P16) -> 0 | Q17: =SUM(Q11:Q16) -> 0 | R17: =SUM(R11:R16) -> 0 | S17: =SUM(S11:S16) -> 0 | T17: =SUM(T11:T16) -> 0 | ... BT17: =SUM(BT11:BT16) -> 0
B19: Uses
B20: Land Acquisition | C20: 0 | D20: 0 | E20: =+C20-D20 -> 0 | F20: 0 | G20: =+SUM(C20,F20) -> 0 | H20: =G20-D20 -> 0 | I20: =SUM(M20:BT20) -> 0 | J20: =SUM(D20,I20) -> 0 | K20: =G20-J20 -> 0 | M20: 0 | N20: 0 | O20: 0 | P20: 0 | Q20: 0 | R20: 0 | S20: 0 | T20: 0 | U20: 0 | V20: 0 | W20: 0 | X20: 0 | Y20: 0 | Z20: 0 | AA20: 0 | AB20: 0 | AC20: 0 | AD20: 0 | AE20: 0 | AF20: 0 | AG20: 0 | AH20: 0 | AI20: 0 | AJ20: 0 | AK20: 0 | AL20: 0 | AM20: 0 | AN20: 0 | AO20: 0 | AP20: 0 | AQ20: 0 | AR20: 0 | AS20: 0 | AT20: 0 | AU20: 0 | AV20: 0 | AW20: 0 | AX20: 0 | AY20: 0 | AZ20: 0 | BA20: 0 | BB20: 0 | BC20: 0 | BD20: 0 | BE20: 0 | BF20: 0 | BG20: 0 | BH20: 0 | BI20: 0 | BJ20: 0 | BK20: 0 | BL20: 0 | BM20: 0 | BN20: 0 | BO20: 0 | BP20: 0 | BQ20: 0 | BR20: 0 | BS20: 0 | BT20: 0
B21: Construction Loan Broker Fee | C21: 0 | D21: 0 | E21: =+C21-D21 -> 0 | F21: 0 | G21: =+SUM(C21,F21) -> 0 | H21: =G21-D21 -> 0 | I21: =SUM(M21:BT21) -> 0 | J21: =SUM(D21,I21) -> 0 | K21: =G21-J21 -> 0 | M21: 0 | N21: 0 | O21: 0 | P21: 0 | Q21: 0 | R21: 0 | S21: 0 | T21: 0 | U21: 0 | V21: 0 | W21: 0 | X21: 0 | Y21: 0 | Z21: 0 | AA21: 0 | AB21: 0 | AC21: 0 | AD21: 0 | AE21: 0 | AF21: 0 | AG21: 0 | AH21: 0 | AI21: 0 | AJ21: 0 | AK21: 0 | AL21: 0 | AM21: 0 | AN21: 0 | AO21: 0 | AP21: 0 | AQ21: 0 | AR21: 0 | AS21: 0 | AT21: 0 | AU21: 0 | AV21: 0 | AW21: 0 | AX21: 0 | AY21: 0 | AZ21: 0 | BA21: 0 | BB21: 0 | BC21: 0 | BD21: 0 | BE21: 0 | BF21: 0 | BG21: 0 | BH21: 0 | BI21: 0 | BJ21: 0 | BK21: 0 | BL21: 0 | BM21: 0 | BN21: 0 | BO21: 0 | BP21: 0 | BQ21: 0 | BR21: 0 | BS21: 0 | BT21: 0
B22: Construction Loan Origination Fee | C22: 0 | D22: 0 | E22: =+C22-D22 -> 0 | F22: 0 | G22: =+SUM(C22,F22) -> 0 | H22: =G22-D22 -> 0 | I22: =SUM(M22:BT22) -> 0 | J22: =SUM(D22,I22) -> 0 | K22: =G22-J22 -> 0 | M22: 0 | N22: 0 | O22: 0 | P22: 0 | Q22: 0 | R22: 0 | S22: 0 | T22: 0 | U22: 0 | V22: 0 | W22: 0 | X22: 0 | Y22: 0 | Z22: 0 | AA22: 0 | AB22: 0 | AC22: 0 | AD22: 0 | AE22: 0 | AF22: 0 | AG22: 0 | AH22: 0 | AI22: 0 | AJ22: 0 | AK22: 0 | AL22: 0 | AM22: 0 | AN22: 0 | AO22: 0 | AP22: 0 | AQ22: 0 | AR22: 0 | AS22: 0 | AT22: 0 | AU22: 0 | AV22: 0 | AW22: 0 | AX22: 0 | AY22: 0 | AZ22: 0 | BA22: 0 | BB22: 0 | BC22: 0 | BD22: 0 | BE22: 0 | BF22: 0 | BG22: 0 | BH22: 0 | BI22: 0 | BJ22: 0 | BK22: 0 | BL22: 0 | BM22: 0 | BN22: 0 | BO22: 0 | BP22: 0 | BQ22: 0 | BR22: 0 | BS22: 0 | BT22: 0
B23: Misc Construction Loan Fees | C23: 0 | D23: 0 | E23: =+C23-D23 -> 0 | F23: 0 | G23: =+SUM(C23,F23) -> 0 | H23: =G23-D23 -> 0 | I23: =SUM(M23:BT23) -> 0 | J23: =SUM(D23,I23) -> 0 | K23: =G23-J23 -> 0 | M23: 0 | N23: 0 | O23: 0 | P23: 0 | Q23: 0 | R23: 0 | S23: 0 | T23: 0 | U23: 0 | V23: 0 | W23: 0 | X23: 0 | Y23: 0 | Z23: 0 | AA23: 0 | AB23: 0 | AC23: 0 | AD23: 0 | AE23: 0 | AF23: 0 | AG23: 0 | AH23: 0 | AI23: 0 | AJ23: 0 | AK23: 0 | AL23: 0 | AM23: 0 | AN23: 0 | AO23: 0 | AP23: 0 | AQ23: 0 | AR23: 0 | AS23: 0 | AT23: 0 | AU23: 0 | AV23: 0 | AW23: 0 | AX23: 0 | AY23: 0 | AZ23: 0 | BA23: 0 | BB23: 0 | BC23: 0 | BD23: 0 | BE23: 0 | BF23: 0 | BG23: 0 | BH23: 0 | BI23: 0 | BJ23: 0 | BK23: 0 | BL23: 0 | BM23: 0 | BN23: 0 | BO23: 0 | BP23: 0 | BQ23: 0 | BR23: 0 | BS23: 0 | BT23: 0
B24: Preferred Equity Broker Fee | C24: 0 | D24: 0 | E24: =+C24-D24 -> 0 | F24: 0 | G24: =+SUM(C24,F24) -> 0 | H24: =G24-D24 -> 0 | I24: =SUM(M24:BT24) -> 0 | J24: =SUM(D24,I24) -> 0 | K24: =G24-J24 -> 0 | M24: 0 | N24: 0 | O24: 0 | P24: 0 | Q24: 0 | R24: 0 | S24: 0 | T24: 0 | U24: 0 | V24: 0 | W24: 0 | X24: 0 | Y24: 0 | Z24: 0 | AA24: 0 | AB24: 0 | AC24: 0 | AD24: 0 | AE24: 0 | AF24: 0 | AG24: 0 | AH24: 0 | AI24: 0 | AJ24: 0 | AK24: 0 | AL24: 0 | AM24: 0 | AN24: 0 | AO24: 0 | AP24: 0 | AQ24: 0 | AR24: 0 | AS24: 0 | AT24: 0 | AU24: 0 | AV24: 0 | AW24: 0 | AX24: 0 | AY24: 0 | AZ24: 0 | BA24: 0 | BB24: 0 | BC24: 0 | BD24: 0 | BE24: 0 | BF24: 0 | BG24: 0 | BH24: 0 | BI24: 0 | BJ24: 0 | BK24: 0 | BL24: 0 | BM24: 0 | BN24: 0 | BO24: 0 | BP24: 0 | BQ24: 0 | BR24: 0 | BS24: 0 | BT24: 0
B25: Preferred Equity Origination Fee | C25: 0 | D25: 0 | E25: =+C25-D25 -> 0 | F25: 0 | G25: =+SUM(C25,F25) -> 0 | H25: =G25-D25 -> 0 | I25: =SUM(M25:BT25) -> 0 | J25: =SUM(D25,I25) -> 0 | K25: =G25-J25 -> 0 | M25: 0 | N25: 0 | O25: 0 | P25: 0 | Q25: 0 | R25: 0 | S25: 0 | T25: 0 | U25: 0 | V25: 0 | W25: 0 | X25: 0 | Y25: 0 | Z25: 0 | AA25: 0 | AB25: 0 | AC25: 0 | AD25: 0 | AE25: 0 | AF25: 0 | AG25: 0 | AH25: 0 | AI25: 0 | AJ25: 0 | AK25: 0 | AL25: 0 | AM25: 0 | AN25: 0 | AO25: 0 | AP25: 0 | AQ25: 0 | AR25: 0 | AS25: 0 | AT25: 0 | AU25: 0 | AV25: 0 | AW25: 0 | AX25: 0 | AY25: 0 | AZ25: 0 | BA25: 0 | BB25: 0 | BC25: 0 | BD25: 0 | BE25: 0 | BF25: 0 | BG25: 0 | BH25: 0 | BI25: 0 | BJ25: 0 | BK25: 0 | BL25: 0 | BM25: 0 | BN25: 0 | BO25: 0 | BP25: 0 | BQ25: 0 | BR25: 0 | BS25: 0 | BT25: 0
B26: Misc Preferred Equity Fees | C26: 0 | D26: 0 | E26: =+C26-D26 -> 0 | F26: 0 | G26: =+SUM(C26,F26) -> 0 | H26: =G26-D26 -> 0 | I26: =SUM(M26:BT26) -> 0 | J26: =SUM(D26,I26) -> 0 | K26: =G26-J26 -> 0 | M26: 0 | N26: 0 | O26: 0 | P26: 0 | Q26: 0 | R26: 0 | S26: 0 | T26: 0 | U26: 0 | V26: 0 | W26: 0 | X26: 0 | Y26: 0 | Z26: 0 | AA26: 0 | AB26: 0 | AC26: 0 | AD26: 0 | AE26: 0 | AF26: 0 | AG26: 0 | AH26: 0 | AI26: 0 | AJ26: 0 | AK26: 0 | AL26: 0 | AM26: 0 | AN26: 0 | AO26: 0 | AP26: 0 | AQ26: 0 | AR26: 0 | AS26: 0 | AT26: 0 | AU26: 0 | AV26: 0 | AW26: 0 | AX26: 0 | AY26: 0 | AZ26: 0 | BA26: 0 | BB26: 0 | BC26: 0 | BD26: 0 | BE26: 0 | BF26: 0 | BG26: 0 | BH26: 0 | BI26: 0 | BJ26: 0 | BK26: 0 | BL26: 0 | BM26: 0 | BN26: 0 | BO26: 0 | BP26: 0 | BQ26: 0 | BR26: 0 | BS26: 0 | BT26: 0
B27: JV Equity Broker Fee | C27: 0 | D27: 0 | E27: =+C27-D27 -> 0 | F27: 0 | G27: =+SUM(C27,F27) -> 0 | H27: =G27-D27 -> 0 | I27: =SUM(M27:BT27) -> 0 | J27: =SUM(D27,I27) -> 0 | K27: =G27-J27 -> 0 | M27: 0 | N27: 0 | O27: 0 | P27: 0 | Q27: 0 | R27: 0 | S27: 0 | T27: 0 | U27: 0 | V27: 0 | W27: 0 | X27: 0 | Y27: 0 | Z27: 0 | AA27: 0 | AB27: 0 | AC27: 0 | AD27: 0 | AE27: 0 | AF27: 0 | AG27: 0 | AH27: 0 | AI27: 0 | AJ27: 0 | AK27: 0 | AL27: 0 | AM27: 0 | AN27: 0 | AO27: 0 | AP27: 0 | AQ27: 0 | AR27: 0 | AS27: 0 | AT27: 0 | AU27: 0 | AV27: 0 | AW27: 0 | AX27: 0 | AY27: 0 | AZ27: 0 | BA27: 0 | BB27: 0 | BC27: 0 | BD27: 0 | BE27: 0 | BF27: 0 | BG27: 0 | BH27: 0 | BI27: 0 | BJ27: 0 | BK27: 0 | BL27: 0 | BM27: 0 | BN27: 0 | BO27: 0 | BP27: 0 | BQ27: 0 | BR27: 0 | BS27: 0 | BT27: 0
B28: JV Equity Origination Fee | C28: 0 | D28: 0 | E28: =+C28-D28 -> 0 | F28: 0 | G28: =+SUM(C28,F28) -> 0 | H28: =G28-D28 -> 0 | I28: =SUM(M28:BT28) -> 0 | J28: =SUM(D28,I28) -> 0 | K28: =G28-J28 -> 0 | M28: 0 | N28: 0 | O28: 0 | P28: 0 | Q28: 0 | R28: 0 | S28: 0 | T28: 0 | U28: 0 | V28: 0 | W28: 0 | X28: 0 | Y28: 0 | Z28: 0 | AA28: 0 | AB28: 0 | AC28: 0 | AD28: 0 | AE28: 0 | AF28: 0 | AG28: 0 | AH28: 0 | AI28: 0 | AJ28: 0 | AK28: 0 | AL28: 0 | AM28: 0 | AN28: 0 | AO28: 0 | AP28: 0 | AQ28: 0 | AR28: 0 | AS28: 0 | AT28: 0 | AU28: 0 | AV28: 0 | AW28: 0 | AX28: 0 | AY28: 0 | AZ28: 0 | BA28: 0 | BB28: 0 | BC28: 0 | BD28: 0 | BE28: 0 | BF28: 0 | BG28: 0 | BH28: 0 | BI28: 0 | BJ28: 0 | BK28: 0 | BL28: 0 | BM28: 0 | BN28: 0 | BO28: 0 | BP28: 0 | BQ28: 0 | BR28: 0 | BS28: 0 | BT28: 0
B29: Misc JV Equity Fees | C29: 0 | D29: 0 | E29: =+C29-D29 -> 0 | F29: 0 | G29: =+SUM(C29,F29) -> 0 | H29: =G29-D29 -> 0 | I29: =SUM(M29:BT29) -> 0 | J29: =SUM(D29,I29) -> 0 | K29: =G29-J29 -> 0 | M29: 0 | N29: 0 | O29: 0 | P29: 0 | Q29: 0 | R29: 0 | S29: 0 | T29: 0 | U29: 0 | V29: 0 | W29: 0 | X29: 0 | Y29: 0 | Z29: 0 | AA29: 0 | AB29: 0 | AC29: 0 | AD29: 0 | AE29: 0 | AF29: 0 | AG29: 0 | AH29: 0 | AI29: 0 | AJ29: 0 | AK29: 0 | AL29: 0 | AM29: 0 | AN29: 0 | AO29: 0 | AP29: 0 | AQ29: 0 | AR29: 0 | AS29: 0 | AT29: 0 | AU29: 0 | AV29: 0 | AW29: 0 | AX29: 0 | AY29: 0 | AZ29: 0 | BA29: 0 | BB29: 0 | BC29: 0 | BD29: 0 | BE29: 0 | BF29: 0 | BG29: 0 | BH29: 0 | BI29: 0 | BJ29: 0 | BK29: 0 | BL29: 0 | BM29: 0 | BN29: 0 | BO29: 0 | BP29: 0 | BQ29: 0 | BR29: 0 | BS29: 0 | BT29: 0
B30: Operating Deficit | C30: 0 | D30: 0 | E30: =+C30-D30 -> 0 | F30: 0 | G30: =+SUM(C30,F30) -> 0 | H30: =G30-D30 -> 0 | I30: =SUM(M30:BT30) -> 0 | J30: =SUM(D30,I30) -> 0 | K30: =G30-J30 -> 0 | M30: 0 | N30: 0 | O30: 0 | P30: 0 | Q30: 0 | R30: 0 | S30: 0 | T30: 0 | U30: 0 | V30: 0 | W30: 0 | X30: 0 | Y30: 0 | Z30: 0 | AA30: 0 | AB30: 0 | AC30: 0 | AD30: 0 | AE30: 0 | AF30: 0 | AG30: 0 | AH30: 0 | AI30: 0 | AJ30: 0 | AK30: 0 | AL30: 0 | AM30: 0 | AN30: 0 | AO30: 0 | AP30: 0 | AQ30: 0 | AR30: 0 | AS30: 0 | AT30: 0 | AU30: 0 | AV30: 0 | AW30: 0 | AX30: 0 | AY30: 0 | AZ30: 0 | BA30: 0 | BB30: 0 | BC30: 0 | BD30: 0 | BE30: 0 | BF30: 0 | BG30: 0 | BH30: 0 | BI30: 0 | BJ30: 0 | BK30: 0 | BL30: 0 | BM30: 0 | BN30: 0 | BO30: 0 | BP30: 0 | BQ30: 0 | BR30: 0 | BS30: 0 | BT30: 0
B31: RE Taxes During Construction | C31: 0 | D31: 0 | E31: =+C31-D31 -> 0 | F31: 0 | G31: =+SUM(C31,F31) -> 0 | H31: =G31-D31 -> 0 | I31: =SUM(M31:BT31) -> 0 | J31: =SUM(D31,I31) -> 0 | K31: =G31-J31 -> 0 | M31: 0 | N31: 0 | O31: 0 | P31: 0 | Q31: 0 | R31: 0 | S31: 0 | T31: 0 | U31: 0 | V31: 0 | W31: 0 | X31: 0 | Y31: 0 | Z31: 0 | AA31: 0 | AB31: 0 | AC31: 0 | AD31: 0 | AE31: 0 | AF31: 0 | AG31: 0 | AH31: 0 | AI31: 0 | AJ31: 0 | AK31: 0 | AL31: 0 | AM31: 0 | AN31: 0 | AO31: 0 | AP31: 0 | AQ31: 0 | AR31: 0 | AS31: 0 | AT31: 0 | AU31: 0 | AV31: 0 | AW31: 0 | AX31: 0 | AY31: 0 | AZ31: 0 | BA31: 0 | BB31: 0 | BC31: 0 | BD31: 0 | BE31: 0 | BF31: 0 | BG31: 0 | BH31: 0 | BI31: 0 | BJ31: 0 | BK31: 0 | BL31: 0 | BM31: 0 | BN31: 0 | BO31: 0 | BP31: 0 | BQ31: 0 | BR31: 0 | BS31: 0 | BT31: 0
... B74: Misc Contingency | C74: 0 | D74: 0 | E74: =+C74-D74 -> 0 | F74: 0 | G74: =+SUM(C74,F74) -> 0 | H74: =G74-D74 -> 0 | I74: =SUM(M74:BT74) -> 0 | J74: =SUM(D74,I74) -> 0 | K74: =G74-J74 -> 0 | M74: 0 | N74: 0 | O74: 0 | P74: 0 | Q74: 0 | R74: 0 | S74: 0 | T74: 0 | U74: 0 | V74: 0 | W74: 0 | X74: 0 | Y74: 0 | Z74: 0 | AA74: 0 | AB74: 0 | AC74: 0 | AD74: 0 | AE74: 0 | AF74: 0 | AG74: 0 | AH74: 0 | AI74: 0 | AJ74: 0 | AK74: 0 | AL74: 0 | AM74: 0 | AN74: 0 | AO74: 0 | AP74: 0 | AQ74: 0 | AR74: 0 | AS74: 0 | AT74: 0 | AU74: 0 | AV74: 0 | AW74: 0 | AX74: 0 | AY74: 0 | AZ74: 0 | BA74: 0 | BB74: 0 | BC74: 0 | BD74: 0 | BE74: 0 | BF74: 0 | BG74: 0 | BH74: 0 | BI74: 0 | BJ74: 0 | BK74: 0 | BL74: 0 | BM74: 0 | BN74: 0 | BO74: 0 | BP74: 0 | BQ74: 0 | BR74: 0 | BS74: 0 | BT74: 0
C75: 0 | D75: 0 | E75: =+C75-D75 -> 0 | F75: 0 | G75: =+SUM(C75,F75) -> 0 | H75: =G75-D75 -> 0 | I75: =SUM(M75:BT75) -> 0 | J75: =SUM(D75,I75) -> 0 | K75: =G75-J75 -> 0 | M75: 0 | N75: 0 | O75: 0 | P75: 0 | Q75: 0 | R75: 0 | S75: 0 | T75: 0 | U75: 0 | V75: 0 | W75: 0 | X75: 0 | Y75: 0 | Z75: 0 | AA75: 0 | AB75: 0 | AC75: 0 | AD75: 0 | AE75: 0 | AF75: 0 | AG75: 0 | AH75: 0 | AI75: 0 | AJ75: 0 | AK75: 0 | AL75: 0 | AM75: 0 | AN75: 0 | AO75: 0 | AP75: 0 | AQ75: 0 | AR75: 0 | AS75: 0 | AT75: 0 | AU75: 0 | AV75: 0 | AW75: 0 | AX75: 0 | AY75: 0 | AZ75: 0 | BA75: 0 | BB75: 0 | BC75: 0 | BD75: 0 | BE75: 0 | BF75: 0 | BG75: 0 | BH75: 0 | BI75: 0 | BJ75: 0 | BK75: 0 | BL75: 0 | BM75: 0 | BN75: 0 | BO75: 0 | BP75: 0 | BQ75: 0 | BR75: 0 | BS75: 0 | BT75: 0
C76: 0 | D76: 0 | E76: =+C76-D76 -> 0 | F76: 0 | G76: =+SUM(C76,F76) -> 0 | H76: =G76-D76 -> 0 | I76: =SUM(M76:BT76) -> 0 | J76: =SUM(D76,I76) -> 0 | K76: =G76-J76 -> 0 | M76: 0 | N76: 0 | O76: 0 | P76: 0 | Q76: 0 | R76: 0 | S76: 0 | T76: 0 | U76: 0 | V76: 0 | W76: 0 | X76: 0 | Y76: 0 | Z76: 0 | AA76: 0 | AB76: 0 | AC76: 0 | AD76: 0 | AE76: 0 | AF76: 0 | AG76: 0 | AH76: 0 | AI76: 0 | AJ76: 0 | AK76: 0 | AL76: 0 | AM76: 0 | AN76: 0 | AO76: 0 | AP76: 0 | AQ76: 0 | AR76: 0 | AS76: 0 | AT76: 0 | AU76: 0 | AV76: 0 | AW76: 0 | AX76: 0 | AY76: 0 | AZ76: 0 | BA76: 0 | BB76: 0 | BC76: 0 | BD76: 0 | BE76: 0 | BF76: 0 | BG76: 0 | BH76: 0 | BI76: 0 | BJ76: 0 | BK76: 0 | BL76: 0 | BM76: 0 | BN76: 0 | BO76: 0 | BP76: 0 | BQ76: 0 | BR76: 0 | BS76: 0 | BT76: 0
C77: 0 | D77: 0 | E77: =+C77-D77 -> 0 | F77: 0 | G77: =+SUM(C77,F77) -> 0 | H77: =G77-D77 -> 0 | I77: =SUM(M77:BT77) -> 0 | J77: =SUM(D77,I77) -> 0 | K77: =G77-J77 -> 0 | M77: 0 | N77: 0 | O77: 0 | P77: 0 | Q77: 0 | R77: 0 | S77: 0 | T77: 0 | U77: 0 | V77: 0 | W77: 0 | X77: 0 | Y77: 0 | Z77: 0 | AA77: 0 | AB77: 0 | AC77: 0 | AD77: 0 | AE77: 0 | AF77: 0 | AG77: 0 | AH77: 0 | AI77: 0 | AJ77: 0 | AK77: 0 | AL77: 0 | AM77: 0 | AN77: 0 | AO77: 0 | AP77: 0 | AQ77: 0 | AR77: 0 | AS77: 0 | AT77: 0 | AU77: 0 | AV77: 0 | AW77: 0 | AX77: 0 | AY77: 0 | AZ77: 0 | BA77: 0 | BB77: 0 | BC77: 0 | BD77: 0 | BE77: 0 | BF77: 0 | BG77: 0 | BH77: 0 | BI77: 0 | BJ77: 0 | BK77: 0 | BL77: 0 | BM77: 0 | BN77: 0 | BO77: 0 | BP77: 0 | BQ77: 0 | BR77: 0 | BS77: 0 | BT77: 0
C78: 0 | D78: 0 | E78: =+C78-D78 -> 0 | F78: 0 | G78: =+SUM(C78,F78) -> 0 | H78: =G78-D78 -> 0 | I78: =SUM(M78:BT78) -> 0 | J78: =SUM(D78,I78) -> 0 | K78: =G78-J78 -> 0 | M78: 0 | N78: 0 | O78: 0 | P78: 0 | Q78: 0 | R78: 0 | S78: 0 | T78: 0 | U78: 0 | V78: 0 | W78: 0 | X78: 0 | Y78: 0 | Z78: 0 | AA78: 0 | AB78: 0 | AC78: 0 | AD78: 0 | AE78: 0 | AF78: 0 | AG78: 0 | AH78: 0 | AI78: 0 | AJ78: 0 | AK78: 0 | AL78: 0 | AM78: 0 | AN78: 0 | AO78: 0 | AP78: 0 | AQ78: 0 | AR78: 0 | AS78: 0 | AT78: 0 | AU78: 0 | AV78: 0 | AW78: 0 | AX78: 0 | AY78: 0 | AZ78: 0 | BA78: 0 | BB78: 0 | BC78: 0 | BD78: 0 | BE78: 0 | BF78: 0 | BG78: 0 | BH78: 0 | BI78: 0 | BJ78: 0 | BK78: 0 | BL78: 0 | BM78: 0 | BN78: 0 | BO78: 0 | BP78: 0 | BQ78: 0 | BR78: 0 | BS78: 0 | BT78: 0
B79: Total Uses | C79: =SUM(C20:C78) -> 0 | D79: =SUM(D20:D78) -> 0 | E79: =SUM(E20:E78) -> 0 | F79: =SUM(F20:F78) -> 0 | G79: =SUM(G20:G78) -> 0 | H79: =SUM(H20:H78) -> 0 | I79: =SUM(I20:I78) -> 0 | J79: =SUM(J20:J78) -> 0 | K79: =SUM(K20:K78) -> 0 | M79: =SUM(M20:M78) -> 0 | N79: =SUM(N20:N78) -> 0 | O79: =SUM(O20:O78) -> 0 | P79: =SUM(P20:P78) -> 0 | Q79: =SUM(Q20:Q78) -> 0 | R79: =SUM(R20:R78) -> 0 | S79: =SUM(S20:S78) -> 0 | T79: =SUM(T20:T78) -> 0 | ... BT79: =SUM(BT20:BT78) -> 0
B81: Delta | C81: =+C17-C79 -> 0 | D81: =+D17-D79 -> 0 | E81: =+E17-E79 -> 0 | F81: =+F17-F79 -> 0 | G81: =+G17-G79 -> 0 | H81: =+H17-H79 -> 0 | I81: =+I17-I79 -> 0 | J81: =+J17-J79 -> 0 | K81: =+K17-K79 -> 0 | M81: =+M17-M79 -> 0 | N81: =+N17-N79 -> 0 | O81: =+O17-O79 -> 0 | P81: =+P17-P79 -> 0 | Q81: =+Q17-Q79 -> 0 | R81: =+R17-R79 -> 0 | S81: =+S17-S79 -> 0 | T81: =+T17-T79 -> 0 | ... BT81: =+BT17-BT79 -> 0

Sheet Dispo - Deal Waterfall
A1: =TEXT(Global!$C$7,"") -> 607 Cedar St
A2: Disposition - Deal Level Waterfall
B6: Date
B7: Days | C7: =IF(ISBLANK(C6),"",0) | D7: =IF(ISBLANK(D6),"",D6-C6) | E7: =IF(ISBLANK(E6),"",E6-D6) | F7: =IF(ISBLANK(F6),"",F6-E6) | G7: =IF(ISBLANK(G6),"",G6-F6) | H7: =IF(ISBLANK(H6),"",H6-G6) | I7: =IF(ISBLANK(I6),"",I6-H6) | J7: =IF(ISBLANK(J6),"",J6-I6) | K7: =IF(ISBLANK(K6),"",K6-J6) | ... BJ7: =IF(ISBLANK(BJ6),"",BJ6-BI6)
B8: Pro-Rata | C8: =IFERROR(C7/365,"") | D8: =IFERROR(D7/365,"") | E8: =IFERROR(E7/365,"") | F8: =IFERROR(F7/365,"") | G8: =IFERROR(G7/365,"") | H8: =IFERROR(H7/365,"") | I8: =IFERROR(I7/365,"") | J8: =IFERROR(J7/365,"") | ... BJ8: =IFERROR(BJ7/365,"")
B9: Status
B11: Waterfall | C11: Levered | D11: Pref Equity | E11: JV Equity | F11: LP | G11: GP | H11: Promote
B12: IRR | C12: =IFERROR(XIRR(C66:BJ66,C6:BJ6,0),0) -> 0 | D12: =IFERROR(XIRR(C112:BJ112,C6:BJ6,0),0) -> 0 | E12: =IFERROR(XIRR(C122:BJ122,C6:BJ6,0),0) -> 0 | F12: =IFERROR(XIRR(C256:BJ256,C6:BJ6,0),0) -> 0 | G12: =IFERROR(XIRR(C247:BJ247,C6:BJ6,0),0) -> 0 | H12: - | J12: Parity Check: | K12: =IF(ABS(SUM(C282:BJ282))<0.5,"Yes","No") -> #REF!
B13: Multiple | C13: =IFERROR(C15/C14,0) -> 0 | D13: =IFERROR(D15/D14,0) -> 0 | E13: =IFERROR(E15/E14,0) -> 0 | F13: =IFERROR(F15/F14,0) -> 0 | G13: =IFERROR(G15/G14,0) -> 0 | H13: -
B14: Equity Invested | C14: =-SUM(C58:BJ58) -> #REF! | D14: =-SUM(C108:BJ108) -> #REF! | E14: =-SUM(C118:BJ118) -> 0 | F14: =-SUM(C250:BJ250) -> 0 | G14: =-SUM(C241:BJ241) -> 0 | H14: -
B15: Gross Cash Flow | C15: =+SUM(C64:BJ64) -> 0 | D15: =SUM(C109:BJ111) -> #REF! | E15: =SUM(C120:BJ120) -> #REF! | F15: =SUM(C251:BJ255) -> #REF! | G15: =SUM(C242:BJ246) -> #REF! | H15: =SUM(C271:BJ271) -> #REF!
B16: Net Cash Flow | C16: =+C15-C14 -> #REF! | D16: =+D15-D14 -> #REF! | E16: =+E15-E14 -> #REF! | F16: =+F15-F14 -> #REF! | G16: =+G15-G14 -> #REF! | H16: -
B18: Preferred Equity Assumptions | C18: Hurdle
B19: Tier 1 - Return of Preference | C19: 0.14
B20: Tier 2 - Return of Pref Equity | C20: ROE
B21: Tier 3 - Minimum Multiple | C21: 1 | D21: No
B23: Waterfall Assumptions | C23: =+TEXT(#REF!,"") -> #REF! | D23: =+TEXT(#REF!,"") -> #REF! | E23: =+TEXT(#REF!,"") -> #REF! | F23: =+TEXT(#REF!,"") -> #REF! | G23: =+TEXT(#REF!,"") -> #REF!
B24: =TEXT(#REF!,"") -> #REF! | D24: =+#REF! -> #REF! | E24: =+#REF! -> #REF! | F24: =+#REF! -> #REF! | G24: =1-F24 -> #REF!
B25: =TEXT(#REF!,"") -> #REF! | D25: =+#REF! -> #REF! | E25: =+#REF! -> #REF! | F25: =+#REF! -> #REF! | G25: =1-F25 -> #REF!
B26: =TEXT(#REF!,"") -> #REF! | C26: On | D26: =+#REF! -> #REF! | E26: =+#REF! -> #REF! | F26: =+#REF! -> #REF! | G26: =1-F26 -> #REF!
B27: =TEXT(#REF!,"") -> #REF! | C27: On | D27: =+#REF! -> #REF! | E27: =+#REF! -> #REF! | F27: =+#REF! -> #REF! | G27: =1-F27 -> #REF!
B28: =TEXT(#REF!,"") -> #REF! | D28: =+#REF! -> #REF! | E28: =+#REF! -> #REF! | F28: =+#REF! -> #REF! | G28: =1-F28 -> #REF!
B30: JV Equity Capital Stack | C30: $ | D30: %
B31: GP | C31: 0 | D31: =IFERROR(C31/$C$33,0) -> 0
B32: LP | C32: 0 | D32: =IFERROR(C32/$C$33,0) -> 0
B33: Total | C33: =SUM(C31:C32) -> 0 | D33: =SUM(D31:D32) -> 0
B35: Sale
B36: Sale Date
B38: Closing Statement: | C38: $ | D38: Per Unit
B39: Sale Price | C39: =286*400000 -> 114400000 | D39: =IFERROR(C39/$C$51,0) -> 0
B40: Broker Fee | C40: =-E40*C39 -> -572000 | D40: =IFERROR(C40/$C$51,0) -> 0 | E40: 0.005
B41: Legal | C41: -100000 | D41: =IFERROR(C41/$C$51,0) -> 0
B42: Deed Stamps | C42: =-E42*C39 -> -228800 | D42: =IFERROR(C42/$C$51,0) -> 0 | E42: 0.002
B43: Partnership Expenses | C43: -50000 | D43: =IFERROR(C43/$C$51,0) -> 0
B44: Miscellaneous | C44: -25000 | D44: =IFERROR(C44/$C$51,0) -> 0
B45: Pro-Rated RETAX | C45: -25000 | D45: =IFERROR(C45/$C$51,0) -> 0
B46: Other Pro-Rations | C46: 0 | D46: =IFERROR(C46/$C$51,0) -> 0
B47: Holdback | C47: -250000 | D47: =IFERROR(C47/$C$51,0) -> 0
B48: Loan Payoff | C48: =-#REF! -> #REF! | D48: =IFERROR(C48/$C$51,0) -> 0
B49: Net Proceeds from Sale | C49: =SUM(C39:C48) -> #REF! | D49: =SUM(D39:D48) -> 0
...

Sheet Dispo - SRIF I Waterfall
A1: =TEXT(Global!$C$7,"") -> 607 Cedar St
A2: Disposition - SRIF I Waterfall
B6: Date
B7: Days | C7: =IF(ISBLANK(C6),"",0) | D7: =IF(ISBLANK(D6),"",D6-C6) | E7: =IF(ISBLANK(E6),"",E6-D6) | F7: =IF(ISBLANK(F6),"",F6-E6) | G7: =IF(ISBLANK(G6),"",G6-F6) | H7: =IF(ISBLANK(H6),"",H6-G6) | I7: =IF(ISBLANK(I6),"",I6-H6) | J7: =IF(ISBLANK(J6),"",J6-I6) | K7: =IF(ISBLANK(K6),"",K6-J6) | ... BJ7: =IF(ISBLANK(BJ6),"",BJ6-BI6)
B8: Pro-Rata | C8: =IFERROR(C7/365,"") | D8: =IFERROR(D7/365,"") | E8: =IFERROR(E7/365,"") | F8: =IFERROR(F7/365,"") | G8: =IFERROR(G7/365,"") | H8: =IFERROR(H7/365,"") | I8: =IFERROR(I7/365,"") | J8: =IFERROR(J7/365,"") | ... BJ8: =IFERROR(BJ7/365,"")
B9: Status
C11: SRIF I | D11: SRIF I Members | E11: SRIF I Manager | F11: SRIF I LP | G11: SRIF I GP | I11: GP Economics
B12: IRR | C12: =IFERROR(XIRR(C39:BJ39,C6:BJ6,0),0) -> 0 | D12: =IFERROR(XIRR(C81:BJ81,C6:BJ6,0),0) -> 0 | E12: - | F12: =IFERROR(XIRR(C107:BJ107,C6:BJ6,0),0) -> 0 | G12: =IFERROR(XIRR(C101:BJ101,C6:BJ6,0),0) -> 0 | I12: 80% Share of Deal Level Promote | K12: =-SUM(C36:BJ36) -> #REF! | M12: Parity Check: | N12: =IF(ABS(SUM(C118:BJ118))<0.5,"Yes","No") -> #REF!
B13: Multiple | C13: =IFERROR(C15/C14,0) -> 0 | D13: =IFERROR(D15/D14,0) -> 0 | E13: - | F13: =IFERROR(F15/F14,0) -> 0 | G13: =IFERROR(G15/G14,0) -> 0 | I13: SRIF I GP | K13: =+G15 -> #REF!
B14: Equity Invested | C14: =-SUM(C32:BJ32) -> 0 | D14: =-SUM(C77:BJ77) -> 0 | E14: - | F14: =-SUM(C104:BJ104) -> 0 | G14: =-SUM(C98:BJ98) -> 0 | I14: Total GP Economics | K14: =SUM(K12:K13) -> #REF!
B15: Gross Cash Flow | C15: =SUM(C37:BJ37) -> #REF! | D15: =SUM(C78:BJ80) -> #REF! | E15: =SUM(C85:BJ87) -> #REF! | F15: =SUM(C105:BJ106) -> #REF! | G15: =SUM(C99:BJ100) -> #REF!
B16: Net Cash Flow | C16: =+C15-C14 -> #REF! | D16: =+D15-D14 -> #REF! | E16: - | F16: =+F15-F14 -> #REF! | G16: =+G15-G14 -> #REF!
B18: SRIF I Cap Table | C18: $ | D18: % | E18: =+TEXT(#REF!,"") -> #REF! | F18: =+TEXT(#REF!,"") -> #REF! | G18: =+TEXT(#REF!,"") -> #REF!
B19: SRIF I GP | C19: =+#REF! -> #REF! | D19: =IFERROR(C19/C$21,0) -> 0 | E19: =+TEXT(#REF!,"") -> #REF! | F19: =+TEXT(#REF!,"") -> #REF! | G19: =+TEXT(#REF!,"") -> #REF!
B20: SRIF I LP | C20: =+#REF! -> #REF! | D20: =IFERROR(C20/C$21,0) -> 0 | E20: =+TEXT(#REF!,"") -> #REF! | F20: =+TEXT(#REF!,"") -> #REF! | G20: =+TEXT(#REF!,"") -> #REF!
B21: Total | C21: =SUM(C19:C20) -> #REF! | D21: =SUM(D19:D20) -> 0 | E21: =+TEXT(#REF!,"") -> #REF! | F21: =+TEXT(#REF!,"") -> #REF! | G21: =+TEXT(#REF!,"") -> #REF!
B23: SRIF I Waterfall Assumptions | C23: Hurdle | D23: Manager | E23: Member | F23: GP % | G23: LP %
B24: =TEXT(#REF!,"") -> #REF! | C24: =+#REF! -> #REF! | D24: 0 | E24: =1-D24 -> 1 | F24: =+D24+$D$19*E24 -> 0 | G24: =1-F24 -> 1
B25: =TEXT(#REF!,"") -> #REF! | C25: =+#REF! -> #REF! | D25: 0 | E25: =1-D25 -> 1 | F25: =+D25+$D$19*E25 -> 0 | G25: =1-F25 -> 1
B26: =TEXT(#REF!,"") -> #REF! | C26: =+#REF! -> #REF! | D26: =+#REF! -> #REF! | E26: =1-D26 -> #REF! | F26: =+D26+$D$19*E26 -> #REF! | G26: =1-F26 -> #REF!
B28: GP to SOF II Cash Flow
B29: Draws:
B30: Deal Level Draws (GP) | C30: 0 | D30: 0 | E30: 0 | F30: 0 | G30: 0 | H30: 0 | I30: 0 | J30: 0 | K30: 0 | L30: 0 | M30: 0 | N30: 0 | O30: 0 | P30: 0 | Q30: 0 | R30: 0 | S30: 0 | T30: 0 | U30: 0 | V30: 0 | W30: 0 | X30: 0 | Y30: 0 | Z30: 0 | AA30: 0 | AB30: 0 | AC30: 0 | AD30: 0 | AE30: 0 | AF30: 0 | AG30: 0 | AH30: 0 | AI30: 0 | AJ30: 0 | AK30: 0 | AL30: 0 | AM30: 0 | AN30: 0 | AO30: 0 | AP30: 0 | AQ30: 0 | AR30: 0 | AS30: 0 | AT30: 0 | AU30: 0 | AV30: 0 | AW30: 0 | AX30: 0 | AY30: 0 | AZ30: 0 | BA30: 0 | BB30: 0 | BC30: 0 | BD30: 0 | BE30: 0 | BF30: 0 | BG30: 0 | BH30: 0 | BI30: 0 | BJ30: 0
B31: Fund Expenses | C31: 0 | D31: 0 | E31: 0 | F31: 0 | G31: 0 | H31: 0 | I31: 0 | J31: 0 | K31: 0 | L31: 0 | M31: 0 | N31: 0 | O31: 0 | P31: 0 | Q31: 0 | R31: 0 | S31: 0 | T31: 0 | U31: 0 | V31: 0 | W31: 0 | X31: 0 | Y31: 0 | Z31: 0 | AA31: 0 | AB31: 0 | AC31: 0 | AD31: 0 | AE31: 0 | AF31: 0 | AG31: 0 | AH31: 0 | AI31: 0 | AJ31: 0 | AK31: 0 | AL31: 0 | AM31: 0 | AN31: 0 | AO31: 0 | AP31: 0 | AQ31: 0 | AR31: 0 | AS31: 0 | AT31: 0 | AU31: 0 | AV31: 0 | AW31: 0 | AX31: 0 | AY31: 0 | AZ31: 0 | BA31: 0 | BB31: 0 | BC31: 0 | BD31: 0 | BE31: 0 | BF31: 0 | BG31: 0 | BH31: 0 | BI31: 0 | BJ31: 0
B32: Total Draws | C32: =SUM(C30:C31) -> 0 | D32: =SUM(D30:D31) -> 0 | E32: =SUM(E30:E31) -> 0 | F32: =SUM(F30:F31) -> 0 | G32: =SUM(G30:G31) -> 0 | H32: =SUM(H30:H31) -> 0 | I32: =SUM(I30:I31) -> 0 | J32: =SUM(J30:J31) -> 0 | ... BJ32: =SUM(BJ30:BJ31) -> 0
B34: Distirbutions:
B35: GP Proceeds | C35: 0 | D35: 0 | E35: 0 | F35: 0 | G35: 0 | H35: 0 | I35: 0 | J35: 0 | K35: 0 | L35: 0 | M35: 0 | N35: 0 | O35: 0 | P35: 0 | Q35: 0 | R35: 0 | S35: 0 | T35: 0 | U35: 0 | V35: 0 | W35: 0 | X35: 0 | Y35: 0 | Z35: 0 | AA35: 0 | AB35: 0 | AC35: 0 | AD35: 0 | AE35: 0 | AF35: 0 | AG35: 0 | AH35: 0 | AI35: 0 | AJ35: 0 | AK35: 0 | AL35: 0 | AM35: 0 | AN35: 0 | AO35: 0 | AP35: 0 | AQ35: 0 | AR35: 0 | AS35: 0 | AT35: 0 | AU35: 0 | AV35: 0 | AW35: 0 | AX35: 0 | AY35: 0 | AZ35: 0 | BA35: 0 | BB35: 0 | BC35: 0 | BD35: 0 | BE35: 0 | BF35: 0 | BG35: 0 | BH35: 0 | BI35: 0 | BJ35: 0
B36: Deal Level Promote Sharing | C36: 0 | D36: =-#REF!*'Dispo - Deal Waterfall'!D271 -> #REF! | E36: =-#REF!*'Dispo - Deal Waterfall'!E271 -> #REF! | F36: 0 | G36: 0 | H36: 0 | I36: 0 | J36: 0 | K36: 0 | L36: 0 | M36: 0 | N36: 0 | O36: 0 | P36: 0 | Q36: 0 | R36: 0 | S36: 0 | T36: 0 | U36: 0 | V36: 0 | W36: 0 | X36: 0 | Y36: 0 | Z36: 0 | AA36: 0 | AB36: 0 | AC36: 0 | AD36: 0 | AE36: 0 | AF36: 0 | AG36: 0 | AH36: 0 | AI36: 0 | AJ36: 0 | AK36: 0 | AL36: 0 | AM36: 0 | AN36: 0 | AO36: 0 | AP36: 0 | AQ36: 0 | AR36: 0 | AS36: 0 | AT36: 0 | AU36: 0 | AV36: 0 | AW36: 0 | AX36: 0 | AY36: 0 | AZ36: 0 | BA36: 0 | BB36: 0 | BC36: 0 | BD36: 0 | BE36: 0 | BF36: 0 | BG36: 0 | BH36: 0 | BI36: 0 | BJ36: 0
B37: Total Distributions | C37: =SUM(C35:C36) -> 0 | D37: =SUM(D35:D36) -> #REF! | E37: =SUM(E35:E36) -> #REF! | F37: =SUM(F35:F36) -> 0 | G37: =SUM(G35:G36) -> 0 | H37: =SUM(H35:H36) -> 0 | I37: =SUM(I35:I36) -> 0 | J37: =SUM(J35:J36) -> 0 | ... BJ37: =SUM(BJ35:BJ36) -> 0
B39: SRIF I Cash Flow | C39: =SUM(C32,C37) -> 0 | D39: =SUM(D32,D37) -> #REF! | E39: =SUM(E32,E37) -> #REF! | F39: =SUM(F32,F37) -> 0 | G39: =SUM(G32,G37) -> 0 | H39: =SUM(H32,H37) -> 0 | I39: =SUM(I32,I37) -> 0 | J39: =SUM(J32,J37) -> 0 | ... BJ39: =SUM(BJ32,BJ37) -> 0
B41: SOF II Waterfall
B42: =TEXT($B$24,"") -> #REF!
B43: Cash Flow Available for Distribution | C43: =+C37 -> 0 | D43: =+D37 -> #REF! | E43: =+E37 -> #REF! | F43: =+F37 -> 0 | G43: =+G37 -> 0 | H43: =+H37 -> 0 | I43: =+I37 -> 0 | J43: =+J37 -> 0 | ... BJ43: =+BJ37 -> 0
B45: Preference Beginning | C45: 0 | D45: =+C48 -> 0 | E45: =+D48 -> #REF! | F45: =+E48 -> #REF! | G45: =+F48 -> #REF! | H45: =+G48 -> #REF! | I45: =+H48 -> #REF! | J45: =+I48 -> #REF! | K45: =+J48 -> #REF! | ... BJ45: =+BI48 -> #REF!
B46: Accrued Preference | C46: =IFERROR(((1+$C$24)^(C$8)-1)*C50,0) -> 0 | D46: =IFERROR(((1+$C$24)^(D$8)-1)*D50,0) -> 0 | E46: =IFERROR(((1+$C$24)^(E$8)-1)*E50,0) -> 0 | F46: =IFERROR(((1+$C$24)^(F$8)-1)*F50,0) -> 0 | G46: =IFERROR(((1+$C$24)^(G$8)-1)*G50,0) -> 0 | H46: =IFERROR(((1+$C$24)^(H$8)-1)*H50,0) -> 0 | I46: =IFERROR(((1+$C$24)^(I$8)-1)*I50,0) -> 0 | J46: =IFERROR(((1+$C$24)^(J$8)-1)*J50,0) -> 0 | ... BJ46: =IFERROR(((1+$C$24)^(BJ$8)-1)*BJ50,0) -> 0
B47: Preference Distributions | C47: =-MAX(0,MIN(SUM(C45:C46),C43)) -> 0 | D47: =-MAX(0,MIN(SUM(D45:D46),D43)) -> #REF! | E47: =-MAX(0,MIN(SUM(E45:E46),E43)) -> #REF! | F47: =-MAX(0,MIN(SUM(F45:F46),F43)) -> #REF! | G47: =-MAX(0,MIN(SUM(G45:G46),G43)) -> #REF! | H47: =-MAX(0,MIN(SUM(H45:H46),H43)) -> #REF! | I47: =-MAX(0,MIN(SUM(I45:I46),I43)) -> #REF! | J47: =-MAX(0,MIN(SUM(J45:J46),J43)) -> #REF! | ... BJ47: =-MAX(0,MIN(SUM(BJ45:BJ46),BJ43)) -> #REF!
B48: Preference Ending | C48: =SUM(C45:C47) -> 0 | D48: =SUM(D45:D47) -> #REF! | E48: =SUM(E45:E47) -> #REF! | F48: =SUM(F45:F47) -> #REF! | G48: =SUM(G45:G47) -> #REF! | H48: =SUM(H45:H47) -> #REF! | I48: =SUM(I45:I47) -> #REF! | J48: =SUM(J45:J47) -> #REF! | ... BJ48: =SUM(BJ45:BJ47) -> #REF!
B50: Tier 1 Beginning Balance | C50: 0 | D50: =+C55 -> 0 | E50: =+D55 -> #REF! | F50: =+E55 -> #REF! | G50: =+F55 -> #REF! | H50: =+G55 -> #REF! | I50: =+H55 -> #REF! | J50: =+I55 -> #REF! | K50: =+J55 -> #REF! | ... BJ50: =+BI55 -> #REF!
B51: Accrued Preference | C51: =+C46 -> 0 | D51: =+D46 -> 0 | E51: =+E46 -> 0 | F51: =+F46 -> 0 | G51: =+G46 -> 0 | H51: =+H46 -> 0 | I51: =+I46 -> 0 | J51: =+J46 -> 0 | ... BJ51: =+BJ46 -> 0
B52: Equity Draws | C52: =+C63 -> 0 | D52: =+D63 -> 0 | E52: =+E63 -> 0 | F52: =+F63 -> 0 | G52: =+G63 -> 0 | H52: =+H63 -> 0 | I52: =+I63 -> 0 | J52: =+J63 -> 0 | ... BJ52: =+BJ63 -> 0
...

Sheet SOFR - Reforecast
A1: =TEXT(Global!$C$7,"") -> 607 Cedar St
A2: SOFR Forward Curve - Reforecast
B6: Date | C6: Adj. Date | D6: SOFR
B7: 45443 | C7: =EOMONTH(B7,0) -> 45443 | D7: 0.0532981
B8: 45473 | C8: =EOMONTH(B8,0) -> 45473 | D8: 0.0532422
B9: 45504 | C9: =EOMONTH(B9,0) -> 45504 | D9: 0.0529618
B10: 45535 | C10: =EOMONTH(B10,0) -> 45535 | D10: 0.0523644
B11: 45565 | C11: =EOMONTH(B11,0) -> 45565 | D11: 0.0518069
B12: 45596 | C12: =EOMONTH(B12,0) -> 45596 | D12: 0.0511731
B13: 45626 | C13: =EOMONTH(B13,0) -> 45626 | D13: 0.0504557
B14: 45657 | C14: =EOMONTH(B14,0) -> 45657 | D14: 0.0497565
B15: 45688 | C15: =EOMONTH(B15,0) -> 45688 | D15: 0.0489395
B16: 45716 | C16: =EOMONTH(B16,0) -> 45716 | D16: 0.0483783
B17: 45747 | C17: =EOMONTH(B17,0) -> 45747 | D17: 0.0477116
B18: 45777 | C18: =EOMONTH(B18,0) -> 45777 | D18: 0.0469026
... B126: 49064 | C126: =EOMONTH(B126,0) -> 49064 | D126: 0.0394871
