Workbook
Name units: [1]Rents!$C$51
Name Units: Rent!$D$29

Sheet CFS-Main Page
B2: Calabash Shores | C2: Address: | D2: 660 Aubrey Ln Calabash, NC, 28467
B3: Cashflow Statement - Main Page | C3: Units | D3: =Units -> 132
C4: Year Built/Reno | D4: 2024 | F4: Scenario | G4: 2 | M4: Tax rate info. | P4: County Link: | Q4: Link
B5: Analysis Start Date | C5: 46174 | G5: =10925000 -> 10925000 | M5: Districts | N5: Jurisdictions | Q5: 2025 Rate
B6: Investment Assumptions/Summary | D6: Per Unit | F6: Pro forma Assumptions | I6: Key Metrics | N6: Calabash | Q6: 0.342
B7: Purchase Price | C7: =IF(OR(G4=0,G4=1),J8,K8)*1000000 -> 35000000 | D7: =C7/$D$3 -> 265151.52 | F7: Rent Increase (Y2 Onwards) | H7: 0.03 | I7: =B2 -> Calabash Shores | J7: 1 | K7: 2 | L7: Broker's Numbers | N7: Brunswick County | Q7: 0.07
B8: NOI After Reserve | C8: =I66 -> 1871250.5 | D8: =C8/$D$3 -> 14176.14 | F8: Other Income Increase (Y2) | H8: =H7 -> 0.03 | I8: Asking Price | J8: =IF(G4=2,"",L8) | K8: 35 | L8: 0
B9: All in Cost | C9: ='Sources & Usage'!C9 -> 35595000 | D9: =C9/$D$3 -> 269659.09 | F9: Expense Increase (Year 2 Onwards) | H9: 0.0275 | I9: Y1 NOI | J9: =IF(G4=2,"",I63) | K9: =IF(G4=1,"",I63) -> 1871250.5 | L9: =H63 -> 2254500
B10: PP Cap Rate | C10: =C8/C7 -> 0.053464299 | F10: Property Management Fee | H10: 0.0275 | I10: Cap rate | J10: =IF(G4=2,"",J9/(J8*1000000)) | K10: =IF(G4=1,"",K9/(K8*1000000)) -> 0.053464299 | L10: 0
B11: Total Rentable Square Feet | C11: =Rent!I29 -> 131840 | D11: =C11/$D$3 -> 998.78788 | F11: Asset Management Fee | H11: 0 | I11: Levered COC | J11: =IF(G4=2,"",G76) | K11: =IF(G4=1,"",G76) -> 0.044291737 | L11: -
B12: Cash on Cash Return | C12: =I76 -> 0.051357409 | F12: Cost of Exit (Brokerage) | H12: 0.01 | I12: Levered IRR | J12: =IF(G4=2,"",G78) | K12: =IF(G4=1,"",G78) -> 0.038638988 | L12: -
B13: Exit Year | C13: 5 | F13: Replacement Reserve (Per Unit) | H13: 0 | I13: Y1 Yield on Cost | J13: =IF(G4=2,"",$I$63/(J8*1000000)) | K13: =IF(G4=1,"",$I$63/'Sources & Usage'!$C$23) -> 0.052570599 | L13: -
B14: Exit Cap Rate | C14: 0.06 | F14: Assesment Ratio | G14: 1 | H14: =G14*C7 -> 35000000 | I14: Reappraisal happens every 4 years in Brunswick County with the next assessment in 2027.
B15: Exit NOI (After Reserve) | C15: =HLOOKUP($C$13+1,$I$46:$S$66,ROWS($I$46:$I$66)) -> 2093870.7 | D15: =C15/$D$3 -> 15862.657 | F15: Y1 Tax Reassessed | G15: =Q16 -> 0.00412 | H15: =(G15*H14)+16000 -> 160200
B16: Exit Price | C16: =HLOOKUP($C$13,$I$46:$S$67,ROWS($I$46:$I$67)) -> 34548867 | D16: =C16/$D$3 -> 261733.84 | F16: Tax growth (Y2 Onwards) | H16: 0.03 | I16: Direct tax in last tax bill was $16000 which is included for Y1 Tax calculations. | N16: Millage Rate | Q16: =SUM(Q6:Q15)/100 -> 0.00412
B18: Rental Assumptions | D18: =Rent!D5 -> 46066 | F18: T3 | G18: T12 | H18: Broker Numbers | I18: 1 | J18: =IF(I18<$C$13+1,I18+1,"") -> 2 | K18: =IF(J18<$C$13+1,J18+1,"") -> 3 | L18: =IF(K18<$C$13+1,K18+1,"") -> 4 | M18: =IF(L18<$C$13+1,L18+1,"") -> 5 | N18: =IF(M18<$C$13+1,M18+1,"") -> 6 | O18: =IF(N18<$C$13+1,N18+1,"") | P18: =IF(O18<$C$13+1,O18+1,"") | Q18: =IF(P18<$C$13+1,P18+1,"") | ... AC18: =IF(AB18<$C$13+1,AB18+1,"")
B19: Loss to Lease | D19: =Rent!H32/Rent!H30 -> -0.016852082 | F19: =-F34/F33 -> 0 | G19: =-G34/G33 -> 0 | H19: =-H34/H33 -> 0 | I19: =-I34/I33 -> -0.016852082 | J19: 0.01 | K19: 0.01 | L19: 0.01 | M19: 0.01 | N19: =M19 -> 0.01 | O19: =N19 -> 0.01 | P19: =O19 -> 0.01 | Q19: =P19 -> 0.01 | R19: =Q19 -> 0.01 | S19: =R19 -> 0.01 | T19: =S19 -> 0.01 | U19: =T19 -> 0.01 | ... AB19: =AA19 -> 0.01
B20: Vacancy | D20: =1-Rent!H29 -> 0.71969697 | F20: =-F36/$G$35 -> 0.56319934 | G20: =-G36/$G$35 -> 0.84663328 | H20: =-H36/$H$35 -> 0.05 | I20: 0.05 | J20: 0.05 | K20: 0.05 | L20: 0.05 | M20: =L20 -> 0.05 | N20: =M20 -> 0.05 | O20: =N20 -> 0.05 | P20: =O20 -> 0.05 | Q20: =P20 -> 0.05 | R20: =Q20 -> 0.05 | S20: =R20 -> 0.05 | T20: =S20 -> 0.05 | ... AB20: =AA20 -> 0.05
B21: Concession/Discount | F21: =-F37/$G$35 -> 0.063974054 | G21: =-G37/$G$35 -> 0.032579475 | H21: =-H37/$H$35 -> 0.03 | I21: 0.01 | J21: 0.01 | K21: 0.01 | L21: 0.01 | M21: =L21 -> 0.01 | N21: =M21 -> 0.01 | O21: =N21 -> 0.01 | P21: =O21 -> 0.01 | Q21: =P21 -> 0.01 | R21: =Q21 -> 0.01 | S21: =R21 -> 0.01 | T21: =S21 -> 0.01 | ... AB21: =AA21 -> 0.01
B22: Bad Debt | F22: =-F38/$G$35 -> 0 | G22: =-G38/$G$35 -> 0 | H22: =-H38/$H$35 -> 0 | I22: 0 | J22: 0 | K22: =J22 -> 0 | L22: =K22 -> 0 | M22: =L22 -> 0 | N22: =M22 -> 0 | O22: =N22 -> 0 | P22: =O22 -> 0 | Q22: =P22 -> 0 | R22: =Q22 -> 0 | ... AB22: =AA22 -> 0
B23: Non Revenue Units | F23: =-F39/$G$35 -> 0 | G23: =-G39/$G$35 -> 0.0029700022 | H23: =-H39/$H$35 -> 0 | I23: =G23 -> 0.0029700022 | J23: =I23 -> 0.0029700022 | K23: =J23 -> 0.0029700022 | L23: =K23 -> 0.0029700022 | M23: =L23 -> 0.0029700022 | N23: =M23 -> 0.0029700022 | O23: =N23 -> 0.0029700022 | P23: =O23 -> 0.0029700022 | Q23: =P23 -> 0.0029700022 | ... AB23: =AA23 -> 0.0029700022
D24: =Rent!H29 -> 0.28030303
B25: Average Rent (GRP) | F25: =F35/Units/12 -> 1970.4798 | G25: =G35/Units/12 -> 2440.2254 | H25: =H35/Units/12 -> 1959.8485 | I25: =I35/Units/12 -> 1996.6892 | J25: =IF(J$18="","",J35/Units/12) -> 2002.2814 | K25: =IF(K$18="","",K35/Units/12) -> 2062.3498 | L25: =IF(L$18="","",L35/Units/12) -> 2124.2203 | M25: =IF(M$18="","",M35/Units/12) -> 2187.9469 | N25: =IF(N$18="","",N35/Units/12) -> 2253.5853 | O25: =IF(O$18="","",O35/Units/12) | P25: =IF(P$18="","",P35/Units/12) | Q25: =IF(Q$18="","",Q35/Units/12) | ... AC25: =IF(AC$18="","",AC35/Units/12)
B26: GRP Increases | I26: =IF(I$18="","",I35/G35-1) -> -0.18176033 | J26: =IF(J$18="","",J35/I35-1) -> 0.0028007199 | K26: =IF(K$18="","",K35/J35-1) -> 0.03 | L26: =IF(L$18="","",L35/K35-1) -> 0.03 | M26: =IF(M$18="","",M35/L35-1) -> 0.03 | N26: =IF(N$18="","",N35/M35-1) -> 0.03 | O26: =IF(O$18="","",O35/N35-1) | P26: =IF(P$18="","",P35/O35-1) | Q26: =IF(Q$18="","",Q35/P35-1) | ... AC26: =IF(AC$18="","",AC35/AB35-1)
B27: Economic Occupancy | F27: =IF(F$18="","",F40/F35) -> 0.22331381 | G27: =IF(G$18="","",G40/G35) -> 0.11781725 | H27: =IF(H$18="","",H40/H35) -> 0.92 | I27: =IF(I$18="","",I40/I35) -> 0.93703 | J27: =IF(J$18="","",J40/J35) -> 0.93703 | K27: =IF(K$18="","",K40/K35) -> 0.93703 | L27: =IF(L$18="","",L40/L35) -> 0.93703 | M27: =IF(M$18="","",M40/M35) -> 0.93703 | ... AC27: =IF(AC$18="","",AC40/AC35)
B28: GEI Increases | I28: =IF(I$18="","",I40/G40-1) -> 5.5076646 | J28: =IF(J$18="","",J40/I40-1) -> 0.0028007199 | K28: =IF(K$18="","",K40/J40-1) -> 0.03 | L28: =IF(L$18="","",L40/K40-1) -> 0.03 | M28: =IF(M$18="","",M40/L40-1) -> 0.03 | N28: =IF(N$18="","",N40/M40-1) -> 0.03 | O28: =IF(O$18="","",O40/N40-1) | P28: =IF(P$18="","",P40/O40-1) | Q28: =IF(Q$18="","",Q40/P40-1) | ... AC28: =IF(AC$18="","",AC40/AB40-1)
B30: Income | D30: Per Unit (T12) | E30: Per Unit Y1 | F30: =F18 -> T3 | G30: T12 | H30: Broker's Numbers | I30: 1 | J30: =IF(I30<$C$13+1,I30+1,"") -> 2 | K30: =IF(J30<$C$13+1,J30+1,"") -> 3 | L30: =IF(K30<$C$13+1,K30+1,"") -> 4 | M30: =IF(L30<$C$13+1,L30+1,"") -> 5 | N30: =IF(M30<$C$13+1,M30+1,"") -> 6 | O30: =IF(N30<$C$13+1,N30+1,"") | P30: =IF(O30<$C$13+1,O30+1,"") | Q30: =IF(P30<$C$13+1,P30+1,"") | ... AC30: =IF(AB30<$C$13+1,AB30+1,"")
B31: Market Rent Potential | D31: =G31/Units -> 29282.705 | E31: =I31/Units -> 23563.182 | F31: ='Historical Analysis'!X9 -> 3121240 | G31: ='Historical Analysis'!W9 -> 3865317 | H31: 3104400 | I31: {=(SUMPRODUCT(Rent!$K$9:$K$28*(Rent!$L$9:$L$28=Rent!$K$8),Rent!$D$9:$D$28)+SUMPRODUCT(Rent!$J$9:$J$28*(Rent!$L$9:$L$28=Rent!$J$8),Rent!$D$9:$D$28))*12} -> 3110340 | J31: =IF(J$30>$C$13+1,"",I$31*(1+$H$7)) -> 3203650.2 | K31: =IF(K$30>$C$13+1,"",J$31*(1+$H$7)) -> 3299759.7 | L31: =IF(L$30>$C$13+1,"",K$31*(1+$H$7)) -> 3398752.5 | M31: =IF(M$30>$C$13+1,"",L$31*(1+$H$7)) -> 3500715.1 | N31: =IF(N$30>$C$13+1,"",M$31*(1+$H$7)) -> 3605736.5 | O31: =IF(O$30>$C$13+1,"",N$31*(1+$H$7)) | P31: =IF(P$30>$C$13+1,"",O$31*(1+$H$7)) | Q31: =IF(Q$30>$C$13+1,"",P$31*(1+$H$7)) | ... AC31: =IF(AC$30>$C$13+1,"",AB$31*(1+$H$7))
B32: Renovation Premium | D32: =G32/Units -> 0 | E32: =I32/Units -> 0 | F32: ='Historical Analysis'!X10 -> 0 | G32: ='Historical Analysis'!W10 -> 0 | H32: 0 | I32: =Rent!I57*12/3 -> 0 | J32: =IF(J30<=$C$13+1,(Rent!I57*12/3)+I32*(1+$H$7),"") -> 0 | K32: =IF(K30<=$C$13+1,(Rent!I57*12/3)+J32*(1+$H$7),"") -> 0 | L32: =IF(L30<=$C$13+1,K32*(1+$H$7),"") -> 0 | M32: =IF(M30<=$C$13+1,L32*(1+$H$7),"") -> 0 | N32: =IF(N30<=$C$13+1,M32*(1+$H$7),"") -> 0 | O32: =IF(O30<=$C$13+1,N32*(1+$H$7),"") | P32: =IF(P30<=$C$13+1,O32*(1+$H$7),"") | Q32: =IF(Q30<=$C$13+1,P32*(1+$H$7),"") | R32: =IF(R30<=$C$13+1,Q32*(1+$H$7),"") | S32: =IF(S30<=$C$13+1,R32*(1+$H$7),"") | ... AC32: =IF(AC30<=$C$13+1,AB32*(1+$H$7),"")
B33: Total Market Rent Potential | D33: =G33/Units -> 29282.705 | E33: =I33/Units -> 23563.182 | F33: =F31+F32 -> 3121240 | G33: =G31+G32 -> 3865317 | H33: =SUM(H31:H32) -> 3104400 | I33: =IF(I$30<=$C$13+1,I31+I32,"") -> 3110340 | J33: =IF(J$30<=$C$13+1,J31+J32,"") -> 3203650.2 | K33: =IF(K$30<=$C$13+1,K31+K32,"") -> 3299759.7 | L33: =IF(L$30<=$C$13+1,L31+L32,"") -> 3398752.5 | M33: =IF(M$30<=$C$13+1,M31+M32,"") -> 3500715.1 | N33: =IF(N$30<=$C$13+1,N31+N32,"") -> 3605736.5 | O33: =IF(O$30<=$C$13+1,O31+O32,"") | P33: =IF(P$30<=$C$13+1,P31+P32,"") | ... AC33: =IF(AC$30<=$C$13+1,AC31+AC32,"")
B34: Loss to Lease | D34: =G34/Units -> 0 | E34: =I34/Units -> 397.08868 | F34: ='Historical Analysis'!X12 -> 0 | G34: ='Historical Analysis'!W12 -> 0 | H34: 0 | I34: =IF(I$30<=$C$13+1,I35-I33,"") -> 52415.705 | J34: =IF(J$30<=$C$13+1,-J19*J33,"") -> -32036.502 | K34: =IF(K$30<=$C$13+1,-K19*K33,"") -> -32997.597 | L34: =IF(L$30<=$C$13+1,-L19*L33,"") -> -33987.525 | M34: =IF(M$30<=$C$13+1,-M19*M33,"") -> -35007.151 | N34: =IF(N$30<=$C$13+1,-N19*N33,"") -> -36057.365 | O34: =IF(O$30<=$C$13+1,-O19*O33,"") | P34: =IF(P$30<=$C$13+1,-P19*P33,"") | Q34: =IF(Q$30<=$C$13+1,-Q19*Q33,"") | ... AC34: =IF(AC$30<=$C$13+1,-AC19*AC33,"")
B35: Scheduled Rental Income | D35: =G35/Units -> 29282.705 | E35: =I35/Units -> 23960.27 | F35: =F33+F34 -> 3121240 | G35: =G33+G34 -> 3865317 | H35: =SUM(H33:H34) -> 3104400 | I35: =IF(I$30<=$C$13+1,Rent!N29*12,"") -> 3162755.7 | J35: =IF(J$30<=$C$13+1,J33+J34,"") -> 3171613.7 | K35: =IF(K$30<=$C$13+1,K33+K34,"") -> 3266762.1 | L35: =IF(L$30<=$C$13+1,L33+L34,"") -> 3364765 | M35: =IF(M$30<=$C$13+1,M33+M34,"") -> 3465707.9 | N35: =IF(N$30<=$C$13+1,N33+N34,"") -> 3569679.2 | O35: =IF(O$30<=$C$13+1,O33+O34,"") | P35: =IF(P$30<=$C$13+1,P33+P34,"") | Q35: =IF(Q$30<=$C$13+1,Q33+Q34,"") | ... AC35: =IF(AC$30<=$C$13+1,AC33+AC34,"")
B36: Vacancy | D36: =G36/Units -> -24791.712 | E36: =I36/Units -> -1198.0135 | F36: ='Historical Analysis'!X14 -> -2176944 | G36: ='Historical Analysis'!W14 -> -3272506 | H36: -155220 | I36: =IF(I$30<=$C$13+1,-I$35*I20,"") -> -158137.79 | J36: =IF(J$30<=$C$13+1,-J$35*J20,"") -> -158580.68 | K36: =IF(K$30<=$C$13+1,-K$35*K20,"") -> -163338.11 | L36: =IF(L$30<=$C$13+1,-L$35*L20,"") -> -168238.25 | M36: =IF(M$30<=$C$13+1,-M$35*M20,"") -> -173285.4 | N36: =IF(N$30<=$C$13+1,-N$35*N20,"") -> -178483.96 | O36: =IF(O$30<=$C$13+1,-O$35*O20,"") | P36: =IF(P$30<=$C$13+1,-P$35*P20,"") | ... AC36: =IF(AC$30<=$C$13+1,-AC$35*AC20,"")
B37: Concession/Discount | D37: =G37/Units -> -954.01515 | E37: =I37/Units -> -239.6027 | F37: ='Historical Analysis'!X15 -> -247280 | G37: ='Historical Analysis'!W15 -> -125930 | H37: -93132 | I37: =IF(I$30<=$C$13+1,-I$35*I21,"") -> -31627.557 | J37: =IF(J$30<=$C$13+1,-J$35*J21,"") -> -31716.137 | K37: =IF(K$30<=$C$13+1,-K$35*K21,"") -> -32667.621 | L37: =IF(L$30<=$C$13+1,-L$35*L21,"") -> -33647.65 | M37: =IF(M$30<=$C$13+1,-M$35*M21,"") -> -34657.079 | N37: =IF(N$30<=$C$13+1,-N$35*N21,"") -> -35696.792 | O37: =IF(O$30<=$C$13+1,-O$35*O21,"") | P37: =IF(P$30<=$C$13+1,-P$35*P21,"") | ... AC37: =IF(AC$30<=$C$13+1,-AC$35*AC21,"")
B38: Bad Debt | D38: =G38/Units -> 0 | E38: =I38/Units -> 0 | F38: ='Historical Analysis'!X16 -> 0 | G38: ='Historical Analysis'!W16 -> 0 | H38: 0 | I38: =IF(I$30<=$C$13+1,-I$35*I22,"") -> 0 | J38: =IF(J$30<=$C$13+1,-J$35*J22,"") -> 0 | K38: =IF(K$30<=$C$13+1,-K$35*K22,"") -> 0 | L38: =IF(L$30<=$C$13+1,-L$35*L22,"") -> 0 | M38: =IF(M$30<=$C$13+1,-M$35*M22,"") -> 0 | N38: =IF(N$30<=$C$13+1,-N$35*N22,"") -> 0 | O38: =IF(O$30<=$C$13+1,-O$35*O22,"") | P38: =IF(P$30<=$C$13+1,-P$35*P22,"") | ... AC38: =IF(AC$30<=$C$13+1,-AC$35*AC22,"")
B39: Non Revenue Units | D39: =G39/Units -> -86.969697 | E39: =I39/Units -> -71.162056 | F39: ='Historical Analysis'!X17 -> 0 | G39: ='Historical Analysis'!W17 -> -11480 | H39: 0 | I39: =IF(I$30<=$C$13+1,-I$35*I23,"") -> -9393.3914 | J39: =IF(J$30<=$C$13+1,-J$35*J23,"") -> -9419.6997 | K39: =IF(K$30<=$C$13+1,-K$35*K23,"") -> -9702.2907 | L39: =IF(L$30<=$C$13+1,-L$35*L23,"") -> -9993.3594 | M39: =IF(M$30<=$C$13+1,-M$35*M23,"") -> -10293.16 | N39: =IF(N$30<=$C$13+1,-N$35*N23,"") -> -10601.955 | O39: =IF(O$30<=$C$13+1,-O$35*O23,"") | P39: =IF(P$30<=$C$13+1,-P$35*P23,"") | ... Z39: =IF(Z$30<=$C$13+1,-Z$35*Z23,"") | AA39: =IF(AA$30<=$C$13+1,Z39*(1+$H$7),"") | AB39: =IF(AB$30<=$C$13+1,AA39*(1+$H$7),"") | AC39: =IF(AC$30<=$C$13+1,AB39*(1+$H$7),"")
B40: Gross Effective Income | D40: =G40/Units -> 3450.0076 | E40: =I40/Units -> 22451.492 | F40: =F35+SUM(F36:F39) -> 697016 | G40: =G35+SUM(G36:G39) -> 455401 | H40: =SUM(H35:H39) -> 2856048 | I40: =IF(I$30<=$C$13+1,SUM(I35:I39),"") -> 2963597 | J40: =IF(J$30<=$C$13+1,SUM(J35:J39),"") -> 2971897.2 | K40: =IF(K$30<=$C$13+1,SUM(K35:K39),"") -> 3061054.1 | L40: =IF(L$30<=$C$13+1,SUM(L35:L39),"") -> 3152885.7 | M40: =IF(M$30<=$C$13+1,SUM(M35:M39),"") -> 3247472.3 | N40: =IF(N$30<=$C$13+1,SUM(N35:N39),"") -> 3344896.5 | O40: =IF(O$30<=$C$13+1,SUM(O35:O39),"") | P40: =IF(P$30<=$C$13+1,SUM(P35:P39),"") | ... AC40: =IF(AC$30<=$C$13+1,SUM(AC35:AC39),"")
B41: Utility Reimbursements | D41: =G41/Units -> 4.4318182 | E41: 15 | F41: ='Historical Analysis'!X19 -> 2340 | G41: ='Historical Analysis'!W19 -> 585 | H41: =173052+72230 -> 245282 | I41: =IF(I$46="","",E41*Units) -> 1980 | J41: =IF(J$46="","",I41*(1+$H$9)) -> 2034.45 | K41: =IF(K$46="","",J41*(1+$H$9)) -> 2090.3974 | L41: =IF(L$46="","",K41*(1+$H$9)) -> 2147.8833 | M41: =IF(M$46="","",L41*(1+$H$9)) -> 2206.9501 | N41: =IF(N$46="","",M41*(1+$H$9)) -> 2267.6412 | O41: =IF(O$46="","",N41*(1+$H$9)) | P41: =IF(P$46="","",O41*(1+$H$9)) | Q41: =IF(Q$46="","",P41*(1+$H$9)) | ... AC41: =IF(AC$46="","",AB41*(1+$H$9))
B42: Other Reimbursements | D42: =G42/Units -> 0.93939394 | E42: 5 | F42: ='Historical Analysis'!X20 -> 496 | G42: ='Historical Analysis'!W20 -> 124 | H42: 60192 | I42: =IF(I$46="","",E42*Units) -> 660 | J42: =IF(J$30="","",(I42*(1+$H$9))) -> 678.15 | K42: =IF(K$46="","",J42*(1+$H$9)) -> 696.79913 | L42: =IF(L$46="","",K42*(1+$H$9)) -> 715.9611 | M42: =IF(M$46="","",L42*(1+$H$9)) -> 735.65003 | N42: =IF(N$46="","",M42*(1+$H$9)) -> 755.88041 | O42: =IF(O$46="","",N42*(1+$H$9)) | P42: =IF(P$46="","",O42*(1+$H$9)) | Q42: =IF(Q$46="","",P42*(1+$H$9)) | R42: =IF(R$46="","",Q42*(1+$H$9)) | ... AC42: =IF(AC$46="","",AB42*(1+$H$9))
B43: Other Income | D43: =G43/Units -> 215.21023 | E43: 500 | F43: ='Historical Analysis'!X21 -> 45501 | G43: ='Historical Analysis'!W21 -> 28407.75 | H43: =5000+37620+3400+19320 -> 65340 | I43: =IF(I$46="","",E43*Units) -> 66000 | J43: =IF(J$46="","",I43*(1+$H$8)) -> 67980 | K43: =IF(K$46="","",J43*(1+$H$8)) -> 70019.4 | L43: =IF(L$46="","",K43*(1+$H$8)) -> 72119.982 | M43: =IF(M$46="","",L43*(1+$H$8)) -> 74283.581 | N43: =IF(N$46="","",M43*(1+$H$8)) -> 76512.089 | O43: =IF(O$46="","",N43*(1+$H$8)) | P43: =IF(P$46="","",O43*(1+$H$8)) | Q43: =IF(Q$46="","",P43*(1+$H$8)) | ... AC43: =IF(AC$46="","",AB43*(1+$H$8))
...

Sheet Rent
B2: ='CFS-Main Page'!B2 -> Calabash Shores | D2: ='CFS-Main Page'!C2 -> Address: | E2: ='CFS-Main Page'!D2 -> 660 Aubrey Ln Calabash, NC, 28467
B3: Rent Roll Analysis | D3: ='CFS-Main Page'!C3 -> Units | E3: ='CFS-Main Page'!D3 -> 132
B4: ='CFS-Main Page'!B4 -> 0 | D4: ='CFS-Main Page'!C4 -> Year Built/Reno | E4: ='CFS-Main Page'!D4 -> 2024
C5: Rent Roll as on | D5: 46066 | E5: Avg Rent | F5: 1x1 | G5: {=-SUMPRODUCT(-($B$9:$B$28=F5),$E$9:$E$28,$J$9:$J$28)/SUMIF($B$9:$B$28,"="&F5,$E$9:$E$28)} -> 1568.64 | H5: 2x2 | I5: {=-SUMPRODUCT(-($B$9:$B$28=H5),$E$9:$E$28,$J$9:$J$28)/SUMIF($B$9:$B$28,"="&H5,$E$9:$E$28)} -> 2441.5258
C6: Rent Schedule
B8: Beds X Baths | C8: Type | D8: Units | E8: Occupied | F8: Vacant/Model | G8: Unit Mix % | H8: Occupancy % | I8: Square Feet | J8: MR - Based on RR | K8: MR - Based on Comps | L8: RR/Comps | M8: Effective Rent | N8: GRP | O8: GRP/unit
B9: 1x1 | C9: Surfside - 1 | D9: =IF(C9="","",COUNTIF($D$62:$D$997,"="&C9)) -> 40 | E9: =IF(C9="","",COUNTIF($I$62:$I$997,"="&C9)) -> 4 | F9: =IFERROR(D9-E9,0) -> 36 | G9: =IFERROR(D9/$D$29,0) -> 0.3030303 | H9: =IFERROR(E9/D9,0) -> 0.1 | I9: =IFERROR(SUMIF($D$62:$D$997,"="&C9,$E$62:$E$997)/D9,0) -> 745 | J9: =IFERROR(SUMIF($D$62:$D$997,"="&C9,$G$62:$G$997)/D9,0) -> 1575.8 | K9: 1700 | L9: MR - Based on RR | M9: =IFERROR(SUMIF($D$62:$D$997,"="&C9,$H$62:$H$997)/E9,0) -> 1941.75 | N9: =IFERROR((M9*E9)+(F9*J9),0) -> 64495.8 | O9: =IFERROR(N9/D9,0) -> 1612.395
B10: 1x1 | C10: Surfside - 1ADA | D10: =IF(C10="","",COUNTIF($D$62:$D$997,"="&C10)) -> 3 | E10: =IF(C10="","",COUNTIF($I$62:$I$997,"="&C10)) -> 1 | F10: =IFERROR(D10-E10,0) -> 2 | G10: =IFERROR(D10/$D$29,0) -> 0.022727273 | H10: =IFERROR(E10/D10,0) -> 0.33333333 | I10: =IFERROR(SUMIF($D$62:$D$997,"="&C10,$E$62:$E$997)/D10,0) -> 745 | J10: =IFERROR(SUMIF($D$62:$D$997,"="&C10,$G$62:$G$997)/D10,0) -> 1540 | K10: 1700 | L10: MR - Based on RR | M10: =IFERROR(SUMIF($D$62:$D$997,"="&C10,$H$62:$H$997)/E10,0) -> 1540 | N10: =IFERROR((M10*E10)+(F10*J10),0) -> 4620 | O10: =IFERROR(N10/D10,0) -> 1540
B11: 2x1 | C11: Shoreline - 4 | D11: =IF(C11="","",COUNTIF($D$62:$D$997,"="&C11)) -> 4 | E11: =IF(C11="","",COUNTIF($I$62:$I$997,"="&C11)) -> 0 | F11: =IFERROR(D11-E11,0) -> 4 | G11: =IFERROR(D11/$D$29,0) -> 0.03030303 | H11: =IFERROR(E11/D11,0) -> 0 | I11: =IFERROR(SUMIF($D$62:$D$997,"="&C11,$E$62:$E$997)/D11,0) -> 936 | J11: =IFERROR(SUMIF($D$62:$D$997,"="&C11,$G$62:$G$997)/D11,0) -> 1650 | K11: 1935 | L11: MR - Based on RR | M11: =IFERROR(SUMIF($D$62:$D$997,"="&C11,$H$62:$H$997)/E11,0) -> 0 | N11: =IFERROR((M11*E11)+(F11*J11),0) -> 6600 | O11: =IFERROR(N11/D11,0) -> 1650
B12: 2x2 | C12: Driftwood - 2 | D12: =IF(C12="","",COUNTIF($D$62:$D$997,"="&C12)) -> 10 | E12: =IF(C12="","",COUNTIF($I$62:$I$997,"="&C12)) -> 7 | F12: =IFERROR(D12-E12,0) -> 3 | G12: =IFERROR(D12/$D$29,0) -> 0.075757576 | H12: =IFERROR(E12/D12,0) -> 0.7 | I12: =IFERROR(SUMIF($D$62:$D$997,"="&C12,$E$62:$E$997)/D12,0) -> 995 | J12: =IFERROR(SUMIF($D$62:$D$997,"="&C12,$G$62:$G$997)/D12,0) -> 1900 | K12: 1935 | L12: MR - Based on RR | M12: =IFERROR(SUMIF($D$62:$D$997,"="&C12,$H$62:$H$997)/E12,0) -> 1996.4286 | N12: =IFERROR((M12*E12)+(F12*J12),0) -> 19675 | O12: =IFERROR(N12/D12,0) -> 1967.5
B13: 2x2 | C13: Driftwood - 2ADA | D13: =IF(C13="","",COUNTIF($D$62:$D$997,"="&C13)) -> 1 | E13: =IF(C13="","",COUNTIF($I$62:$I$997,"="&C13)) -> 0 | F13: =IFERROR(D13-E13,0) -> 1 | G13: =IFERROR(D13/$D$29,0) -> 0.0075757576 | H13: =IFERROR(E13/D13,0) -> 0 | I13: =IFERROR(SUMIF($D$62:$D$997,"="&C13,$E$62:$E$997)/D13,0) -> 995 | J13: =IFERROR(SUMIF($D$62:$D$997,"="&C13,$G$62:$G$997)/D13,0) -> 1675 | K13: 1935 | L13: MR - Based on RR | M13: =IFERROR(SUMIF($D$62:$D$997,"="&C13,$H$62:$H$997)/E13,0) -> 0 | N13: =IFERROR((M13*E13)+(F13*J13),0) -> 1675 | O13: =IFERROR(N13/D13,0) -> 1675
B14: 2x2 | C14: Seaglass - 3 | D14: =IF(C14="","",COUNTIF($D$62:$D$997,"="&C14)) -> 12 | E14: =IF(C14="","",COUNTIF($I$62:$I$997,"="&C14)) -> 2 | F14: =IFERROR(D14-E14,0) -> 10 | G14: =IFERROR(D14/$D$29,0) -> 0.090909091 | H14: =IFERROR(E14/D14,0) -> 0.16666667 | I14: =IFERROR(SUMIF($D$62:$D$997,"="&C14,$E$62:$E$997)/D14,0) -> 1000 | J14: =IFERROR(SUMIF($D$62:$D$997,"="&C14,$G$62:$G$997)/D14,0) -> 1905.8333 | K14: 1935 | L14: MR - Based on RR | M14: =IFERROR(SUMIF($D$62:$D$997,"="&C14,$H$62:$H$997)/E14,0) -> 1860 | N14: =IFERROR((M14*E14)+(F14*J14),0) -> 22778.333 | O14: =IFERROR(N14/D14,0) -> 1898.1944
B15: 2x2 | C15: Beach Haven In-line Unit | D15: =IF(C15="","",COUNTIF($D$62:$D$997,"="&C15)) -> 38 | E15: =IF(C15="","",COUNTIF($I$62:$I$997,"="&C15)) -> 4 | F15: =IFERROR(D15-E15,0) -> 34 | G15: =IFERROR(D15/$D$29,0) -> 0.28787879 | H15: =IFERROR(E15/D15,0) -> 0.10526316 | I15: =IFERROR(SUMIF($D$62:$D$997,"="&C15,$E$62:$E$997)/D15,0) -> 1149 | J15: =IFERROR(SUMIF($D$62:$D$997,"="&C15,$G$62:$G$997)/D15,0) -> 1956.7895 | K15: 1935 | L15: MR - Based on RR | M15: =IFERROR(SUMIF($D$62:$D$997,"="&C15,$H$62:$H$997)/E15,0) -> 2312 | N15: =IFERROR((M15*E15)+(F15*J15),0) -> 75778.842 | O15: =IFERROR(N15/D15,0) -> 1994.1801
B16: 2x2 | C16: Ocean Breeze - End Unit | D16: =IF(C16="","",COUNTIF($D$62:$D$997,"="&C16)) -> 22 | E16: =IF(C16="","",COUNTIF($I$62:$I$997,"="&C16)) -> 18 | F16: =IFERROR(D16-E16,0) -> 4 | G16: =IFERROR(D16/$D$29,0) -> 0.16666667 | H16: =IFERROR(E16/D16,0) -> 0.81818182 | I16: =IFERROR(SUMIF($D$62:$D$997,"="&C16,$E$62:$E$997)/D16,0) -> 1210 | J16: =IFERROR(SUMIF($D$62:$D$997,"="&C16,$G$62:$G$997)/D16,0) -> 2810 | K16: 1935 | L16: MR - Based on RR | M16: =IFERROR(SUMIF($D$62:$D$997,"="&C16,$H$62:$H$997)/E16,0) -> 2845.5556 | N16: =IFERROR((M16*E16)+(F16*J16),0) -> 62460 | O16: =IFERROR(N16/D16,0) -> 2839.0909
B17: 2x2 | C17: Lighthouse - 5 | D17: =IF(C17="","",COUNTIF($D$62:$D$997,"="&C17)) -> 2 | E17: =IF(C17="","",COUNTIF($I$62:$I$997,"="&C17)) -> 1 | F17: =IFERROR(D17-E17,0) -> 1 | G17: =IFERROR(D17/$D$29,0) -> 0.015151515 | H17: =IFERROR(E17/D17,0) -> 0.5 | I17: =IFERROR(SUMIF($D$62:$D$997,"="&C17,$E$62:$E$997)/D17,0) -> 1417 | J17: =IFERROR(SUMIF($D$62:$D$997,"="&C17,$G$62:$G$997)/D17,0) -> 2610 | K17: 1935 | L17: MR - Based on RR | M17: =IFERROR(SUMIF($D$62:$D$997,"="&C17,$H$62:$H$997)/E17,0) -> 2870 | N17: =IFERROR((M17*E17)+(F17*J17),0) -> 5480 | O17: =IFERROR(N17/D17,0) -> 2740
D18: =IF(C18="","",COUNTIF($D$62:$D$997,"="&C18)) | E18: =IF(C18="","",COUNTIF($I$62:$I$997,"="&C18)) | F18: =IFERROR(D18-E18,0) -> 0 | G18: =IFERROR(D18/$D$29,0) -> 0 | H18: =IFERROR(E18/D18,0) -> 0 | I18: =IFERROR(SUMIF($D$62:$D$997,"="&C18,$E$62:$E$997)/D18,0) -> 0 | J18: =IFERROR(SUMIF($D$62:$D$997,"="&C18,$G$62:$G$997)/D18,0) -> 0 | K18: 0 | M18: =IFERROR(SUMIF($D$62:$D$997,"="&C18,$H$62:$H$997)/E18,0) -> 0 | N18: =IFERROR((M18*E18)+(F18*J18),0) -> 0 | O18: =IFERROR(N18/D18,0) -> 0
D19: =IF(C19="","",COUNTIF($D$62:$D$997,"="&C19)) | E19: =IF(C19="","",COUNTIF($I$62:$I$997,"="&C19)) | F19: =IFERROR(D19-E19,0) -> 0 | G19: =IFERROR(D19/$D$29,0) -> 0 | H19: =IFERROR(E19/D19,0) -> 0 | I19: =IFERROR(SUMIF($D$62:$D$997,"="&C19,$E$62:$E$997)/D19,0) -> 0 | J19: =IFERROR(SUMIF($D$62:$D$997,"="&C19,$G$62:$G$997)/D19,0) -> 0 | K19: 0 | M19: =IFERROR(SUMIF($D$62:$D$997,"="&C19,$H$62:$H$997)/E19,0) -> 0 | N19: =IFERROR((M19*E19)+(F19*J19),0) -> 0 | O19: =IFERROR(N19/D19,0) -> 0
D20: =IF(C20="","",COUNTIF($D$62:$D$997,"="&C20)) | E20: =IF(C20="","",COUNTIF($I$62:$I$997,"="&C20)) | F20: =IFERROR(D20-E20,0) -> 0 | G20: =IFERROR(D20/$D$29,0) -> 0 | H20: =IFERROR(E20/D20,0) -> 0 | I20: =IFERROR(SUMIF($D$62:$D$997,"="&C20,$E$62:$E$997)/D20,0) -> 0 | J20: =IFERROR(SUMIF($D$62:$D$997,"="&C20,$G$62:$G$997)/D20,0) -> 0 | K20: 0 | M20: =IFERROR(SUMIF($D$62:$D$997,"="&C20,$H$62:$H$997)/E20,0) -> 0 | N20: =IFERROR((M20*E20)+(F20*J20),0) -> 0 | O20: =IFERROR(N20/D20,0) -> 0
D21: =IF(C21="","",COUNTIF($D$62:$D$997,"="&C21)) | E21: =IF(C21="","",COUNTIF($I$62:$I$997,"="&C21)) | F21: =IFERROR(D21-E21,0) -> 0 | G21: =IFERROR(D21/$D$29,0) -> 0 | H21: =IFERROR(E21/D21,0) -> 0 | I21: =IFERROR(SUMIF($D$62:$D$997,"="&C21,$E$62:$E$997)/D21,0) -> 0 | J21: =IFERROR(SUMIF($D$62:$D$997,"="&C21,$G$62:$G$997)/D21,0) -> 0 | K21: 0 | M21: =IFERROR(SUMIF($D$62:$D$997,"="&C21,$H$62:$H$997)/E21,0) -> 0 | N21: =IFERROR((M21*E21)+(F21*J21),0) -> 0 | O21: =IFERROR(N21/D21,0) -> 0
D22: =IF(C22="","",COUNTIF($D$62:$D$997,"="&C22)) | E22: =IF(C22="","",COUNTIF($I$62:$I$997,"="&C22)) | F22: =IFERROR(D22-E22,0) -> 0 | G22: =IFERROR(D22/$D$29,0) -> 0 | H22: =IFERROR(E22/D22,0) -> 0 | I22: =IFERROR(SUMIF($D$62:$D$997,"="&C22,$E$62:$E$997)/D22,0) -> 0 | J22: =IFERROR(SUMIF($D$62:$D$997,"="&C22,$G$62:$G$997)/D22,0) -> 0 | K22: 0 | M22: =IFERROR(SUMIF($D$62:$D$997,"="&C22,$H$62:$H$997)/E22,0) -> 0 | N22: =IFERROR((M22*E22)+(F22*J22),0) -> 0 | O22: =IFERROR(N22/D22,0) -> 0
D23: =IF(C23="","",COUNTIF($D$62:$D$997,"="&C23)) | E23: =IF(C23="","",COUNTIF($I$62:$I$997,"="&C23)) | F23: =IFERROR(D23-E23,0) -> 0 | G23: =IFERROR(D23/$D$29,0) -> 0 | H23: =IFERROR(E23/D23,0) -> 0 | I23: =IFERROR(SUMIF($D$62:$D$997,"="&C23,$E$62:$E$997)/D23,0) -> 0 | J23: =IFERROR(SUMIF($D$62:$D$997,"="&C23,$G$62:$G$997)/D23,0) -> 0 | K23: 0 | M23: =IFERROR(SUMIF($D$62:$D$997,"="&C23,$H$62:$H$997)/E23,0) -> 0 | N23: =IFERROR((M23*E23)+(F23*J23),0) -> 0 | O23: =IFERROR(N23/D23,0) -> 0
D24: =IF(C24="","",COUNTIF($D$62:$D$997,"="&C24)) | E24: =IF(C24="","",COUNTIF($I$62:$I$997,"="&C24)) | F24: =IFERROR(D24-E24,0) -> 0 | G24: =IFERROR(D24/$D$29,0) -> 0 | H24: =IFERROR(E24/D24,0) -> 0 | I24: =IFERROR(SUMIF($D$62:$D$997,"="&C24,$E$62:$E$997)/D24,0) -> 0 | J24: =IFERROR(SUMIF($D$62:$D$997,"="&C24,$G$62:$G$997)/D24,0) -> 0 | K24: 0 | M24: =IFERROR(SUMIF($D$62:$D$997,"="&C24,$H$62:$H$997)/E24,0) -> 0 | N24: =IFERROR((M24*E24)+(F24*J24),0) -> 0 | O24: =IFERROR(N24/D24,0) -> 0
D25: =IF(C25="","",COUNTIF($D$62:$D$997,"="&C25)) | E25: =IF(C25="","",COUNTIF($I$62:$I$997,"="&C25)) | F25: =IFERROR(D25-E25,0) -> 0 | G25: =IFERROR(D25/$D$29,0) -> 0 | H25: =IFERROR(E25/D25,0) -> 0 | I25: =IFERROR(SUMIF($D$62:$D$997,"="&C25,$E$62:$E$997)/D25,0) -> 0 | J25: =IFERROR(SUMIF($D$62:$D$997,"="&C25,$G$62:$G$997)/D25,0) -> 0 | K25: 0 | M25: =IFERROR(SUMIF($D$62:$D$997,"="&C25,$H$62:$H$997)/E25,0) -> 0 | N25: =IFERROR((M25*E25)+(F25*J25),0) -> 0 | O25: =IFERROR(N25/D25,0) -> 0 | Q25: 2350
D26: =IF(C26="","",COUNTIF($D$62:$D$997,"="&C26)) | E26: =IF(C26="","",COUNTIF($I$62:$I$997,"="&C26)) | F26: =IFERROR(D26-E26,0) -> 0 | G26: =IFERROR(D26/$D$29,0) -> 0 | H26: =IFERROR(E26/D26,0) -> 0 | I26: =IFERROR(SUMIF($D$62:$D$997,"="&C26,$E$62:$E$997)/D26,0) -> 0 | J26: =IFERROR(SUMIF($D$62:$D$997,"="&C26,$G$62:$G$997)/D26,0) -> 0 | K26: 0 | M26: =IFERROR(SUMIF($D$62:$D$997,"="&C26,$H$62:$H$997)/E26,0) -> 0 | N26: =IFERROR((M26*E26)+(F26*J26),0) -> 0 | O26: =IFERROR(N26/D26,0) -> 0 | Q26: 2350
D27: =IF(C27="","",COUNTIF($D$62:$D$997,"="&C27)) | E27: =IF(C27="","",COUNTIF($I$62:$I$997,"="&C27)) | F27: =IFERROR(D27-E27,0) -> 0 | G27: =IFERROR(D27/$D$29,0) -> 0 | H27: =IFERROR(E27/D27,0) -> 0 | I27: =IFERROR(SUMIF($D$62:$D$997,"="&C27,$E$62:$E$997)/D27,0) -> 0 | J27: =IFERROR(SUMIF($D$62:$D$997,"="&C27,$G$62:$G$997)/D27,0) -> 0 | K27: 0 | M27: =IFERROR(SUMIF($D$62:$D$997,"="&C27,$H$62:$H$997)/E27,0) -> 0 | N27: =IFERROR((M27*E27)+(F27*J27),0) -> 0 | O27: =IFERROR(N27/D27,0) -> 0 | Q27: 2025
D28: =IF(C28="","",COUNTIF($D$62:$D$997,"="&C28)) | E28: =IF(C28="","",COUNTIF($I$62:$I$997,"="&C28)) | F28: =IFERROR(D28-E28,0) -> 0 | G28: =IFERROR(D28/$D$29,0) -> 0 | H28: =IFERROR(E28/D28,0) -> 0 | I28: =IFERROR(SUMIF($D$62:$D$997,"="&C28,$E$62:$E$997)/D28,0) -> 0 | J28: =IFERROR(SUMIF($D$62:$D$997,"="&C28,$G$62:$G$997)/D28,0) -> 0 | K28: 0 | M28: =IFERROR(SUMIF($D$62:$D$997,"="&C28,$H$62:$H$997)/E28,0) -> 0 | N28: =IFERROR((M28*E28)+(F28*J28),0) -> 0 | O28: =IFERROR(N28/D28,0) -> 0 | Q28: 1525
C29: Total | D29: =SUM(D9:D28) -> 132 | E29: =SUM(E9:E28) -> 37 | F29: =SUM(F9:F28) -> 95 | G29: =SUM(G9:G28) -> 1 | H29: =E29/Units -> 0.28030303 | I29: =SUMPRODUCT($D$9:$D$28,I9:I28) -> 131840 | J29: =SUMPRODUCT($D$9:$D$28,J9:J28) -> 259195 | K29: =SUMPRODUCT($D$9:$D$28,K9:K28) -> 245315 | M29: =SUMPRODUCT(E9:E28,M9:M28) -> 90340 | N29: =SUM(N9:N28) -> 263562.98 | Q29: 1525
G30: MRP | H30: =J29*12 -> 3110340 | I30: Rent per Unit | J30: =SUMPRODUCT(D9:D28,J9:J28)/D29 -> 1963.5985 | K30: =SUMPRODUCT(D9:D28,K9:K28)/D29 -> 1858.447 | M30: =SUMPRODUCT(E9:E28,M9:M28)/E29 -> 2441.6216 | Q30: 2350
G31: GRP | H31: =N29*12 -> 3162755.7 | I31: Rent per Sq ft | J31: =J30/J32 -> 1.9659815 | K31: =K30/K32 -> 1.8607024 | M31: =M30/(SUMPRODUCT(E9:E28,I9:I28)/E29) -> 2.231554 | Q31: 1525
G32: Loss/(Gain) to lease | H32: =H30-H31 -> -52415.705 | I32: Average sq ft | J32: =SUMPRODUCT(D9:D28,I9:I28)/D29 -> 998.78788 | K32: =SUMPRODUCT(D9:D28,I9:I28)/D29 -> 998.78788 | M32: =SUMPRODUCT(E9:E28,I9:I28)/E29 -> 1094.1351 | Q32: 2350
Q33: 2350
Q34: 1540
C35: Renovation Rent Premium and Cost Schdule | Q35: 1702
C36: Type | D36: Units | G36: Cost Per Unit | H36: Total Cost | I36: Premium Per Unit | Q36: 2350
C37: =IF(C9="","",C9) -> Surfside - 1 | D37: =D9 -> 40 | G37: 0 | H37: =IFERROR(G37*D37,0) -> 0 | I37: 0 | Q37: 2870
C38: =IF(C10="","",C10) -> Surfside - 1ADA | D38: =D10 -> 3 | G38: 0 | H38: =IFERROR(G38*D38,0) -> 0 | I38: 0 | Q38: 1365
C39: =IF(C11="","",C11) -> Shoreline - 4 | D39: =D11 -> 4 | G39: 0 | H39: =IFERROR(G39*D39,0) -> 0 | I39: 0 | Q39: 1695
C40: =IF(C12="","",C12) -> Driftwood - 2 | D40: =D12 -> 10 | G40: 0 | H40: =IFERROR(G40*D40,0) -> 0 | I40: 0 | Q40: 2870
C41: =IF(C13="","",C13) -> Driftwood - 2ADA | D41: =D13 -> 1 | G41: 0 | H41: =IFERROR(G41*D41,0) -> 0 | I41: 0 | Q41: 2870
C42: =IF(C14="","",C14) -> Seaglass - 3 | D42: =D14 -> 12 | G42: 0 | H42: =IFERROR(G42*D42,0) -> 0 | I42: 0 | Q42: 2870
...

Sheet Sources & Usage
B2: =Loan!B2 -> Calabash Shores | C2: ='CFS-Main Page'!C2 -> Address: | D2: ='CFS-Main Page'!D2 -> 660 Aubrey Ln Calabash, NC, 28467
B3: Sources & Usage | C3: ='CFS-Main Page'!C3 -> Units | D3: ='CFS-Main Page'!D3 -> 132
B4: =Loan!B4 -> 0 | C4: ='CFS-Main Page'!C4 -> Year Built/Reno | D4: ='CFS-Main Page'!D4 -> 2024
B6: Source of Funding (Pre Refinance) | C6: Amount | D6: Per Unit
B7: Debt | C7: =IF(Loan!C9=0,Loan!C30,Loan!$C$9) -> 24500000 | D7: =C7/Units -> 185606.06 | E7: =C7/$C$9 -> 0.68829892
B8: Equity | C8: =C23-C7 -> 11095000 | D8: =C8/Units -> 84053.03 | E8: =C8/$C$9 -> 0.31170108
B9: Total | C9: =SUM(C7:C8) -> 35595000 | D9: =SUM(D7:D8) -> 269659.09 | E9: =SUM(E7:E8) -> 1
B11: Usage of Funding | C11: Amount | D11: Per Unit
B12: Purchase Price | C12: ='CFS-Main Page'!C7 -> 35000000 | D12: =C12/Units -> 265151.52 | E12: =C12/$C$23 -> 0.98328417
B13: Loan Processing Fees | C13: =C7*F13 -> 245000 | D13: =C13/Units -> 1856.0606 | E13: =C13/$C$23 -> 0.0068829892 | F13: 0.01
B14: Acquisition Fees | C14: =F14*C12 -> 350000 | D14: =C14/Units -> 2651.5152 | E14: =C14/$C$23 -> 0.0098328417 | F14: 0.01
B15: Renovation Cost | C15: =Rent!H57 -> 0 | D15: =C15/Units -> 0 | E15: =C15/$C$23 -> 0
B16: Additional Capex | C16: 0 | D16: =C16/Units -> 0 | E16: =C16/$C$23 -> 0
B17: Equity Fees | C17: 0 | D17: =C17/Units -> 0 | E17: =C17/$C$23 -> 0
B18: Legal | C18: 0 | D18: =C18/Units -> 0 | E18: =C18/$C$23 -> 0
B19: Other Closing Cost | C19: 0 | D19: =C19/Units -> 0 | E19: =C19/$C$23 -> 0
B20: Other Closing Cost | C20: 0 | D20: =C20/Units -> 0 | E20: =C20/$C$23 -> 0
B21: Other Closing Cost | C21: 0 | D21: =C21/Units -> 0 | E21: =C21/$C$23 -> 0
B22: Other Closing Cost | C22: =C12*F22 -> 0 | D22: =C22/Units -> 0 | E22: =C22/$C$23 -> 0 | F22: 0
B23: Total | C23: =SUM(C12:C22) -> 35595000 | D23: =SUM(D12:D22) -> 269659.09 | E23: 1

Sheet Loan
B2: =Rent!B2 -> Calabash Shores | C2: ='CFS-Main Page'!C2 -> Address: | D2: ='CFS-Main Page'!D2 -> 660 Aubrey Ln Calabash, NC, 28467
B3: Loan Schedule | C3: ='CFS-Main Page'!C3 -> Units | D3: ='CFS-Main Page'!D3 -> 132
B4: =Rent!B4 -> 0 | C4: ='CFS-Main Page'!C4 -> Year Built/Reno | D4: ='CFS-Main Page'!D4 -> 2024
B6: Loan Assumptions - Acquisition Loan
B7: Project Cost | C7: ='Sources & Usage'!C23 -> 35595000
B8: LTV | C8: 0.7 | D8: =C9/C7 -> 0.68829892
B9: Loan Amount | C9: =IF(C12>0,ROUND('CFS-Main Page'!C7*C8,-4),0) -> 24500000
B10: Processing Fees | C10: =C9*D10 -> 245000 | D10: ='Sources & Usage'!F13 -> 0.01
B11: Amortization Period (Years) | C11: 30
B12: Loan Termination for Refinance | C12: ='CFS-Main Page'!C13 -> 5 | D12: ← Input 0 if not using
B13: Interest Rate | C13: =3.912%+1.4% -> 0.05312
B14: I/O Period | C14: 3
B15: Debt Service Constant | C15: =-PMT(C13/12,C11*12,1)*12 -> 0.06672601
B16: Annual Payment Constant | C16: =C15*C9 -> 1634787.3
B17: Loan Schedule (First) | D17: 0 | E17: 1 | F17: 2 | G17: 3 | H17: 4 | I17: 5 | J17: 6 | K17: 7 | L17: 8 | M17: 9 | N17: 10
B18: Loan Amount BB | E18: =D23 -> 24500000 | F18: =E23 -> 24500000 | G18: =F23 -> 24500000 | H18: =G23 -> 24500000 | I18: =H23 -> 24166653 | J18: =I23 -> 0 | K18: =J23 -> 0 | L18: =K23 -> 0 | ... N18: =M23 -> 0
B19: Interest Payment | E19: =IF(E17>$C$12,0,E18*$C$13) -> 1301440 | F19: =IF(F17>$C$12,0,F18*$C$13) -> 1301440 | G19: =IF(G17>$C$12,0,G18*$C$13) -> 1301440 | H19: =IF(H17>$C$12,0,H18*$C$13) -> 1301440 | I19: =IF(I17>$C$12,0,I18*$C$13) -> 1283732.6 | J19: =IF(J17>$C$12,0,J18*$C$13) -> 0 | K19: =IF(K17>$C$12,0,K18*$C$13) -> 0 | L19: =IF(L17>$C$12,0,L18*$C$13) -> 0 | ... N19: =IF(N17>$C$12,0,N18*$C$13) -> 0
B20: Principal Payment | E20: =IF(OR(E17<=$C$14,E17>$C$12),0,$C$16-E19) -> 0 | F20: =IF(OR(F17<=$C$14,F17>$C$12),0,$C$16-F19) -> 0 | G20: =IF(OR(G17<=$C$14,G17>$C$12),0,$C$16-G19) -> 0 | H20: =IF(OR(H17<=$C$14,H17>$C$12),0,$C$16-H19) -> 333347.25 | I20: =IF(OR(I17<=$C$14,I17>$C$12),0,$C$16-I19) -> 351054.66 | J20: =IF(OR(J17<=$C$14,J17>$C$12),0,$C$16-J19) -> 0 | K20: =IF(OR(K17<=$C$14,K17>$C$12),0,$C$16-K19) -> 0 | L20: =IF(OR(L17<=$C$14,L17>$C$12),0,$C$16-L19) -> 0 | ... N20: =IF(OR(N17<=$C$14,N17>$C$12),0,$C$16-N19) -> 0
B21: Loan Payoff | E21: =IF(E17=$C$12,E18-E20,0) -> 0 | F21: =IF(F17=$C$12,F18-F20,0) -> 0 | G21: =IF(G17=$C$12,G18-G20,0) -> 0 | H21: =IF(H17=$C$12,H18-H20,0) -> 0 | I21: =IF(I17=$C$12,I18-I20,0) -> 23815598 | J21: =IF(J17=$C$12,J18-J20,0) -> 0 | K21: =IF(K17=$C$12,K18-K20,0) -> 0 | L21: =IF(L17=$C$12,L18-L20,0) -> 0 | ... N21: =IF(N17=$C$12,N18-N20,0) -> 0
B22: Total Debt Payment | E22: =SUM(E19:E20) -> 1301440 | F22: =SUM(F19:F20) -> 1301440 | G22: =SUM(G19:G20) -> 1301440 | H22: =SUM(H19:H20) -> 1634787.3 | I22: =SUM(I19:I20) -> 1634787.3 | J22: =SUM(J19:J20) -> 0 | K22: =SUM(K19:K20) -> 0 | L22: =SUM(L19:L20) -> 0 | ... N22: =SUM(N19:N20) -> 0
B23: Loan Balance End of Year | D23: =C9 -> 24500000 | E23: =E18-E20-E21 -> 24500000 | F23: =F18-F20-F21 -> 24500000 | G23: =G18-G20-G21 -> 24500000 | H23: =H18-H20-H21 -> 24166653 | I23: =I18-I20-I21 -> 0 | J23: =J18-J20-J21 -> 0 | K23: =K18-K20-K21 -> 0 | L23: =L18-L20-L21 -> 0 | ... N23: =N18-N20-N21 -> 0
B25: Loan Assumptions - Refinance | G25: Refinancing assumptions
B26: Total cost | C26: ='Sources & Usage'!C23 -> 35595000 | G26: Year of Refinance | H26: =C12 -> 5
G27: =CONCATENATE("Year ", H26," NOI") -> Year 5 NOI | H27: {=IF(H26<1,0,INDEX('CFS-Main Page'!I63:S63,Loan!$H$26))} -> 2030409.2
B28: LTV | C28: 0.8 | G28: DCR Sizing | H28: 1.25
B29: LTC | C29: =C30/C26 -> 0
B30: Loan Amount | C30: 0 | D30: ← Input 0 if not using Refinance and Loan amount can be Hardcoded. =ROUND(IF(H26=0,C28*C26,H33),-4) | G30: Constant | H30: =-PMT(C33/12,C31*12,1)*12 -> 0.075848163
B31: Amortization Period (Years) | C31: 30 | G31: Debt Service | H31: =IF(H26=0,C30*H30,H27/H28) -> 1624327.4
B32: Loan Term (Years)_Holding | C32: =IF(H26>0,MIN('CFS-Main Page'!C13+$H$26,N35),'CFS-Main Page'!C13) -> 10 | G32: Max Proceed | H32: =ROUND(H31/H30,-4) -> 21420000
B33: Interest Rate | C33: 0.065 | G33: Bridge Loan payoff | H33: =SUM(E21:N21) -> 23815598
B34: I/O Period | C34: 10
B35: Loan Schedule (Refinance) | D35: 0 | E35: 1 | F35: 2 | G35: 3 | H35: 4 | I35: 5 | J35: 6 | K35: 7 | L35: 8 | M35: 9 | N35: 10
B36: Loan Amount BB | E36: =IF($H$26>0,IF(E$35=$H$26+1,$C$30,IF(E$35>=$H$26,D$41,0)),IF(E$35=1,$C$30,D$41)) -> 0 | F36: =IF($H$26>0,IF(F$35=$H$26+1,$C$30,IF(F$35>=$H$26,E$41,0)),IF(F$35=1,$C$30,E$41)) -> 0 | G36: =IF($H$26>0,IF(G$35=$H$26+1,$C$30,IF(G$35>=$H$26,F$41,0)),IF(G$35=1,$C$30,F$41)) -> 0 | H36: =IF($H$26>0,IF(H$35=$H$26+1,$C$30,IF(H$35>=$H$26,G$41,0)),IF(H$35=1,$C$30,G$41)) -> 0 | I36: =IF($H$26>0,IF(I$35=$H$26+1,$C$30,IF(I$35>=$H$26,H$41,0)),IF(I$35=1,$C$30,H$41)) -> 0 | J36: =IF($H$26>0,IF(J$35=$H$26+1,$C$30,IF(J$35>=$H$26,I$41,0)),IF(J$35=1,$C$30,I$41)) -> 0 | K36: =IF($H$26>0,IF(K$35=$H$26+1,$C$30,IF(K$35>=$H$26,J$41,0)),IF(K$35=1,$C$30,J$41)) -> 0 | L36: =IF($H$26>0,IF(L$35=$H$26+1,$C$30,IF(L$35>=$H$26,K$41,0)),IF(L$35=1,$C$30,K$41)) -> 0 | ... N36: =IF($H$26>0,IF(N$35=$H$26+1,$C$30,IF(N$35>=$H$26,M$41,0)),IF(N$35=1,$C$30,M$41)) -> 0
B37: Interest Payment | E37: =IF(E35>$C$32,0,E36*$C$33) -> 0 | F37: =IF(F35>$C$32,0,F36*$C$33) -> 0 | G37: =IF(G35>$C$32,0,G36*$C$33) -> 0 | H37: =IF(H35>$C$32,0,H36*$C$33) -> 0 | I37: =IF(I35>$C$32,0,I36*$C$33) -> 0 | J37: =IF(J35>$C$32,0,J36*$C$33) -> 0 | K37: =IF(K35>$C$32,0,K36*$C$33) -> 0 | L37: =IF(L35>$C$32,0,L36*$C$33) -> 0 | ... N37: =IF(N35>$C$32,0,N36*$C$33) -> 0
B38: Principal | E38: =IF(E36>0,IF(OR(E35<=$C$34,E35>$C$32),0,$H$31-E37),0) -> 0 | F38: =IF(F36>0,IF(OR(F35<=$C$34,F35>$C$32),0,$H$31-F37),0) -> 0 | G38: =IF(G36>0,IF(OR(G35<=$C$34,G35>$C$32),0,$H$31-G37),0) -> 0 | H38: =IF(H36>0,IF(OR(H35<=$C$34,H35>$C$32),0,$H$31-H37),0) -> 0 | I38: =IF(I36>0,IF(OR(I35<=$C$34,I35>$C$32),0,$H$31-I37),0) -> 0 | J38: =IF(J36>0,IF(OR(J35<=$C$34,J35>$C$32),0,$H$31-J37),0) -> 0 | K38: =IF(K36>0,IF(OR(K35<=$C$34,K35>$C$32),0,$H$31-K37),0) -> 0 | L38: =IF(L36>0,IF(OR(L35<=$C$34,L35>$C$32),0,$H$31-L37),0) -> 0 | ... N38: =IF(N36>0,IF(OR(N35<=$C$34,N35>$C$32),0,$H$31-N37),0) -> 0
B39: Loan Payoff | E39: =IF(E35=$C$32,E36-E38,0) -> 0 | F39: =IF(F35=$C$32,F36-F38,0) -> 0 | G39: =IF(G35=$C$32,G36-G38,0) -> 0 | H39: =IF(H35=$C$32,H36-H38,0) -> 0 | I39: =IF(I35=$C$32,I36-I38,0) -> 0 | J39: =IF(J35=$C$32,J36-J38,0) -> 0 | K39: =IF(K35=$C$32,K36-K38,0) -> 0 | L39: =IF(L35=$C$32,L36-L38,0) -> 0 | ... N39: =IF(N35=$C$32,N36-N38,0) -> 0
B40: Total Debt Payment | E40: =E37+E38 -> 0 | F40: =F37+F38 -> 0 | G40: =G37+G38 -> 0 | H40: =H37+H38 -> 0 | I40: =I37+I38 -> 0 | J40: =J37+J38 -> 0 | K40: =K37+K38 -> 0 | L40: =L37+L38 -> 0 | ... N40: =N37+N38 -> 0
B41: Loan Balance End of Year | D41: =IF(H26>0,0,C30) -> 0 | E41: =E$36-E$38-E$39 -> 0 | F41: =F$36-F$38-F$39 -> 0 | G41: =G$36-G$38-G$39 -> 0 | H41: =H$36-H$38-H$39 -> 0 | I41: =I$36-I$38-I$39 -> 0 | J41: =J$36-J$38-J$39 -> 0 | K41: =K$36-K$38-K$39 -> 0 | L41: =L$36-L$38-L$39 -> 0 | ... N41: =N$36-N$38-N$39 -> 0
B43: Total Principal Payment | E43: =E20+E38 -> 0 | F43: =F20+F38 -> 0 | G43: =G20+G38 -> 0 | H43: =H20+H38 -> 333347.25 | I43: =I20+I38 -> 351054.66 | J43: =J20+J38 -> 0 | K43: =K20+K38 -> 0 | L43: =L20+L38 -> 0 | ... N43: =N20+N38 -> 0
B44: Total Loan Payoff | E44: =E21+E39-(IF(E21>0,F36,0)) -> 0 | F44: =F21+F39-(IF(F21>0,G36,0)) -> 0 | G44: =G21+G39-(IF(G21>0,H36,0)) -> 0 | H44: =H21+H39-(IF(H21>0,I36,0)) -> 0 | I44: =I21+I39-(IF(I21>0,J36,0)) -> 23815598 | J44: =J21+J39-(IF(J21>0,K36,0)) -> 0 | K44: =K21+K39-(IF(K21>0,L36,0)) -> 0 | L44: =L21+L39-(IF(L21>0,M36,0)) -> 0 | ... N44: =N21+N39-(IF(N21>0,O36,0)) -> 0
...

Sheet Historical Analysis
B2: ='Sources & Usage'!B2 -> Calabash Shores
B3: Historical Analysis
B4: ='Sources & Usage'!B4 -> 0
D5: =1 -> 1 | E5: =D5+1 -> 2 | F5: =E5+1 -> 3 | G5: =F5+1 -> 4 | H5: =G5+1 -> 5 | I5: =H5+1 -> 6 | J5: =I5+1 -> 7 | K5: =J5+1 -> 8 | L5: =K5+1 -> 9 | ... O5: =N5+1 -> 12
C6: ="T12 ending "&TEXT(O6,"mmm-yy") -> T12 ending Dec-25 | D6: 45658 | E6: =EOMONTH(D6,1) -> 45716 | F6: =EOMONTH(E6,1) -> 45747 | G6: =EOMONTH(F6,1) -> 45777 | H6: =EOMONTH(G6,1) -> 45808 | I6: =EOMONTH(H6,1) -> 45838 | J6: =EOMONTH(I6,1) -> 45869 | K6: =EOMONTH(J6,1) -> 45900 | L6: =EOMONTH(K6,1) -> 45930 | ... O6: =EOMONTH(N6,1) -> 46022 | Q6: T12 | R6: T3 | T6: Category | V6: Summary
Q8: =SUM(D8:O8) -> 0 | R8: =SUM(M8:O8)*4 -> 0 | T8: 1 - Market Rent Potential | V8: Operating Incomes | W8: T12 | X8: T3
C9: Net Rental Income | Q9: =SUM(D9:O9) -> 0 | R9: =SUM(M9:O9)*4 -> 0 | T9: 2 - Increase in Rent from Renovation | U9: 1 | V9: Market Rent Potential | W9: =SUMIF($B$1:$B$495,U9,$Q$1:$Q$495) -> 3865317 | X9: =SUMIF($B$1:$B$495,U9,$R$1:$R$495) -> 3121240
B10: 1 | C10: Gross Possible Rent | D10: 342198 | E10: 347296 | F10: 346450 | G10: 344142 | H10: 337405 | I10: 341284 | J10: 342324 | K10: 341704 | L10: 342204 | M10: 260655 | N10: 260225 | O10: 259430 | Q10: =SUM(D10:O10) -> 3865317 | R10: =SUM(M10:O10)*4 -> 3121240 | T10: 3 - Loss to Lease | U10: 2 | V10: Increase in Market Rent Potential from Renovation | W10: =SUMIF($B$1:$B$495,U10,$Q$1:$Q$495) -> 0 | X10: =SUMIF($B$1:$B$495,U10,$R$1:$R$495) -> 0
C11: Gross Potential Rent | D11: 342198 | E11: 347296 | F11: 346450 | G11: 344142 | H11: 337405 | I11: 341284 | J11: 342324 | K11: 341704 | L11: 342204 | M11: 260655 | N11: 260225 | O11: 259430 | Q11: =SUM(D11:O11) -> 3865317 | R11: =SUM(M11:O11)*4 -> 3121240 | T11: 4 - Vacancy | V11: Total Market Rent Potential | W11: =SUM(W9:W10) -> 3865317 | X11: =SUM(X9:X10) -> 3121240
C12: Deductions | Q12: =SUM(D12:O12) -> 0 | R12: =SUM(M12:O12)*4 -> 0 | T12: 5 - Concession/Discount | U12: 3 | V12: Loss to Lease | W12: =SUMIF($B$1:$B$495,U12,$Q$1:$Q$495) -> 0 | X12: =SUMIF($B$1:$B$495,U12,$R$1:$R$495) -> 0 | Y12: =W12/W11 -> 0
B13: 4 | C13: Vacancy Loss | D13: -336374 | E13: -319718 | F13: -318688 | G13: -311160 | H13: -295563 | I13: -288482 | J13: -292912 | K13: -284302 | L13: -281071 | M13: -187981 | N13: -180049 | O13: -176206 | Q13: =SUM(D13:O13) -> -3272506 | R13: =SUM(M13:O13)*4 -> -2176944 | T13: 6 - Bad Debt | V13: Gross Rent Potential | W13: =W11+W12 -> 3865317 | X13: =X11+X12 -> 3121240
B14: 7 | C14: Vacancy Loss - Model Units | D14: -2870 | E14: -2870 | F14: -2870 | G14: -2870 | H14: 0 | I14: 0 | J14: 0 | K14: 0 | L14: 0 | M14: 0 | N14: 0 | O14: 0 | Q14: =SUM(D14:O14) -> -11480 | R14: =SUM(M14:O14)*4 -> 0 | T14: 7 - Non Revenue Units | U14: 4 | V14: Vacancy | W14: =SUMIF($B$1:$B$495,U14,$Q$1:$Q$495) -> -3272506 | X14: =SUMIF($B$1:$B$495,U14,$R$1:$R$495) -> -2176944
B15: 5 | C15: Rent Concessions | D15: 0 | E15: 0 | F15: 0 | G15: 0 | H15: -10440 | I15: -17220 | J15: -13310 | K15: -16530 | L15: -6090 | M15: -17570 | N15: -20440 | O15: -23310 | Q15: =SUM(D15:O15) -> -124910 | R15: =SUM(M15:O15)*4 -> -245280 | T15: 8 - Utility Reimbursements | U15: 5 | V15: Concession/Discount | W15: =SUMIF($B$1:$B$495,U15,$Q$1:$Q$495) -> -125930 | X15: =SUMIF($B$1:$B$495,U15,$R$1:$R$495) -> -247280
B16: 5 | C16: Referral Discount | D16: 0 | E16: 0 | F16: 0 | G16: 0 | H16: 0 | I16: 0 | J16: 0 | K16: 0 | L16: 0 | M16: 0 | N16: 0 | O16: -500 | Q16: =SUM(D16:O16) -> -500 | R16: =SUM(M16:O16)*4 -> -2000 | T16: 9 - Other Reimbursements | U16: 6 | V16: Bad Debt | W16: =SUMIF($B$1:$B$495,U16,$Q$1:$Q$495) -> 0 | X16: =SUMIF($B$1:$B$495,U16,$R$1:$R$495) -> 0
B17: 5 | C17: Miscellaneous Credit | D17: 0 | E17: 0 | F17: 0 | G17: 0 | H17: 0 | I17: 0 | J17: -520 | K17: 0 | L17: 0 | M17: 0 | N17: 0 | O17: 0 | Q17: =SUM(D17:O17) -> -520 | R17: =SUM(M17:O17)*4 -> 0 | T17: 10 - Other Income | U17: 7 | V17: Non Revenue Units | W17: =SUMIF($B$1:$B$495,U17,$Q$1:$Q$495) -> -11480 | X17: =SUMIF($B$1:$B$495,U17,$R$1:$R$495) -> 0
C18: Total Deductions | D18: -339244 | E18: -322588 | F18: -321558 | G18: -314030 | H18: -306003 | I18: -305702 | J18: -306742 | K18: -300832 | L18: -287161 | M18: -205551 | N18: -200489 | O18: -200016 | Q18: =SUM(D18:O18) -> -3409916 | R18: =SUM(M18:O18)*4 -> -2424224 | T18: 11 - Repair & Maintenance | V18: Gross Effective Income | W18: =SUM(W13:W17) -> 455401 | X18: =SUM(X13:X17) -> 697016
C19: Total Net Rental Income | D19: 2954 | E19: 24708 | F19: 24892 | G19: 30112 | H19: 31402 | I19: 35582 | J19: 35582 | K19: 40872 | L19: 55043 | M19: 55104 | N19: 59736 | O19: 59414 | Q19: =SUM(D19:O19) -> 455401 | R19: =SUM(M19:O19)*4 -> 697016 | T19: 12 - Cleaning & Decorating | U19: 8 | V19: Utility Reimbursements | W19: =SUMIF($B$1:$B$495,U19,$Q$1:$Q$495) -> 585 | X19: =SUMIF($B$1:$B$495,U19,$R$1:$R$495) -> 2340
C20: Other Income | Q20: =SUM(D20:O20) -> 0 | R20: =SUM(M20:O20)*4 -> 0 | T20: 13 - Contract & Services | U20: 9 | V20: Other Reimbursements | W20: =SUMIF($B$1:$B$495,U20,$Q$1:$Q$495) -> 124 | X20: =SUMIF($B$1:$B$495,U20,$R$1:$R$495) -> 496
B21: 8 | C21: Electric Income | D21: 0 | E21: 0 | F21: 0 | G21: 0 | H21: 0 | I21: 0 | J21: 0 | K21: 0 | L21: 0 | M21: 0 | N21: 76 | O21: 282 | Q21: =SUM(D21:O21) -> 358 | R21: =SUM(M21:O21)*4 -> 1432 | T21: 14 - Utility- Electricity | U21: 10 | V21: Other Income | W21: =SUMIF($B$1:$B$495,U21,$Q$1:$Q$495) -> 28407.75 | X21: =SUMIF($B$1:$B$495,U21,$R$1:$R$495) -> 45501
B22: 8 | C22: Water Income | D22: 0 | E22: 0 | F22: 0 | G22: 0 | H22: 0 | I22: 0 | J22: 0 | K22: 0 | L22: 0 | M22: 0 | N22: 32 | O22: 118 | Q22: =SUM(D22:O22) -> 150 | R22: =SUM(M22:O22)*4 -> 600 | T22: 15 - Utility- Water | V22: Total Operating Revenue | W22: =SUM(W18:W21) -> 484517.75 | X22: =SUM(X18:X21) -> 745353
B23: 9 | C23: Broadband Income | D23: 0 | E23: 0 | F23: 0 | G23: 0 | H23: 0 | I23: 0 | J23: 0 | K23: 0 | L23: 0 | M23: 0 | N23: 26 | O23: 98 | Q23: =SUM(D23:O23) -> 124 | R23: =SUM(M23:O23)*4 -> 496 | T23: 16 - Utility- Others
B24: 10 | C24: Insurance Income | D24: 0 | E24: 0 | F24: 0 | G24: 40 | H24: 70 | I24: -90 | J24: -20 | K24: 0 | L24: 0 | M24: 0 | N24: 0 | O24: 0 | Q24: =SUM(D24:O24) -> 0 | R24: =SUM(M24:O24)*4 -> 0 | T24: 17 - Marketing | V24: Operating Expenses | W24: T12 | X24: T3
B25: 10 | C25: Tenant Service Request Income | D25: 0 | E25: 0 | F25: 0 | G25: 0 | H25: 0 | I25: 0 | J25: 0 | K25: 0 | L25: 0 | M25: 0 | N25: 0 | O25: 0 | Q25: =SUM(D25:O25) -> 0 | R25: =SUM(M25:O25)*4 -> 0 | T25: 18 - Payroll | U25: 11 | V25: Repair & Maintenance | W25: =SUMIF($B$1:$B$495,U25,$Q$1:$Q$495) -> 183567.24 | X25: =SUMIF($B$1:$B$495,U25,$R$1:$R$495) -> 172429.24
B26: 10 | C26: Late Fees | D26: 0 | E26: 0 | F26: 0 | G26: 287 | H26: 111.5 | I26: -398.5 | J26: 0 | K26: 143.5 | L26: 0 | M26: 224 | N26: 468.75 | O26: -382.5 | Q26: =SUM(D26:O26) -> 453.75 | R26: =SUM(M26:O26)*4 -> 1241 | T26: 19 - RE Taxes | U26: 12 | V26: Cleaning & Decorating | W26: =SUMIF($B$1:$B$495,U26,$Q$1:$Q$495) -> 13994.57 | X26: =SUMIF($B$1:$B$495,U26,$R$1:$R$495) -> 27232.76
B27: 10 | C27: Valet Tips | D27: 300 | E27: 300 | F27: 600 | G27: 0 | H27: 300 | I27: -300 | J27: 0 | K27: 100 | L27: 300 | M27: 100 | N27: 100 | O27: 100 | Q27: =SUM(D27:O27) -> 1900 | R27: =SUM(M27:O27)*4 -> 1200 | T27: 20 - Insurance | U27: 13 | V27: Contract & Services | W27: =SUMIF($B$1:$B$495,U27,$Q$1:$Q$495) -> 14865.53 | X27: =SUMIF($B$1:$B$495,U27,$R$1:$R$495) -> 11974
B28: 10 | C28: Application Fee | D28: 85 | E28: 85 | F28: 425 | G28: 0 | H28: 854 | I28: -170 | J28: 810 | K28: 255 | L28: 525 | M28: 170 | N28: 425 | O28: 255 | Q28: =SUM(D28:O28) -> 3719 | R28: =SUM(M28:O28)*4 -> 3400 | T28: 21 - Property Mangement fees | U28: 14 | V28: Utility | W28: =SUMIF($B$1:$B$495,U28,$Q$1:$Q$495) -> 73738.93 | X28: =SUMIF($B$1:$B$495,U28,$R$1:$R$495) -> 75831.68
B29: 10 | C29: Pet Fee | D29: 0 | E29: 0 | F29: 0 | G29: 0 | H29: 0 | I29: 0 | J29: 0 | K29: 35 | L29: 385 | M29: 35 | N29: 490 | O29: 70 | Q29: =SUM(D29:O29) -> 1015 | R29: =SUM(M29:O29)*4 -> 2380 | T29: 22 - General & Administrative Expenses | U29: 15 | V29: Utility- Water | W29: =SUMIF($B$1:$B$495,U29,$Q$1:$Q$495) -> 79997.63 | X29: =SUMIF($B$1:$B$495,U29,$R$1:$R$495) -> 89185
B30: 8 | C30: Utility Administration Fee | D30: 0 | E30: 0 | F30: 0 | G30: 0 | H30: 0 | I30: 0 | J30: 0 | K30: 0 | L30: 0 | M30: 0 | N30: 16 | O30: 61 | Q30: =SUM(D30:O30) -> 77 | R30: =SUM(M30:O30)*4 -> 308 | T30: 23 - Other taxes/Permit license fees | U30: 16 | V30: Utility- Others | W30: =SUMIF($B$1:$B$495,U30,$Q$1:$Q$495) -> 7313.09 | X30: =SUMIF($B$1:$B$495,U30,$R$1:$R$495) -> 23186.4
B31: 10 | C31: Miscellaneous Income | D31: 0 | E31: 0 | F31: 0 | G31: 0 | H31: 0 | I31: 0 | J31: 0 | K31: 0 | L31: 0 | M31: 0 | N31: 160 | O31: 160 | Q31: =SUM(D31:O31) -> 320 | R31: =SUM(M31:O31)*4 -> 1280 | T31: 24 - NOI | U31: 17 | V31: Marketing | W31: =SUMIF($B$1:$B$495,U31,$Q$1:$Q$495) -> 154532.67 | X31: =SUMIF($B$1:$B$495,U31,$R$1:$R$495) -> 147922.44
B32: 10 | C32: Other Income - Other | D32: 0 | E32: 0 | F32: 0 | G32: 0 | H32: 0 | I32: 0 | J32: 0 | K32: 12000 | L32: 0 | M32: 9000 | N32: 0 | O32: 0 | Q32: =SUM(D32:O32) -> 21000 | R32: =SUM(M32:O32)*4 -> 36000 | T32: 1 - Market Rent Potential | U32: 18 | V32: Payroll | W32: =SUMIF($B$1:$B$495,U32,$Q$1:$Q$495) -> 95880.89 | X32: =SUMIF($B$1:$B$495,U32,$R$1:$R$495) -> 98123.52
C33: Total Other Income | D33: 385 | E33: 385 | F33: 1025 | G33: 327 | H33: 1335.5 | I33: -958.5 | J33: 790 | K33: 12533.5 | L33: 1210 | M33: 9529 | N33: 1793.75 | O33: 761.5 | Q33: =SUM(D33:O33) -> 29116.75 | R33: =SUM(M33:O33)*4 -> 48337 | T33: 2 - Increase in Rent from Renovation | U33: 19 | V33: RE Taxes | W33: =SUMIF($B$1:$B$495,U33,$Q$1:$Q$495) -> 118548.62 | X33: =SUMIF($B$1:$B$495,U33,$R$1:$R$495) -> 118548.6
C34: TOTAL INCOME | D34: 3339 | E34: 25093 | F34: 25917 | G34: 30439 | H34: 32737.5 | I34: 34623.5 | J34: 36372 | K34: 53405.5 | L34: 56253 | M34: 64633 | N34: 61529.75 | O34: 60175.5 | Q34: =SUM(D34:O34) -> 484517.75 | R34: =SUM(M34:O34)*4 -> 745353 | T34: 3 - Loss to Lease | U34: 20 | V34: Insurance | W34: =SUMIF($B$1:$B$495,U34,$Q$1:$Q$495) -> 350471.86 | X34: =SUMIF($B$1:$B$495,U34,$R$1:$R$495) -> 819039.28
C35: EXPENSE | Q35: =SUM(D35:O35) -> 0 | R35: =SUM(M35:O35)*4 -> 0 | T35: 4 - Vacancy | U35: 21 | V35: Property Mangement fees | W35: =SUMIF($B$1:$B$495,U35,$Q$1:$Q$495) -> 30312.65 | X35: =SUMIF($B$1:$B$495,U35,$R$1:$R$495) -> 30000 | Y35: =W35/W18 -> 0.066562546
C36: Administrative Expense | Q36: =SUM(D36:O36) -> 0 | R36: =SUM(M36:O36)*4 -> 0 | T36: 5 - Concession/Discount | U36: 22 | V36: General & Administrative Expenses | W36: =SUMIF($B$1:$B$495,U36,$Q$1:$Q$495) -> 44364.92 | X36: =SUMIF($B$1:$B$495,U36,$R$1:$R$495) -> 85518.4
B37: 22 | C37: Administrative Expense - Other | D37: 0 | E37: 0 | F37: 51.39 | G37: 0 | H37: 0 | I37: 0 | J37: 0 | K37: 0 | L37: 0 | M37: 56 | N37: 203 | O37: 0 | Q37: =SUM(D37:O37) -> 310.39 | R37: =SUM(M37:O37)*4 -> 1036 | T37: 6 - Bad Debt | U37: 23 | V37: Other taxes/Permit license fees | W37: =SUMIF($B$1:$B$495,U37,$Q$1:$Q$495) -> 1832.97 | X37: =SUMIF($B$1:$B$495,U37,$R$1:$R$495) -> 0
B38: 22 | C38: Office Supplies | D38: 150.64 | E38: 936.09 | F38: 288.48 | G38: 98.46 | H38: 0 | I38: 1253.31 | J38: 0 | K38: 0 | L38: 202.82 | M38: 171.75 | N38: 248.98 | O38: 276.02 | Q38: =SUM(D38:O38) -> 3626.55 | R38: =SUM(M38:O38)*4 -> 2787 | T38: 7 - Non Revenue Units | V38: Operating Expenses | W38: =SUM(W25:W37) -> 1169421.6 | X38: =SUM(X25:X37) -> 1698991.3
B39: 22 | C39: Copier Expense | D39: 0 | E39: 0 | F39: 0 | G39: 0 | H39: 0 | I39: 0 | J39: 0 | K39: 0 | L39: 0 | M39: 0 | N39: 0 | O39: 0 | Q39: =SUM(D39:O39) -> 0 | R39: =SUM(M39:O39)*4 -> 0 | T39: 8 - Utility Reimbursements
B40: 22 | C40: Postage | D40: 0 | E40: 0 | F40: 0 | G40: 0 | H40: 0 | I40: 0 | J40: 0 | K40: 0 | L40: 0 | M40: 0 | N40: 5927.81 | O40: 0 | Q40: =SUM(D40:O40) -> 5927.81 | R40: =SUM(M40:O40)*4 -> 23711.24 | T40: 9 - Other Reimbursements | V40: Net Operating Income (NOI) | W40: =W22-W38 -> -684903.82 | X40: =X22-X38 -> -953638.32
B41: 22 | C41: Internet & Phone | D41: 0 | E41: 0 | F41: 1324.22 | G41: 270.45 | H41: 2021.23 | I41: 561.3 | J41: 859.75 | K41: 930.34 | L41: 0 | M41: 124.37 | N41: 124.83 | O41: 1052.96 | Q41: =SUM(D41:O41) -> 7269.45 | R41: =SUM(M41:O41)*4 -> 5208.64 | T41: 10 - Other Income | U41: 25 | V41: Replacement Reserve | W41: =SUMIF($B$1:$B$495,U41,$Q$1:$Q$495) -> 0 | X41: =SUMIF($B$1:$B$495,U41,$R$1:$R$495) -> 0
B42: 22 | C42: Reimbursable Travel | D42: 0 | E42: 0 | F42: 0 | G42: 0 | H42: 0 | I42: 27.6 | J42: 14.05 | K42: 14.5 | L42: 13.25 | M42: 0 | N42: 35.25 | O42: 0 | Q42: =SUM(D42:O42) -> 104.65 | R42: =SUM(M42:O42)*4 -> 141 | T42: 11 - Repair & Maintenance | U42: 24 | V42: NOI as per T 12 | W42: =SUMIF($B$1:$B$495,U42,$Q$1:$Q$495) -> -684903.82 | X42: =SUMIF($B$1:$B$495,U42,$R$1:$R$495) -> -953638.32
...

Sheet Rent Comp
A1: Property Id | B1: Map # | C1: Building Name | D1: Link to Website | E1: Address | F1: Rating | G1: Apartments.com Ad Level | H1: Common View Last 60 Days | I1: % Overlap with Subject Property | J1: Units | K1: Stories | L1: Yr Blt/Ren | M1: Avg SF | N1: mi Away | O1: Rent/SF | P1: Rent/Unit | Q1: Studio | R1: 1 bed | S1: SqFt | T1: Rent psf | U1: 2 Beds | V1: SqFt | W1: Rent psf | X1: 2 Beds-Ranch | Y1: SqFt | Z1: Rent psf | AA1: Occ % | AB1: Concess % | AE1: #3 Beds | AF1: Neighborhood
C6: Subject Property | O6: Actual rents from Rent Roll
C7: ='CFS-Main Page'!B2 -> Calabash Shores | D7: Link | E7: ='CFS-Main Page'!D2 -> 660 Aubrey Ln Calabash, NC, 28467 | J7: =Units -> 132 | L7: ='CFS-Main Page'!D4 -> 2024 | O7: =Rent!J31 -> 1.9659815 | P7: =Rent!J30 -> 1963.5985 | R7: =Rent!G5 -> 1568.64 | S7: =AVERAGE(Rent!I9:I10) -> 745 | T7: =R7/S7 -> 2.105557 | U7: =Rent!I5 -> 2441.5258 | V7: =AVERAGE(Rent!I11:I14,Rent!I17) -> 1068.6 | W7: =U7/V7 -> 2.2847892 | X7: =Rent!K5 -> 0 | Y7: =AVERAGE(Rent!I15:I16) -> 1179.5 | Z7: =X7/Y7 -> 0 | AA7: =Rent!H29 -> 0.28030303
C9: Comps
A10: 1 | C10: River Rock at Shingletree | D10: Link | E10: 31 Quaker Ridge Drive Carolina Shores, NC 28467 | J10: 136 | L10: 2024 | N10: 2.14 | T10: =R10/S10 -> #DIV/0! | U10: 1954 | V10: 1376 | W10: =U10/V10 -> 1.4200581 | X10: 1990 | Y10: 1376 | Z10: =X10/Y10 -> 1.4462209 | AA10: 0.632
A11: =A10+1 -> 2 | C11: Egret Landing | D11: Link | E11: 3021 Siskin Drive Northwest Calabash, NC 28467 | J11: 198 | L11: 2024 | N11: 2.24 | T11: =R11/S11 -> #DIV/0! | U11: 2223 | V11: 1311 | W11: =U11/V11 -> 1.6956522 | X11: 1850 | Y11: 1310 | Z11: =X11/Y11 -> 1.4122137 | AA11: 0.732
A12: =A11+1 -> 3 | C12: River Oaks | D12: Link | E12: 119 River Village Drive Little River, SC 29566 | J12: 190 | L12: 2018 | N12: 2.44 | T12: =R12/S12 -> #DIV/0! | U12: 1733 | V12: 1147 | W12: =U12/V12 -> 1.510898 | X12: 2238 | Y12: 1140 | Z12: =X12/Y12 -> 1.9631579 | AA12: 0.958
A13: =A12+1 -> 4 | C13: Heartsease at Calabash | D13: Link | E13: 1035 Brightwater Way Calabash, NC 28467 | J13: 158 | L13: 2024 | N13: 0.73 | R13: 1762 | S13: 1161 | T13: =R13/S13 -> 1.5176572 | U13: 1850 | V13: 1366 | W13: =U13/V13 -> 1.3543192 | X13: 2175 | Y13: 1440 | Z13: =X13/Y13 -> 1.5104167 | AA13: 0.956
A14: 5 | C14: Heartsease at Ocean Isle Beach | D14: Link | E14: 1956 Sparrowstar Way Ocean Isle Beach, NC 28469 | J14: 136 | L14: 2025 | N14: 4.93 | R14: 1530 | S14: 929 | T14: =R14/S14 -> 1.6469322 | U14: 1672 | V14: 1343 | W14: =U14/V14 -> 1.2449739 | AA14: 0.868
Q28: Studio | R28: 1 Beds | S28: Sqft | T28: PSF | U28: 2 Beds | V28: Sqft | W28: PSF | X28: 3 Beds | Y28: Sqft | Z28: PSF
M29: A. | N29: Avg Rent of Comps | Q29: =AVERAGE(Q10:Q26) -> #DIV/0! | R29: =AVERAGE(R10:R26) -> 1646 | S29: =AVERAGE(S10:S26) -> 1045 | T29: =AVERAGE(T10:T26) -> #DIV/0! | U29: =AVERAGE(U10:U26) -> 1886.4 | V29: =AVERAGE(V10:V26) -> 1308.6 | W29: =AVERAGE(W10:W26) -> 1.4451803 | X29: =AVERAGE(X10:X26) -> 2063.25 | ... Z29: =AVERAGE(Z10:Z26) -> 1.5830023
M30: B. | N30: Subject Prop Rent | Q30: =Q7 -> 0 | R30: =R7 -> 1568.64 | S30: =S7 -> 745 | T30: =T7 -> 2.105557 | U30: =U7 -> 2441.5258 | V30: =V7 -> 1068.6 | W30: =W7 -> 2.2847892 | X30: =X7 -> 0 | ... Z30: =Z7 -> 0
M32: C. | N32: C=A-B | Q32: =Q29-Q30 -> #DIV/0! | R32: =R29-R30 -> 77.36 | T32: =T29-T30 -> #DIV/0! | U32: =U29-U30 -> -555.12577 | W32: =W29-W30 -> -0.83960894 | X32: =X29-X30 -> 2063.25 | Z32: =Z29-Z30 -> 1.5830023
M33: *Source - Hello Data

Sheet Quick Comps
B1: Comp 1 | I1: Comp 2 | P1: Comp 3 | W1: Comp 4 | AD1: Comp 5 | AK1: Comp 6
B2: Units | D2: PIN/Parcel ID | I2: Units | K2: PIN/Parcel ID | P2: Units | R2: PIN/Parcel ID | W2: Units | Y2: PIN/Parcel ID | AD2: Units | AF2: PIN/Parcel ID | AK2: Units | AM2: PIN/Parcel ID
B3: Built in: | D3: Last Sales Date | I3: Built in: | K3: Last Sales Date | P3: Built in: | R3: Last Sales Date | W3: Built in: | Y3: Last Sales Date | AD3: Built in: | AF3: Last Sales Date | AK3: Built in: | AM3: Last Sales Date
B4: Managed By: | D4: Price / Unit | I4: Managed By: | K4: Price / Unit | P4: Managed By: | R4: Price / | W4: Managed By: | Y4: Price / | AD4: Managed By: | AF4: Price / | AK4: Managed By: | AM4: Price / Unit
B5: Rent Survey Date: | D5: Year Assessed | F5: Per Unit | I5: Rent Survey Date: | K5: Year Assessed | M5: Per Unit | P5: Rent Survey Date: | R5: Year Assessed | T5: Per Unit | W5: Rent Survey Date: | Y5: Year Assessed | AA5: Per Unit | AD5: Rent Survey Date: | AF5: Year Assessed | AH5: Per Unit | AK5: Rent Survey Date: | AM5: Year Assessed | AO5: Per Unit
B6: Occupancy: | D6: Land | F6: =E6/C2 -> #DIV/0! | I6: Occupancy: | K6: Land | M6: =L6/J2 -> #DIV/0! | P6: Occupancy: | R6: Land | T6: =S6/Q2 -> #DIV/0! | W6: Occupancy: | Y6: Land | AA6: =Z6/X2 -> #DIV/0! | AD6: Occupancy: | AF6: Land | AH6: =AG6/AE2 -> #DIV/0! | AK6: Occupancy: | AM6: Land | AO6: =AN6/AL2 -> #DIV/0!
B7: Last Rent Increase: | D7: Improvements | F7: =E7/C2 -> #DIV/0! | I7: Last Rent Increase: | K7: Improvements | M7: =L7/J2 -> #DIV/0! | P7: Last Rent Increase: | R7: Improvements | T7: =S7/Q2 -> #DIV/0! | W7: Last Rent Increase: | Y7: Improvements | AA7: =Z7/X2 -> #DIV/0! | AD7: Last Rent Increase: | AF7: Improvements | AH7: =AG7/AE2 -> #DIV/0! | AK7: Last Rent Increase: | AM7: Improvements | AO7: =AN7/AL2 -> #DIV/0!
B8: Concessions? | D8: Total | E8: =SUM(E6:E7) -> 0 | F8: =SUM(F6:F7) -> #DIV/0! | I8: Concessions? | K8: Total | L8: =SUM(L6:L7) -> 0 | M8: =SUM(M6:M7) -> #DIV/0! | P8: Concessions? | R8: Total | S8: =SUM(S6:S7) -> 0 | T8: =SUM(T6:T7) -> #DIV/0! | W8: Concessions? | Y8: Total | Z8: =SUM(Z6:Z7) -> 0 | AA8: =SUM(AA6:AA7) -> #DIV/0! | AD8: Concessions? | AF8: Total | AG8: =SUM(AG6:AG7) -> 0 | AH8: =SUM(AH6:AH7) -> #DIV/0! | AK8: Concessions? | AM8: Total | AN8: =SUM(AN6:AN7) -> 0 | AO8: =SUM(AO6:AO7) -> #DIV/0!
B9: Income Restricted? | D9: Tax District | I9: Income Restricted? | K9: Tax District | P9: Income Restricted? | R9: Tax District | W9: Income Restricted? | Y9: Tax District | AD9: Income Restricted? | AF9: Tax District | AK9: Income Restricted? | AM9: Tax District
B10: Tax Credit? | D10: Zoning | I10: Tax Credit? | K10: Zoning | P10: Tax Credit? | R10: Zoning | W10: Tax Credit? | Y10: Zoning | AD10: Tax Credit? | AF10: Zoning | AK10: Tax Credit? | AM10: Zoning
B11: Building Style | D11: Acres | I11: Building Style | K11: Acres | P11: Building Style | R11: Acres | W11: Building Style | Y11: Acres | AD11: Building Style | AF11: Acres | AK11: Building Style | AM11: Acres
B12: Distance from Subject | C12: 0 | D12: Density | E12: =IFERROR(C2/E11,0) -> 0 | I12: Distance from Subject | K12: Density | L12: =IFERROR(J2/L11,0) -> 0 | P12: Distance from Subject | R12: Density | S12: =IFERROR(Q2/S11,0) -> 0 | W12: Distance from Subject | Y12: Density | Z12: =IFERROR(X2/Z11,0) -> 0 | AD12: Distance from Subject | AF12: Density | AG12: =IFERROR(AE2/AG11,0) -> 0 | AK12: Distance from Subject | AM12: Density | AN12: =IFERROR(AL2/AN11,0) -> 0
B14: Studio | I14: Studio | P14: Studio | W14: Studio | AD14: Studio | AK14: Studio
B15: Unit Type | C15: Units | D15: Square Feet | E15: Base Rent | F15: PSF | G15: % of Mix | I15: Unit Type | J15: Units | K15: Square Feet | L15: Base Rent | M15: PSF | N15: % of Mix | P15: Unit Type | Q15: Units | R15: Square Feet | S15: Base Rent | T15: PSF | U15: % of Mix | W15: Unit Type | X15: Units | Y15: Square Feet | Z15: Base Rent | AA15: PSF | AB15: % of Mix | AD15: Unit Type | AE15: Units | AF15: Square Feet | AG15: Base Rent | AH15: PSF | AI15: % of Mix | AK15: Unit Type | AL15: Units | AM15: Square Feet | AN15: Base Rent | AO15: PSF | AP15: % of Mix
B16: 0x1 | F16: =IFERROR(E16/D16,0) -> 0 | G16: =C16/$C$2 -> #DIV/0! | M16: =IFERROR(L16/K16,0) -> 0 | N16: =J16/J$2 -> #DIV/0! | T16: =IFERROR(S16/R16,0) -> 0 | U16: =Q16/Q$2 -> #DIV/0! | AA16: =IFERROR(Z16/Y16,0) -> 0 | AB16: =X16/X$2 -> #DIV/0! | AH16: =IFERROR(AG16/AF16,0) -> 0 | AI16: =AE16/AE$2 -> #DIV/0! | AO16: =IFERROR(AN16/AM16,0) -> 0 | AP16: =AL16/AL$2 -> #DIV/0!
